Workbook
Name \0: #REF!
Name \00: #REF!
Name \01: #REF!
Name \a: #REF!
Name \b: #REF!
Name \c: #REF!
Name \d: #REF!
Name \DDR32Cont: OFFSET(DRAM!#REF!,0,0,COUNTA(DRAM!#REF!),5)
Name \DDR32Spot: OFFSET(DRAM!#REF!,0,0,COUNTA(DRAM!#REF!),8)
Name \e: #REF!
Name \f: #REF!
Name \g: #REF!
Name \h: #REF!
Name \i: #REF!
Name \MLC32Cont: OFFSET(NAND!#REF!,0,0,COUNTA(NAND!#REF!),5)
Name \MLC32Spot: OFFSET(NAND!#REF!,0,0,COUNTA(NAND!#REF!),6)
Name \MLC64Cont: OFFSET(NAND!#REF!,0,0,COUNTA(NAND!#REF!),5)
Name \MLC64Spot: OFFSET(NAND!#REF!,0,0,COUNTA(NAND!#REF!),6)
Name \MSD4CL2Spot: OFFSET(#REF!,0,0,COUNTA(#REF!),6)
Name \MSD4CL6Spot: OFFSET(#REF!,0,0,COUNTA(#REF!),5)
Name \MSD8CL2Spot: OFFSET(#REF!,0,0,COUNTA(#REF!),6)
Name \MSD8CL6Spot: OFFSET(#REF!,0,0,COUNTA(#REF!),5)
Name \SD4CL2Spot: OFFSET(#REF!,0,0,COUNTA(#REF!),6)
Name \SD4CL6Spot: OFFSET(#REF!,0,0,COUNTA(#REF!),5)
Name \SD8CL2Spot: OFFSET(#REF!,0,0,COUNTA(#REF!),6)
Name \SD8CL6Spot: OFFSET(#REF!,0,0,COUNTA(#REF!),5)
Name \TLC64Cont: OFFSET(NAND!#REF!,0,0,COUNTA(NAND!$A$26:$A$2668),5)
Name \TLC64Spot: OFFSET(NAND!#REF!,0,0,COUNTA(NAND!#REF!),6)
Name __ben1: #REF!
Name __ben2: #REF!
Name __cpu1: #REF!
Name __cpu2: #REF!
Name __cpu3: #REF!
Name __cpu4: #REF!
Name __dat1: #REF!
Name __dat2: #REF!
Name __dat3: #REF!
Name __dat4: #REF!
Name __fpu1: #REF!
Name __fpu2: #REF!
Name __fpu3: #REF!
Name __fpu4: #REF!
Name __lsu1: #REF!
Name __lsu2: #REF!
Name __lsu3: #REF!
Name __lsu4: #REF!
Name __msu1: #REF!
Name __msu2: #REF!
Name __msu3: #REF!
Name __msu4: #REF!
Name __mv1: #REF!
Name __mv2: #REF!
Name __mv3: #REF!
Name __mv4: #REF!
Name __pu1: #REF!
Name __pu2: #REF!
Name __pu3: #REF!
Name __pu4: #REF!
Name __ssu1: #REF!
Name __ssu2: #REF!

Sheet Cover
D30: Memory Price Tracker
D33: =TODAY() -> 46213
D42: Sanford C. Bernstein (Hong Kong) Limited
D43: 盛博香港有限公司
D46: Asian Semiconductors & Global Memory
H49: Mark Li | O49: Edward Hou, CFA | X49: Yipin Cai, CFA
H50: Senior Research Analyst | O50: Senior Research Associate | X50: Senior Research Associate
H51: mark.li@bernsteinsg.com | O51: edward.hou@bernsteinsg.com | X51: yipin.cai@bernsteinsg.com
D58: This model is directed to and intended only for our clients who are “eligible counterparties”, “professional clients”, “institutional investors” and/or “professional investors” as defined by applicable local regulations and must not be redistributed to retail clients. This model is being provided to you with the understanding that you are an investment professional familiar with its limitations and that it may not be reproduced, re-distributed, transmitted or otherwise made available to, or shared with, any third party. Clients may not create derivative works, resell, or commercially exploit any part of the information contained herein with any third party for any purpose without Bernstein’s express prior written consent. This restriction includes extracting data, using this content to develop indexes or products, or inputting any portion of the information contained herein into machine learning or artificial intelligence systems. The analysis contained herein is based on numerous assumptions. Different assumptions could result in materially different results. We believe that the data in this model obtained from public sources is reliable; however, we make no representation that such data is accurate or complete. Estimates of future performance in this model are based on assumptions that may not be realized due to unforeseen factors like market volatility/fluctuation. This model is not a research report, nor is it a substitute for our published research; on its own, this model should not be relied upon to make an investment decision. For our latest research reports, which contain information that may be used to support investment decisions and important disclosures, please see our website at https://www.bernsteinresearch.com.

Sheet N_Summary
Q1: Current Year | R1: 2026 | T1: For Spot | Z1: For Contract | AA1: 2-Qtr Ahead | AB1: Prior Qtr | AC1: Month in the Current Qtr
Q2: Current Month | R2: 5 | T2: N-3 | U2: N-2 | V2: N-1 | W2: N | X2: N+1 | Y2: N+2 | AC2: =(LEFT(W4)-1)*3+1 -> 4 | AD2: =AC2+1 -> 5 | AE2: =AD2+1 -> 6
T3: =DATE($R$1,$R$2-2,0) -> 46081 | U3: =DATE($R$1,$R$2-1,0) -> 46112 | V3: =DATE($R$1,$R$2,0) -> 46142 | W3: =DATE($R$1,$R$2+1,0) -> 46173 | X3: =DATE($R$1,$R$2+2,0) -> 46203 | Y3: =DATE($R$1,$R$2+3,0) -> 46234 | AC3: =DATE($R$1,AC2+1,0) -> 46142 | AD3: =DATE($R$1,AD2+1,0) -> 46173 | AE3: =DATE($R$1,AE2+1,0) -> 46203
T4: =TEXT(ROUNDUP(MONTH(T3)/3,0),0)&"Q"&RIGHT(TEXT(YEAR(T3),0),2) -> 1Q26 | U4: =TEXT(ROUNDUP(MONTH(U3)/3,0),0)&"Q"&RIGHT(TEXT(YEAR(U3),0),2) -> 1Q26 | V4: =TEXT(ROUNDUP(MONTH(V3)/3,0),0)&"Q"&RIGHT(TEXT(YEAR(V3),0),2) -> 2Q26 | W4: =TEXT(ROUNDUP(MONTH(W3)/3,0),0)&"Q"&RIGHT(TEXT(YEAR(W3),0),2) -> 2Q26 | X4: =TEXT(ROUNDUP(MONTH(X3)/3,0),0)&"Q"&RIGHT(TEXT(YEAR(X3),0),2) -> 2Q26 | Y4: =TEXT(ROUNDUP(MONTH(Y3)/3,0),0)&"Q"&RIGHT(TEXT(YEAR(Y3),0),2) -> 3Q26 | AA4: =TEXT(ROUNDUP(MONTH(DATE($R$1,$R$2-5,0))/3,0),0)&"Q"&RIGHT(TEXT(YEAR(DATE($R$1,$R$2-5,0)),0),2) -> 4Q25 | AB4: =T4 -> 1Q26 | AC4: =TEXT(ROUNDUP(MONTH(AC3)/3,0),0)&"Q"&RIGHT(TEXT(YEAR(AC3),0),2) -> 2Q26 | AD4: =TEXT(ROUNDUP(MONTH(AD3)/3,0),0)&"Q"&RIGHT(TEXT(YEAR(AD3),0),2) -> 2Q26 | AE4: =TEXT(ROUNDUP(MONTH(AE3)/3,0),0)&"Q"&RIGHT(TEXT(YEAR(AE3),0),2) -> 2Q26
T5: =LEFT(T4,2)&"CY"&RIGHT(T4,2) -> 1QCY26 | U5: =LEFT(U4,2)&"CY"&RIGHT(U4,2) -> 1QCY26 | V5: =LEFT(V4,2)&"CY"&RIGHT(V4,2) -> 2QCY26 | W5: =LEFT(W4,2)&"CY"&RIGHT(W4,2) -> 2QCY26 | X5: =LEFT(X4,2)&"CY"&RIGHT(X4,2) -> 2QCY26 | Y5: =LEFT(Y4,2)&"CY"&RIGHT(Y4,2) -> 3QCY26 | AA5: =LEFT(AA4,2)&"CY"&RIGHT(AA4,2) -> 4QCY25 | AB5: =LEFT(AB4,2)&"CY"&RIGHT(AB4,2) -> 1QCY26 | AC5: =LEFT(AC4,2)&"CY"&RIGHT(AC4,2) -> 2QCY26 | AD5: =LEFT(AD4,2)&"CY"&RIGHT(AD4,2) -> 2QCY26 | AE5: =LEFT(AE4,2)&"CY"&RIGHT(AE4,2) -> 2QCY26
T6: =IF(LEFT(T4,1)="4",1,LEFT(T4,1)+1)&"QFY"&IF(LEFT(T4,1)="4",RIGHT(T4,2)+1,RIGHT(T4,2)) -> 2QFY26 | U6: =IF(LEFT(U4,1)="4",1,LEFT(U4,1)+1)&"QFY"&IF(LEFT(U4,1)="4",RIGHT(U4,2)+1,RIGHT(U4,2)) -> 2QFY26 | V6: =IF(LEFT(V4,1)="4",1,LEFT(V4,1)+1)&"QFY"&IF(LEFT(V4,1)="4",RIGHT(V4,2)+1,RIGHT(V4,2)) -> 3QFY26 | W6: =IF(LEFT(W4,1)="4",1,LEFT(W4,1)+1)&"QFY"&IF(LEFT(W4,1)="4",RIGHT(W4,2)+1,RIGHT(W4,2)) -> 3QFY26 | X6: =IF(LEFT(X4,1)="4",1,LEFT(X4,1)+1)&"QFY"&IF(LEFT(X4,1)="4",RIGHT(X4,2)+1,RIGHT(X4,2)) -> 3QFY26 | Y6: =IF(LEFT(Y4,1)="4",1,LEFT(Y4,1)+1)&"QFY"&IF(LEFT(Y4,1)="4",RIGHT(Y4,2)+1,RIGHT(Y4,2)) -> 4QFY26 | AA6: =IF(LEFT(AA4,1)="4",1,LEFT(AA4,1)+1)&"QFY"&IF(LEFT(AA4,1)="4",RIGHT(AA4,2)+1,RIGHT(AA4,2)) -> 1QFY26 | AB6: =T6 -> 2QFY26 | AC6: =IF(LEFT(AC4,1)="4",1,LEFT(AC4,1)+1)&"QFY"&IF(LEFT(AC4,1)="4",RIGHT(AC4,2)+1,RIGHT(AC4,2)) -> 3QFY26 | AD6: =IF(LEFT(AD4,1)="4",1,LEFT(AD4,1)+1)&"QFY"&IF(LEFT(AD4,1)="4",RIGHT(AD4,2)+1,RIGHT(AD4,2)) -> 3QFY26 | AE6: =IF(LEFT(AE4,1)="4",1,LEFT(AE4,1)+1)&"QFY"&IF(LEFT(AE4,1)="4",RIGHT(AE4,2)+1,RIGHT(AE4,2)) -> 3QFY26
C10: FOR EXHIBIT USE ONLY
F11: =U11 -> Price at End of Month | L11: Quarterly Avg | U11: Price at End of Month | AA11: Quarterly Avg
F12: =U12 -> Mar-26 | G12: =V12 -> Apr-26 | H12: =W12 -> May-26 | I12: =X12 -> MoM | L12: =AA12 -> 1QCY26 | M12: =AB12 -> 2QCY26 QTD | N12: =AC12 -> QoQ | U12: =TEXT($U$3,"MMM-YY") -> Mar-26 | V12: =TEXT($V$3,"MMM-YY") -> Apr-26 | W12: =TEXT($W$3,"MMM-YY") -> May-26 | X12: MoM | AA12: =$T$5 -> 1QCY26 | AB12: =$W$5&IF(OR(R2=3,R2=6,R2=9,R2=12),," QTD") -> 2QCY26 QTD | AC12: QoQ
C13: =R13 -> DRAM | I13: =X13 -> 46112 | J13: =Y13 -> 46142 | K13: =Z13 -> 46173 | Q13: 2023 Weight | R13: DRAM | X13: =EOMONTH(Y13,-1) -> 46112 | Y13: =EOMONTH(Z13,-1) -> 46142 | Z13: =$W$3 -> 46173
C14: =R14 -> Spot Price (US$/GB) | R14: Spot Price (US$/GB)
C15: =R15 -> PC DRAM | E15: DDR4 8Gb Chip | F15: =U15 -> 33.96 | G15: =V15 -> 32.48 | H15: =W15 -> 34.1 | I15: =X15 -> 0.032218845 | J15: =Y15 -> -0.043580683 | K15: =Z15 -> 0.049876847 | L15: =AA15 -> 31.229948 | M15: =AB15 -> 32.919048 | N15: =AC15 -> 0.054085883 | R15: PC DRAM | T15: 8Gb DDR4 | U15: {=INDEX(DRAM!$L:$L,MATCH(U3,DRAM!$I:$I,1),)} -> 33.96 | V15: {=INDEX(DRAM!$L:$L,MATCH(V3,DRAM!$I:$I,1),)} -> 32.48 | W15: {=INDEX(DRAM!$L:$L,MATCH(W3,DRAM!$I:$I,1),)} -> 34.1 | X15: {=U15/INDEX(DRAM!$L:$L,MATCH(T3,DRAM!$I:$I,1),)-1} -> 0.032218845 | Y15: =V15/U15-1 -> -0.043580683 | Z15: =W15/V15-1 -> 0.049876847 | AA15: =AVERAGEIF(DRAM!$C:$C,N_Summary!T$4,DRAM!$L:$L) -> 31.229948 | AB15: =AVERAGEIF(DRAM!$C:$C,N_Summary!W$4,DRAM!$L:$L) -> 32.919048 | AC15: =AB15/AA15-1 -> 0.054085883
E16: DDR5 16Gb Chip | F16: =U16 -> 18.713 | G16: =V16 -> 19.5 | H16: =W16 -> 20.95 | I16: =X16 -> -0.052506329 | J16: =Y16 -> 0.042056324 | K16: =Z16 -> 0.074358974 | L16: =AA16 -> 18.554405 | M16: =AB16 -> 19.651917 | N16: =AC16 -> 0.059150993 | T16: 16Gb DDR5 | U16: {=INDEX(DRAM!$Z:$Z,MATCH(U3,DRAM!$S:$S,1),)/2} -> 18.713 | V16: {=INDEX(DRAM!$Z:$Z,MATCH(V3,DRAM!$S:$S,1),)/2} -> 19.5 | W16: {=INDEX(DRAM!$Z:$Z,MATCH(W3,DRAM!$S:$S,1),)/2} -> 20.95 | X16: {=U16/(INDEX(DRAM!$Z:$Z,MATCH(T3,DRAM!$S:$S,1),)/2)-1} -> -0.052506329 | Y16: =V16/U16-1 -> 0.042056324 | Z16: =W16/V16-1 -> 0.074358974 | AA16: =AVERAGEIF(DRAM!$C:$C,N_Summary!T$4,DRAM!$Z:$Z)/2 -> 18.554405 | AB16: =AVERAGEIF(DRAM!$C:$C,N_Summary!W$4,DRAM!$Z:$Z)/2 -> 19.651917 | AC16: =AB16/AA16-1 -> 0.059150993
C17: =R17 -> Server DRAM | E17: =T17 -> DDR4 64GB RDIMM* | F17: =U17 -> 20.3125 | G17: =V17 -> 22.421875 | H17: =W17 -> 23.125 | I17: =X17 -> 0.39484979 | J17: =Y17 -> 0.10384615 | K17: =Z17 -> 0.031358885 | L17: =AA17 -> 15.382812 | ... N17: =AC17 -> 0.47102308 | R17: Server DRAM | T17: DDR4 64GB RDIMM* | U17: =INDEX(DRAM!$AT:$AW,MATCH(U3,DRAM!$AS:$AS,1),MATCH($T17,DRAM!$AT$28:$AW$28,0))/64 -> 20.3125 | V17: =INDEX(DRAM!$AT:$AW,MATCH(V3,DRAM!$AS:$AS,1),MATCH($T17,DRAM!$AT$28:$AW$28,0))/64 -> 22.421875 | W17: =INDEX(DRAM!$AT:$AW,MATCH(W3,DRAM!$AS:$AS,1),MATCH($T17,DRAM!$AT$28:$AW$28,0))/64 -> 23.125 | X17: =U17/(INDEX(DRAM!$AT:$AW,MATCH(T3,DRAM!$AS:$AS,1),MATCH($T17,DRAM!$AT$28:$AW$28,0))/64)-1 -> 0.39484979 | Y17: =V17/U17-1 -> 0.10384615 | Z17: =W17/V17-1 -> 0.031358885 | AA17: =AVERAGEIF(DRAM!$AQ:$AQ,N_Summary!T$4,DRAM!$AV:$AV)/64 -> 15.382812 | AB17: =AVERAGEIF(DRAM!$AQ:$AQ,N_Summary!W$4,DRAM!$AV:$AV)/64 -> 22.628472 | AC17: =AB17/AA17-1 -> 0.47102308
E18: =T18 -> DDR5 64GB RDIMM* | F18: =U18 -> 37.5 | G18: =V18 -> 35 | H18: =W18 -> 35.546875 | I18: =X18 -> 0.10344828 | J18: =Y18 -> -0.066666667 | K18: =Z18 -> 0.015625 | L18: =AA18 -> 30.436198 | ... N18: =AC18 -> 0.17327629 | T18: DDR5 64GB RDIMM* | U18: =INDEX(DRAM!$AT:$BA,MATCH(U3,DRAM!$AS:$AS,1),MATCH($T18,DRAM!$AT$28:$BA$28,0))/64 -> 37.5 | V18: =INDEX(DRAM!$AT:$BA,MATCH(V3,DRAM!$AS:$AS,1),MATCH($T18,DRAM!$AT$28:$BA$28,0))/64 -> 35 | W18: =INDEX(DRAM!$AT:$BA,MATCH(W3,DRAM!$AS:$AS,1),MATCH($T18,DRAM!$AT$28:$BA$28,0))/64 -> 35.546875 | X18: =U18/(INDEX(DRAM!$AT:$BA,MATCH(T3,DRAM!$AS:$AS,1),MATCH($T18,DRAM!$AT$28:$BA$28,0))/64)-1 -> 0.10344828 | Y18: =V18/U18-1 -> -0.066666667 | Z18: =W18/V18-1 -> 0.015625 | AA18: =AVERAGEIF(DRAM!$AQ:$AQ,N_Summary!T$4,DRAM!$AZ:$AZ)/64 -> 30.436198 | AB18: =AVERAGEIF(DRAM!$AQ:$AQ,N_Summary!W$4,DRAM!$AZ:$AZ)/64 -> 35.710069 | AC18: =AB18/AA18-1 -> 0.17327629
F20: =U20 -> Prior Price | I20: =X20 -> Price for 2QCY26 | J20: =X20 -> Price for 2QCY26 | L20: =AA20 -> 2QCY26 Over 1QCY26 | U20: Prior Price | X20: ="Price for "&$W$5 -> Price for 2QCY26 | AA20: =$W$5&" Over "&$T$5 -> 2QCY26 Over 1QCY26
C21: =R21 -> DRAM | F21: =U21 -> 4QCY25 | G21: =V21 -> 1QCY26 | H21: =W21 -> QoQ | I21: =X21 -> Apr-26 | J21: =Y21 -> May-26 | K21: =Z21 -> Jun-26 | L21: =AA21 -> Apr-26 | M21: =AB21 -> May-26 | N21: =AC21 -> Jun-26 | Q21: 2025 Weight | R21: DRAM | U21: =$AA$5 -> 4QCY25 | V21: =$AB$5 -> 1QCY26 | W21: QoQ | X21: =TEXT($AC$3,"MMM-YY") -> Apr-26 | Y21: =TEXT($AD$3,"MMM-YY") -> May-26 | Z21: =TEXT($AE$3,"MMM-YY") -> Jun-26 | AA21: =X21 -> Apr-26 | AB21: =Y21 -> May-26 | AC21: =Z21 -> Jun-26
C22: =R22 -> Contract Price (US$/GB, except the price of uMCP & eMCP is module price) | R22: Contract Price (US$/GB, except the price of uMCP & eMCP is module price)
C23: =R23 -> PC DRAM | E23: DDR4 8Gb Chip | F23: =U23 -> 8.1333333 | G23: =V23 -> 12.5 | H23: =W23 -> 0.53688525 | I23: =X23 -> 16 | J23: =Y23 -> 20 | K23: =Z23 -> #N/A | L23: =AA23 -> 0.28 | M23: =AB23 -> 0.6 | N23: =AC23 -> #N/A | P23: =AVERAGE(AA23:AA27) -> 0.33569223 | Q23: 0.10303961 | R23: PC DRAM | T23: 8Gb DDR4 | U23: =AVERAGEIF(DRAM!$BQ:$BQ,N_Summary!AA$4,DRAM!$BV:$BV) -> 8.1333333 | V23: =AVERAGEIF(DRAM!$BQ:$BQ,N_Summary!AB$4,DRAM!$BV:$BV) -> 12.5 | W23: =V23/U23-1 -> 0.53688525 | X23: {=INDEX(DRAM!$BV:$BV,MATCH(N_Summary!AC$3,DRAM!$BS:$BS,0),)} -> 16 | Y23: {=INDEX(DRAM!$BV:$BV,MATCH(N_Summary!AD$3,DRAM!$BS:$BS,0),)} -> 20 | Z23: {=INDEX(DRAM!$BV:$BV,MATCH(N_Summary!AE$3,DRAM!$BS:$BS,0),)} -> #N/A | AA23: =X23/$V23-1 -> 0.28 | AB23: =Y23/$V23-1 -> 0.6 | AC23: =Z23/$V23-1 -> #N/A
E24: DDR5 16Gb Chip | F24: =U24 -> 8.1666667 | G24: =V24 -> 14.916667 | H24: =W24 -> 0.82653061 | I24: =X24 -> 17.5 | J24: =Y24 -> 18.75 | K24: =Z24 -> #N/A | L24: =AA24 -> 0.17318436 | M24: =AB24 -> 0.25698324 | N24: =AC24 -> #N/A | T24: 16Gb DDR5 | U24: =AVERAGEIF(DRAM!$BQ:$BQ,N_Summary!AA$4,DRAM!$BX:$BX)/2 -> 8.1666667 | V24: =AVERAGEIF(DRAM!$BQ:$BQ,N_Summary!AB$4,DRAM!$BX:$BX)/2 -> 14.916667 | W24: =V24/U24-1 -> 0.82653061 | X24: {=INDEX(DRAM!$BX:$BX,MATCH(N_Summary!AC$3,DRAM!$BS:$BS,0),)/2} -> 17.5 | Y24: {=INDEX(DRAM!$BX:$BX,MATCH(N_Summary!AD$3,DRAM!$BS:$BS,0),)/2} -> 18.75 | Z24: {=INDEX(DRAM!$BX:$BX,MATCH(N_Summary!AE$3,DRAM!$BS:$BS,0),)/2} -> #N/A | AA24: =X24/$V24-1 -> 0.17318436 | AB24: =Y24/$V24-1 -> 0.25698324 | AC24: =Z24/$V24-1 -> #N/A
E25: =T25 -> DDR5 16GB UDIMM* | F25: =U25 -> 4.09375 | G25: =V25 -> 8.6666667 | H25: =W25 -> 1.1170483 | I25: =X25 -> 12.5625 | J25: =Y25 -> 12.8125 | K25: =Z25 -> #N/A | L25: =AA25 -> 0.44951923 | ... N25: =AC25 -> #N/A | T25: DDR5 16GB UDIMM* | U25: =AVERAGEIF(DRAM!$BQ:$BQ,N_Summary!AA$4,DRAM!$CB:$CB)/16 -> 4.09375 | V25: =AVERAGEIF(DRAM!$BQ:$BQ,N_Summary!AB$4,DRAM!$CB:$CB)/16 -> 8.6666667 | W25: =V25/U25-1 -> 1.1170483 | X25: {=INDEX(DRAM!$CB:$CB,MATCH(N_Summary!AC$3,DRAM!$BS:$BS,0),)/16} -> 12.5625 | Y25: {=INDEX(DRAM!$CB:$CB,MATCH(N_Summary!AD$3,DRAM!$BS:$BS,0),)/16} -> 12.8125 | Z25: {=INDEX(DRAM!$CB:$CB,MATCH(N_Summary!AE$3,DRAM!$BS:$BS,0),)/16} -> #N/A | AA25: =X25/$V25-1 -> 0.44951923 | AB25: =Y25/$V25-1 -> 0.47836538 | AC25: =Z25/$V25-1 -> #N/A | AD25: =R54*AVERAGE(U23:U24)+(1-R54)*(U25*U53+U27*(1-U53)) -> 4.5704217 | AE25: =R54*AVERAGE(V23:V24)+(1-R54)*(V25*V53+V27*(1-V53)) -> 9.3457545 | AF25: =R54*AVERAGE(X23:X24)+(1-R54)*(X25*X53+X27*(1-X53)) -> 13.16373 | AG25: =R54*AVERAGE(Y23:Y24)+(1-R54)*(Y25*Y53+Y27*(1-Y53)) -> 13.631502 | AH25: =R54*AVERAGE(Z23:Z24)+(1-R54)*(Z25*Z53+Z27*(1-Z53)) -> #N/A
E26: =T26 -> DDR4 16GB UDIMM* | F26: =U26 -> 4.59375 | G26: =V26 -> 10.3125 | H26: =W26 -> 1.244898 | I26: =X26 -> 14.1875 | J26: =Y26 -> 14.1875 | K26: =Z26 -> #N/A | L26: =AA26 -> 0.37575758 | ... N26: =AC26 -> #N/A | T26: DDR4 16GB UDIMM* | U26: =AVERAGEIF(DRAM!$BQ:$BQ,N_Summary!AA$4,DRAM!$CC:$CC)/16 -> 4.59375 | V26: =AVERAGEIF(DRAM!$BQ:$BQ,N_Summary!AB$4,DRAM!$CC:$CC)/16 -> 10.3125 | W26: =V26/U26-1 -> 1.244898 | X26: {=INDEX(DRAM!$CC:$CC,MATCH(N_Summary!AC$3,DRAM!$BS:$BS,0),)/16} -> 14.1875 | Y26: {=INDEX(DRAM!$CC:$CC,MATCH(N_Summary!AD$3,DRAM!$BS:$BS,0),)/16} -> 14.1875 | Z26: {=INDEX(DRAM!$CC:$CC,MATCH(N_Summary!AE$3,DRAM!$BS:$BS,0),)/16} -> #N/A | AA26: =X26/$V26-1 -> 0.37575758 | AB26: =Y26/$V26-1 -> 0.37575758 | AC26: =Z26/$V26-1 -> #N/A | AE26: =AE25/AD25-1 -> 1.0448342 | AF26: =AF25/AE25-1 -> 0.40852507 | AG26: =AG25/$AE25-1 -> 0.45857694 | AH26: =AH25/$AE25-1 -> #N/A
E27: =T27 -> DDR4 8GB UDIMM* | F27: =U27 -> 4.875 | G27: =V27 -> 10.625 | H27: =W27 -> 1.1794872 | I27: =X27 -> 14.875 | J27: =Y27 -> 14.875 | K27: =Z27 -> #N/A | L27: =AA27 -> 0.4 | ... N27: =AC27 -> #N/A | T27: DDR4 8GB UDIMM* | U27: =AVERAGEIF(DRAM!$BQ:$BQ,N_Summary!AA$4,DRAM!$CD:$CD)/8 -> 4.875 | V27: =AVERAGEIF(DRAM!$BQ:$BQ,N_Summary!AB$4,DRAM!$CD:$CD)/8 -> 10.625 | W27: =V27/U27-1 -> 1.1794872 | X27: {=INDEX(DRAM!$CD:$CD,MATCH(N_Summary!AC$3,DRAM!$BS:$BS,0),)/8} -> 14.875 | Y27: {=INDEX(DRAM!$CD:$CD,MATCH(N_Summary!AD$3,DRAM!$BS:$BS,0),)/8} -> 14.875 | Z27: {=INDEX(DRAM!$CD:$CD,MATCH(N_Summary!AE$3,DRAM!$BS:$BS,0),)/8} -> #N/A | AA27: =X27/$V27-1 -> 0.4 | AB27: =Y27/$V27-1 -> 0.4 | AC27: =Z27/$V27-1 -> #N/A
C29: =R29 -> Server DRAM | E29: =T29 -> DDR5 96GB RDIMM* | F29: =U29 -> 6.9270833 | G29: =V29 -> 13.854167 | H29: =W29 -> 1 | I29: =X29 -> 20.4375 | J29: =Y29 -> 21.041667 | K29: =Z29 -> #N/A | L29: =AA29 -> 0.47518797 | ... N29: =AC29 -> #N/A | P29: =AVERAGE(AA30,AA32) -> 0.50118584 | Q29: 0.37202453 | R29: Server DRAM | T29: DDR5 96GB RDIMM* | U29: =AVERAGEIF(DRAM!$BQ:$BQ,N_Summary!AA$4,DRAM!$CL:$CL)/96 -> 6.9270833 | V29: =AVERAGEIF(DRAM!$BQ:$BQ,N_Summary!AB$4,DRAM!$CL:$CL)/96 -> 13.854167 | W29: =V29/U29-1 -> 1 | X29: =INDEX(DRAM!$CE:$CW,MATCH(N_Summary!AC$3,DRAM!$CA:$CA,0),MATCH($T29,DRAM!$CE$28:$CW$28,0))/96 -> 20.4375 | Y29: =INDEX(DRAM!$CE:$CW,MATCH(N_Summary!AD$3,DRAM!$CA:$CA,0),MATCH($T29,DRAM!$CE$28:$CW$28,0))/96 -> 21.041667 | Z29: =INDEX(DRAM!$CE:$CW,MATCH(N_Summary!AE$3,DRAM!$CA:$CA,0),MATCH($T29,DRAM!$CE$28:$CW$28,0))/96 -> #N/A | AA29: =X29/$V29-1 -> 0.47518797 | AB29: =Y29/$V29-1 -> 0.51879699 | AC29: =Z29/$V29-1 -> #N/A
E30: =T30 -> DDR5 64GB RDIMM* | F30: =U30 -> 6.640625 | G30: =V30 -> 12.953125 | H30: =W30 -> 0.95058824 | I30: =X30 -> 19.109375 | J30: =Y30 -> 19.765625 | K30: =Z30 -> #N/A | L30: =AA30 -> 0.47527141 | ... N30: =AC30 -> #N/A | T30: DDR5 64GB RDIMM* | U30: =AVERAGEIF(DRAM!$BQ:$BQ,N_Summary!AA$4,DRAM!$CP:$CP)/64 -> 6.640625 | V30: =AVERAGEIF(DRAM!$BQ:$BQ,N_Summary!AB$4,DRAM!$CP:$CP)/64 -> 12.953125 | W30: =V30/U30-1 -> 0.95058824 | X30: =INDEX(DRAM!$CE:$CW,MATCH(N_Summary!AC$3,DRAM!$CA:$CA,0),MATCH($T30,DRAM!$CE$28:$CW$28,0))/64 -> 19.109375 | Y30: =INDEX(DRAM!$CE:$CW,MATCH(N_Summary!AD$3,DRAM!$CA:$CA,0),MATCH($T30,DRAM!$CE$28:$CW$28,0))/64 -> 19.765625 | Z30: =INDEX(DRAM!$CE:$CW,MATCH(N_Summary!AE$3,DRAM!$CA:$CA,0),MATCH($T30,DRAM!$CE$28:$CW$28,0))/64 -> #N/A | AA30: =X30/$V30-1 -> 0.47527141 | AB30: =Y30/$V30-1 -> 0.52593486 | AC30: =Z30/$V30-1 -> #N/A
E31: =T31 -> DDR5 48GB RDIMM* | F31: =U31 -> 7.0833333 | G31: =V31 -> 13.816667 | H31: =W31 -> 0.95058824 | I31: =X31 -> 20.383333 | J31: =Y31 -> 21.083333 | K31: =Z31 -> #N/A | L31: =AA31 -> 0.47527141 | ... N31: =AC31 -> #N/A | T31: DDR5 48GB RDIMM* | U31: =AVERAGEIF(DRAM!$BQ:$BQ,N_Summary!AA$4,DRAM!$CK:$CK)/48 -> 7.0833333 | V31: =AVERAGEIF(DRAM!$BQ:$BQ,N_Summary!AB$4,DRAM!$CK:$CK)/48 -> 13.816667 | W31: =V31/U31-1 -> 0.95058824 | X31: =INDEX(DRAM!$CE:$CW,MATCH(N_Summary!AC$3,DRAM!$CA:$CA,0),MATCH($T31,DRAM!$CE$28:$CW$28,0))/48 -> 20.383333 | Y31: =INDEX(DRAM!$CE:$CW,MATCH(N_Summary!AD$3,DRAM!$CA:$CA,0),MATCH($T31,DRAM!$CE$28:$CW$28,0))/48 -> 21.083333 | Z31: =INDEX(DRAM!$CE:$CW,MATCH(N_Summary!AE$3,DRAM!$CA:$CA,0),MATCH($T31,DRAM!$CE$28:$CW$28,0))/48 -> #N/A | AA31: =X31/$V31-1 -> 0.47527141 | AB31: =Y31/$V31-1 -> 0.52593486 | AC31: =Z31/$V31-1 -> #N/A
E32: =T32 -> DDR4 64GB RDIMM* | F32: =U32 -> 5.84375 | G32: =V32 -> 11.53125 | H32: =W32 -> 0.97326203 | I32: =X32 -> 17.609375 | J32: =Y32 -> 17.609375 | K32: =Z32 -> #N/A | L32: =AA32 -> 0.52710027 | ... N32: =AC32 -> #N/A | T32: DDR4 64GB RDIMM* | U32: =AVERAGEIF(DRAM!$BQ:$BQ,N_Summary!AA$4,DRAM!$CF:$CF)/64 -> 5.84375 | V32: =AVERAGEIF(DRAM!$BQ:$BQ,N_Summary!AB$4,DRAM!$CF:$CF)/64 -> 11.53125 | W32: =V32/U32-1 -> 0.97326203 | X32: =INDEX(DRAM!$CE:$CW,MATCH(N_Summary!AC$3,DRAM!$CA:$CA,0),MATCH($T32,DRAM!$CE$28:$CW$28,0))/64 -> 17.609375 | Y32: =INDEX(DRAM!$CE:$CW,MATCH(N_Summary!AD$3,DRAM!$CA:$CA,0),MATCH($T32,DRAM!$CE$28:$CW$28,0))/64 -> 17.609375 | Z32: =INDEX(DRAM!$CE:$CW,MATCH(N_Summary!AE3,DRAM!$CA:$CA,0),MATCH($T32,DRAM!$CE$28:$CW$28,0))/64 -> #N/A | AA32: =X32/$V32-1 -> 0.52710027 | AB32: =Y32/$V32-1 -> 0.52710027 | AC32: =Z32/$V32-1 -> #N/A
E33: =T33 -> DDR5 32GB RDIMM* | F33: =U33 -> 7.03125 | G33: =V33 -> 13.71875 | H33: =W33 -> 0.95111111 | I33: =X33 -> 20.25 | J33: =Y33 -> 20.90625 | K33: =Z33 -> #N/A | L33: =AA33 -> 0.476082 | ... N33: =AC33 -> #N/A | T33: DDR5 32GB RDIMM* | U33: =AVERAGEIF(DRAM!$BQ:$BQ,N_Summary!AA$4,DRAM!$CO:$CO)/32 -> 7.03125 | V33: =AVERAGEIF(DRAM!$BQ:$BQ,N_Summary!AB$4,DRAM!$CO:$CO)/32 -> 13.71875 | W33: =V33/U33-1 -> 0.95111111 | X33: =INDEX(DRAM!$CE:$CW,MATCH(N_Summary!AC$3,DRAM!$CA:$CA,0),MATCH($T33,DRAM!$CE$28:$CW$28,0))/32 -> 20.25 | Y33: =INDEX(DRAM!$CE:$CW,MATCH(N_Summary!AD$3,DRAM!$CA:$CA,0),MATCH($T33,DRAM!$CE$28:$CW$28,0))/32 -> 20.90625 | Z33: =INDEX(DRAM!$CE:$CW,MATCH(N_Summary!AE$3,DRAM!$CA:$CA,0),MATCH($T33,DRAM!$CE$28:$CW$28,0))/32 -> #N/A | AA33: =X33/$V33-1 -> 0.476082 | AB33: =Y33/$V33-1 -> 0.523918 | AC33: =Z33/$V33-1 -> #N/A
E34: =T34 -> DDR4 32GB RDIMM* | F34: =U34 -> 6.84375 | G34: =V34 -> 13.5 | H34: =W34 -> 0.97260274 | I34: =X34 -> 20.625 | J34: =Y34 -> 20.625 | K34: =Z34 -> #N/A | L34: =AA34 -> 0.52777778 | ... N34: =AC34 -> #N/A | T34: DDR4 32GB RDIMM* | U34: =AVERAGEIF(DRAM!$BQ:$BQ,N_Summary!AA$4,DRAM!$CE:$CE)/32 -> 6.84375 | V34: =AVERAGEIF(DRAM!$BQ:$BQ,N_Summary!AB$4,DRAM!$CE:$CE)/32 -> 13.5 | W34: =V34/U34-1 -> 0.97260274 | X34: =INDEX(DRAM!$CE:$CW,MATCH(N_Summary!AC$3,DRAM!$CA:$CA,0),MATCH($T34,DRAM!$CE$28:$CW$28,0))/32 -> 20.625 | Y34: =INDEX(DRAM!$CE:$CW,MATCH(N_Summary!AD$3,DRAM!$CA:$CA,0),MATCH($T34,DRAM!$CE$28:$CW$28,0))/32 -> 20.625 | Z34: =INDEX(DRAM!$CE:$CW,MATCH(N_Summary!AE3,DRAM!$CA:$CA,0),MATCH($T34,DRAM!$CE$28:$CW$28,0))/32 -> #N/A | AA34: =X34/$V34-1 -> 0.52777778 | AB34: =Y34/$V34-1 -> 0.52777778 | AC34: =Z34/$V34-1 -> #N/A
C36: =R36 -> Mobile DRAM | E36: =T36 -> LPDDR5 16GB Discrete | F36: =U36 -> 3.9964418 | G36: =V36 -> 6.3261351 | H36: =W36 -> 0.5829419 | I36: =X36 -> 11.425 | L36: =AA36 -> 0.806 | P36: =AVERAGE(AA36:AC39) -> 0.76075 | Q36: 0.37493586 | R36: Mobile DRAM | T36: LPDDR5 16GB Discrete | U36: =INDEX(DRAM!$EB:$EH,MATCH(AA$4,DRAM!$EA:$EA,0),MATCH($T36,DRAM!$EB$28:$EH$28,0))/16 -> 3.9964418 | V36: =INDEX(DRAM!$EB:$EH,MATCH(AB$4,DRAM!$EA:$EA,0),MATCH($T36,DRAM!$EB$28:$EH$28,0))/16 -> 6.3261351 | W36: =V36/U36-1 -> 0.5829419 | X36: =INDEX(DRAM!$EB:$EH,MATCH(N_Summary!$AC$4,DRAM!$EA:$EA,0),MATCH($T36,DRAM!$EB$28:$EH$28,0))/16 -> 11.425 | AA36: =X36/V36-1 -> 0.806 | AD36: =AVERAGE(U36:U37)*AD44+AVERAGE(U38:U39)*(1-AD44) -> 3.9734359 | AE36: =AVERAGE(V36:V37)*AE44+AVERAGE(V38:V39)*(1-AE44) -> 6.28287 | AF36: =AVERAGE(X36:X37)*AF44+AVERAGE(X38:X39)*(1-AF44) -> 11.186642
E37: =T37 -> LPDDR5 12GB Discrete | F37: =U37 -> 3.99754 | G37: =V37 -> 6.3401776 | H37: =W37 -> 0.58601981 | I37: =X37 -> 11.425 | L37: =AA37 -> 0.802 | T37: LPDDR5 12GB Discrete | U37: =INDEX(DRAM!$EC:$EH,MATCH(AA$4,DRAM!$EA:$EA,0),MATCH($T37,DRAM!$EC$28:$EH$28,0))/12 -> 3.99754 | V37: =INDEX(DRAM!$EC:$EH,MATCH(AB$4,DRAM!$EA:$EA,0),MATCH($T37,DRAM!$EC$28:$EH$28,0))/12 -> 6.3401776 | W37: =V37/U37-1 -> 0.58601981 | X37: =INDEX(DRAM!$EC:$EH,MATCH(N_Summary!$AC$4,DRAM!$EA:$EA,0),MATCH($T37,DRAM!$EC$28:$EH$28,0))/12 -> 11.425 | AA37: =X37/V37-1 -> 0.802 | AE37: =AE36/AD36-1 -> 0.58121843 | AF37: =AF36/AE36-1 -> 0.78049866
E38: =T38 -> LPDDR4X 8GB Discrete | F38: =U38 -> 3.9333333 | G38: =V38 -> 6.1808387 | H38: =W38 -> 0.57139966 | I38: =X38 -> 10.6125 | L38: =AA38 -> 0.717 | T38: LPDDR4X 8GB Discrete | U38: =INDEX(DRAM!$EC:$EH,MATCH(AA$4,DRAM!$EA:$EA,0),MATCH($T38,DRAM!$EC$28:$EH$28,0))/8 -> 3.9333333 | V38: =INDEX(DRAM!$EC:$EH,MATCH(AB$4,DRAM!$EA:$EA,0),MATCH($T38,DRAM!$EC$28:$EH$28,0))/8 -> 6.1808387 | W38: =V38/U38-1 -> 0.57139966 | X38: =INDEX(DRAM!$EC:$EH,MATCH(N_Summary!$AC$4,DRAM!$EA:$EA,0),MATCH($T38,DRAM!$EC$28:$EH$28,0))/8 -> 10.6125 | AA38: =X38/V38-1 -> 0.717
E39: =T39 -> LPDDR4X 4GB Discrete | F39: =U39 -> 3.9333333 | G39: =V39 -> 6.1699651 | H39: =W39 -> 0.56863519 | I39: =X39 -> 10.6 | L39: =AA39 -> 0.718 | T39: LPDDR4X 4GB Discrete | U39: =INDEX(DRAM!$EC:$EH,MATCH(AA$4,DRAM!$EA:$EA,0),MATCH($T39,DRAM!$EC$28:$EH$28,0))/4 -> 3.9333333 | V39: =INDEX(DRAM!$EC:$EH,MATCH(AB$4,DRAM!$EA:$EA,0),MATCH($T39,DRAM!$EC$28:$EH$28,0))/4 -> 6.1699651 | W39: =V39/U39-1 -> 0.56863519 | X39: =INDEX(DRAM!$EC:$EH,MATCH(N_Summary!$AC$4,DRAM!$EA:$EA,0),MATCH($T39,DRAM!$EC$28:$EH$28,0))/4 -> 10.6 | AA39: =X39/V39-1 -> 0.718
E40: uMCP (LPDDR4X 64Gb+NAND 128GB)** | F40: =U40 -> 40.866703 | G40: =V40 -> 65.653153 | H40: =W40 -> 0.60651944 | I40: =X40 -> 116.6 | L40: =AA40 -> 0.776 | T40: LPDDR4X 128GB/64Gb uMCP | U40: =INDEX(DRAM!$EC:$EH,MATCH(AA$4,DRAM!$EA:$EA,0),MATCH($T40,DRAM!$EC$28:$EH$28,0)) -> 40.866703 | V40: =INDEX(DRAM!$EC:$EH,MATCH(AB$4,DRAM!$EA:$EA,0),MATCH($T40,DRAM!$EC$28:$EH$28,0)) -> 65.653153 | W40: =V40/U40-1 -> 0.60651944 | X40: =INDEX(DRAM!$EC:$EH,MATCH(N_Summary!$AC$4,DRAM!$EA:$EA,0),MATCH($T40,DRAM!$EC$28:$EH$28,0)) -> 116.6 | AA40: =X40/V40-1 -> 0.776
E41: eMCP (LPDDR4X 32Gb+NAND 64GB)** | F41: =U41 -> 20.901194 | G41: =V41 -> 34.831971 | H41: =W41 -> 0.66650625 | I41: =X41 -> 76.7 | L41: =AA41 -> 1.202 | T41: LPDDR4X 64GB/32Gb eMCP | U41: =INDEX(DRAM!$EC:$EH,MATCH(AA$4,DRAM!$EA:$EA,0),MATCH($T41,DRAM!$EC$28:$EH$28,0)) -> 20.901194 | V41: =INDEX(DRAM!$EC:$EH,MATCH(AB$4,DRAM!$EA:$EA,0),MATCH($T41,DRAM!$EC$28:$EH$28,0)) -> 34.831971 | W41: =V41/U41-1 -> 0.66650625 | X41: =INDEX(DRAM!$EC:$EH,MATCH(N_Summary!$AC$4,DRAM!$EA:$EA,0),MATCH($T41,DRAM!$EC$28:$EH$28,0)) -> 76.7 | AA41: =X41/V41-1 -> 1.202
C43: =R43 -> Specialty DRAM | E43: =T43 -> DDR4 4Gb | F43: =U43 -> 7 | G43: =V43 -> 12.666667 | H43: =W43 -> 0.80952381 | I43: =X43 -> 20 | J43: =Y43 -> 24 | K43: =Z43 -> #N/A | L43: =AA43 -> 0.57894737 | ... N43: =AC43 -> #N/A | P43: =AVERAGE(AA43:AA44) -> 0.62280702 | Q43: 0.15 | R43: Specialty DRAM | T43: DDR4 4Gb | U43: =AVERAGEIF(DRAM!$BQ:$BQ,N_Summary!AA$4,DRAM!$CQ:$CQ)*2 -> 7 | V43: =AVERAGEIF(DRAM!$BQ:$BQ,N_Summary!AB$4,DRAM!$CQ:$CQ)*2 -> 12.666667 | W43: =V43/U43-1 -> 0.80952381 | X43: =INDEX(DRAM!$CE:$CW,MATCH(N_Summary!AC3,DRAM!$CA:$CA,0),MATCH($T43,DRAM!$CE$28:$CW$28,0))/4*8 -> 20 | Y43: =INDEX(DRAM!$CE:$CW,MATCH(N_Summary!AD3,DRAM!$CA:$CA,0),MATCH($T43,DRAM!$CE$28:$CW$28,0))/4*8 -> 24 | Z43: =INDEX(DRAM!$CE:$CW,MATCH(N_Summary!AE3,DRAM!$CA:$CA,0),MATCH($T43,DRAM!$CE$28:$CW$28,0))/4*8 -> #N/A | AA43: =X43/$V43-1 -> 0.57894737 | AB43: =Y43/$V43-1 -> 0.89473684 | AC43: =Z43/$V43-1 -> #N/A
E44: =T44 -> DDR3 4Gb | F44: =U44 -> 5.9333333 | G44: =V44 -> 12 | H44: =W44 -> 1.0224719 | I44: =X44 -> 20 | J44: =Y44 -> 22 | K44: =Z44 -> #N/A | L44: =AA44 -> 0.66666667 | ... N44: =AC44 -> #N/A | P44: =SUMPRODUCT(P23:P43,Q23:Q43) -> 0.59969653 | T44: DDR3 4Gb | U44: =AVERAGEIF(DRAM!$BQ:$BQ,N_Summary!AA$4,DRAM!$CR:$CR)*2 -> 5.9333333 | V44: =AVERAGEIF(DRAM!$BQ:$BQ,N_Summary!AB$4,DRAM!$CR:$CR)*2 -> 12 | W44: =V44/U44-1 -> 1.0224719 | X44: =INDEX(DRAM!$CE:$CW,MATCH(N_Summary!AC3,DRAM!$CA:$CA,0),MATCH($T44,DRAM!$CE$28:$CW$28,0))/4*8 -> 20 | Y44: =INDEX(DRAM!$CE:$CW,MATCH(N_Summary!AD3,DRAM!$CA:$CA,0),MATCH($T44,DRAM!$CE$28:$CW$28,0))/4*8 -> 22 | Z44: =INDEX(DRAM!$CE:$CW,MATCH(N_Summary!AE3,DRAM!$CA:$CA,0),MATCH($T44,DRAM!$CE$28:$CW$28,0))/4*8 -> #N/A | AA44: =X44/$V44-1 -> 0.66666667 | AB44: =Y44/$V44-1 -> 0.83333333 | AC44: =Z44/$V44-1 -> #N/A | AD44: 0.62997325 | AE44: 0.68123678 | AF44: 0.7088753
C45: =R45 -> Weighted Average | F45: =U45 -> 5.449422 | G45: =V45 -> 10.121424 | H45: =W45 -> 0.85733893 | I45: =X45 -> 15.841155 | J45: =Y45 -> 16.561147 | K45: =Z45 -> #N/A | L45: =AA45 -> 0.56511133 | M45: =AB45 -> 0.63624674 | N45: =AC45 -> #N/A | R45: Weighted Average | U45: =SUM((R54*AVERAGE(U23:U24)+(1-R54)*(U25*U53+U27*(1-U53)))*$Q23,(AVERAGE(U29:U31)*U53+AVERAGE(U32)*(1-U53))*$Q29,AVERAGE(U36:U39)*$Q36,AVERAGE(U43:U44)*$Q43) -> 5.449422 | V45: =SUM((R54*AVERAGE(V23:V24)+(1-R54)*(V25*V53+V27*(1-V53)))*$Q23,(AVERAGE(V29:V31)*V53+AVERAGE(V32)*(1-V53))*$Q29,AVERAGE(V36:V39)*$Q36,AVERAGE(V43:V44)*$Q43) -> 10.121424 | W45: =V45/U45-1 -> 0.85733893 | X45: =SUM((R54*AVERAGE(X23:X24)+(1-R54)*(X25*X53+X27*(1-X53)))*$Q23,(AVERAGE(X29:X31)*X53+AVERAGE(X32)*(1-X53))*$Q29,AVERAGE(X36:X39)*$Q36,AVERAGE(X43:X44)*$Q43) -> 15.841155 | Y45: =SUM((R54*AVERAGE(Y23:Y24)+(1-R54)*(Y25*Y53+Y27*(1-Y53)))*$Q23,(AVERAGE(Y29:Y31)*Y53+AVERAGE(Y32)*(1-Y53))*$Q29,AVERAGE(X36:X39)*$Q36,AVERAGE(Y43:Y44)*$Q43) -> 16.561147 | Z45: =SUM((R54*AVERAGE(Z23:Z24)+(1-R54)*(Z25*Z53+Z27*(1-Z53)))*$Q23,(AVERAGE(Z29:Z31)*Z53+AVERAGE(Z32)*(1-Z53))*$Q29,AVERAGE(X36:X39)*$Q36,AVERAGE(Z43:Z44)*$Q43) -> #N/A | AA45: =X45/$V45-1 -> 0.56511133 | AB45: =Y45/$V45-1 -> 0.63624674 | AC45: =Z45/$V45-1 -> #N/A
P46: =SUMPRODUCT(P48:P50,Q48:Q50) -> -0.057905801
C47: Bernstein Estimate (Blended ASP, inc HBM)**** | Q47: 2025 Relative M/S | R47: Bernstein Estimate (Blended ASP, inc HBM)
...

Sheet DRAM
B19: Source: DRAMeXchange and Bernstein analysis
E20: Spot Price | BS20: Contract Price
DP21: For Exhibit
E22: Daily | S22: Daily | AH22: Weekly | AQ22: Weekly | BS22: Monthly | EA22: Quarterly
E25: Spot-PC DRAM DDR4_8Gb_1Gx8_2666/3200MHz | S25: Spot-PC DRAM DDR5_16Gb_2Gx8_4800/5600MHz | AH25: Spot-PC DRAM DDR4_8Gb_1Gx8_2666/3200MHz | AL25: Spot-PC DRAM DDR5_16Gb_2Gx8_4800/5600MHz | AQ25: Spot-Server DRAM | CA25: Price | CB25: DDR5 | CC25: DDR4 | DA25: =DQ27&" MoM" -> DDR4 32GB RDIMM MoM | DB25: =DR27&" MoM" -> DDR4 64GB RDIMM MoM | DK25: =DS27&" MoM" -> 32GB MoM | DL25: =DT27&" MoM" -> 64GB MoM | EA25: Price | FI25: eMCP LPDDR3 32GB + 24Gb | FP25: DDR2 1Gb, 128Mx8 800MHz | FU25: DDR2 1Gb, 128Mx8 800MHz | FZ25: DDR3 2Gb | GE25: DDR3 2Gb | GJ25: DDR3_4Gb_512Mx8_1600MHz | GO25: DDR3_4Gb_512Mx8_1600MHz
E26: DDR4 8Gb | N26: 1D/5D/15D Delta | S26: DDR5 16Gb | AB26: 1D/5D/15D Delta | AH26: DDR4 8Gb | AL26: DDR5 16Gb | AQ26: DRAM Server DRAM Average Spot Price (US$) | BB26: WoW | BS26: PC Die Contract Price (US$) | CA26: Average Contract Price (US$) | CT26: DDR5 vs. DDR4 | CX26: MoM | DA26: MoM | DQ26: Server Contract Price (US$/GB) | EA26: Average Contract Price (US$) | EJ26: QoQ | FI26: Mobile DRAM Contract | FP26: DDR2 1Gb Spot | FU26: DDR2 1Gb Contract | FZ26: DDR3 2Gb Spot | GE26: DDR3 2Gb Contract | GJ26: DDR3 4Gb Spot | GO26: DDR3 4Gb Contract
L27: Spot | Z27: Spot | AT27: Spot | AU27: Contract | AV27: Spot | AW27: Contract | AX27: Spot | AY27: Contract | AZ27: Spot | BA27: Contract | BB27: =AT28 -> DDR4 32GB RDIMM | BE27: =AV28 -> DDR4 64GB RDIMM | BH27: =AX28 -> DDR5 32GB RDIMM | BK27: =AZ28 -> DDR5 64GB RDIMM | BT27: DDR4_8Gb_1Gx8 | BV27: DDR4_8Gb_1Gx8 | BW27: DDR4_16Gb_2Gx8 | BX27: DDR5_16Gb_2Gx8 | CB27: PC | CC27: PC | CD27: PC | CE27: Server | CF27: Server | CG27: Server | CH27: Server | CI27: Server | CJ27: Server | CK27: Server | CL27: Server | CM27: Server | CN27: Server | CO27: Server | CP27: Server | CQ27: Specialty | CR27: Specialty | CX27: PC | CY27: PC | CZ27: PC | DA27: Server | DB27: Server | DC27: Server | DD27: Server | DE27: Server | DF27: Server | DG27: Server | DH27: Server | DI27: Server | DJ27: Server | DK27: Server | DL27: Server | DM27: Specialty | DN27: Specialty | DQ27: =DQ28 -> DDR4 32GB RDIMM | DR27: =DR28 -> DDR4 64GB RDIMM | DS27: 32GB | DT27: 64GB | DU27: 48GB | DV27: 96GB | DW27: 128GB | DX27: 128GB | EC27: Mobile | EE27: Mobile | EF27: Mobile | EG27: Mobile eMCP | EH27: Mobile uMCP
C28: Qtr | D28: Month | E28: Date | F28: Spot (US$/Gb) | G28: Contract (US$/Gb) | I28: Date | J28: High | K28: Low | L28: Avg | M28: Contract | N28: 1D Delta | O28: 1W Delta | P28: 2W Delta | Q28: Delta V.S. Contract | S28: Date | T28: Spot (US$/Gb) | U28: Contract (US$/Gb) | W28: Date | X28: High | Y28: Low | Z28: Avg | AA28: Contract | AB28: 1D Delta | AC28: 1W Delta | AD28: 2W Delta | AE28: Delta V.S. Contract | AH28: =I28 -> Date | AI28: =L28 -> Avg | AJ28: =O28 -> 1W Delta | AK28: =P28 -> 2W Delta | AL28: =M28 -> Contract | AM28: =AI28 -> Avg | AN28: =AJ28 -> 1W Delta | AO28: =AK28 -> 2W Delta | AQ28: Qtr | AR28: Month | AS28: Date | AT28: DDR4 32GB RDIMM | AU28: Contract Price | AV28: DDR4 64GB RDIMM | AW28: Contract Price | AX28: DDR5 32GB RDIMM | AY28: Contract Price | AZ28: DDR5 64GB RDIMM | BA28: Contract Price | BB28: 1W Delta | BC28: 2W Delta | BD28: 3W Delta | BE28: =BB28 -> 1W Delta | BF28: =BC28 -> 2W Delta | BG28: =BD28 -> 3W Delta | BH28: 1W Delta | BI28: 2W Delta | BJ28: 3W Delta | BK28: =BH28 -> 1W Delta | BL28: =BI28 -> 2W Delta | BM28: =BJ28 -> 3W Delta | BQ28: Qtr | BR28: Month | BS28: Date | BT28: High | BU28: Low | BV28: Avg | BW28: Avg | BX28: Avg | CA28: Date | CB28: DDR5 16GB UDIMM | CC28: DDR4 16GB UDIMM | CD28: DDR4 8GB UDIMM | CE28: DDR4 32GB RDIMM | CF28: DDR4 64GB RDIMM | CG28: DDR5 32GB RDIMM 5600Mbps | CH28: DDR5 64GB RDIMM 5600Mbps | CI28: DDR5 32GB RDIMM 4800Mbps | CJ28: DDR5 64GB RDIMM 4800Mbps | CK28: DDR5 48GB RDIMM | CL28: DDR5 96GB RDIMM | CM28: DDR5 128GB RDIMM (3DS) | CN28: DDR5 128GB RDIMM (non-3DS) | CO28: DDR5 32GB RDIMM | CP28: DDR5 64GB RDIMM | CQ28: DDR4 4Gb | CR28: DDR3 4Gb | CT28: DDR5 16GB UDIMM vs. DDR4 16GB UDIMM | CU28: DDR5 32GB RDIMM vs. DDR4 32GB RDIMM | CV28: DDR5 64GB RDIMM vs. DDR4 64GB RDIMM | CX28: DDR5 16GB UDIMM | CY28: DDR4 16GB UDIMM | CZ28: DDR4 UDIMM 8GB | DA28: =CE28 -> DDR4 32GB RDIMM | DB28: =CF28 -> DDR4 64GB RDIMM | DC28: DDR5 32GB RDIMM 5600Mbps | DD28: DDR5 64GB RDIMM 5600Mbps | DE28: DDR5 32GB RDIMM 4800Mbps | DF28: DDR5 64GB RDIMM 4800Mbps | DG28: DDR5 48GB RDIMM | DH28: DDR5 96GB RDIMM | DI28: DDR5 128GB RDIMM (3DS) | DJ28: DDR5 128GB RDIMM (non-3DS) | DK28: DDR5 32GB RDIMM | DL28: DDR5 64GB RDIMM | DM28: =CQ28 -> DDR4 4Gb | DN28: =CR28 -> DDR3 4Gb | DQ28: =DA28 -> DDR4 32GB RDIMM | DR28: =DB28 -> DDR4 64GB RDIMM | DS28: DDR5 32GB RDIMM | DT28: DDR5 64GB RDIMM | DU28: DDR5 48GB RDIMM | DV28: DDR5 96GB RDIMM | DW28: DDR5 128GB RDIMM (3DS) | DX28: DDR5 128GB RDIMM (non-3DS) | EA28: Date | EB28: LPDDR5 16GB discrete | EC28: LPDDR5 8GB discrete | ED28: LPDDR5 12GB discrete | EE28: LPDDR4X 8GB discrete | EF28: LPDDR4X 4GB discrete | EG28: LPDDR4X 64GB/32Gb eMCP | EH28: LPDDR4X 128GB/64Gb uMCP | EJ28: LPDDR5 16GB discrete | EK28: =EC28 -> LPDDR5 8GB discrete | EL28: LPDDR5 12GB discrete | EM28: =EE28 -> LPDDR4X 8GB discrete | EN28: =EF28 -> LPDDR4X 4GB discrete | EO28: =EG28 -> LPDDR4X 64GB/32Gb eMCP | EP28: =EH28 -> LPDDR4X 128GB/64Gb uMCP | FI28: Date | FJ28: High | FK28: Low | FL28: Avg | FP28: Date | FQ28: Avg | FR28: 8Gb Eq | FU28: Date | FV28: Avg | FW28: 8Gb Eq | FZ28: Date | GA28: Avg | GB28: 8Gb Eq | GE28: Date | GF28: Avg | GG28: 8Gb Eq | GJ28: Date | GK28: Avg | GL28: 8Gb Eq | GO28: Date | GP28: Avg | GQ28: 8Gb Eq
C29: {=_xlfn.IFS(MONTH(D29)<4,1,MONTH(D29)<7,2,MONTH(D29)<10,3,MONTH(D29)>9,4)&"Q"&RIGHT(YEAR(D29),2)} -> 1Q16 | D29: =EOMONTH(E29,0) -> 42429 | E29: =+I29 -> 42425 | F29: =+L29/8 -> 0.601875 | G29: =+M29/8 -> 0.42 | I29: 42425 | J29: 5.05 | K29: 4.6 | L29: 4.815 | M29: 3.36 | Q29: =L29/M29-1 -> 0.43303571 | AH29: =I30 -> 42426 | AI29: =IFERROR(VLOOKUP(AH29,$I:$L,4,FALSE),VLOOKUP(AH29,$I:$L,4,TRUE)) -> 4.813 | AQ29: {=_xlfn.IFS(MONTH(AR29)<4,1,MONTH(AR29)<7,2,MONTH(AR29)<10,3,MONTH(AR29)>9,4)&"Q"&RIGHT(YEAR(AR29),2)} -> 1Q19 | AR29: =EOMONTH(AS29,0) -> 43496 | AS29: 43479 | AU29: {=INDEX($CE$29:$CE$1449,MATCH($AR29,$CA$29:$CA$1449,0),)} -> 232.87 | AW29: {=INDEX($CF$29:$CF$1449,MATCH($AR29,$CA$29:$CA$1449,0),)} -> 475 | BQ29: {=_xlfn.IFS(MONTH(BR29)<4,1,MONTH(BR29)<7,2,MONTH(BR29)<10,3,MONTH(BR29)>9,4)&"Q"&RIGHT(YEAR(BR29),2)} -> 2Q16 | BR29: =EOMONTH(BS29,0) -> 42551 | BS29: 42551 | BT29: 3.06 | BU29: 2.81 | BV29: 2.94 | EA29: 3Q17 | EF29: 25.4 | FI29: =$EA29 -> 3Q17 | FN29: =YEAR(FP29) -> 2009 | FO29: =WEEKNUM(FP29) -> 5 | FP29: 39844 | FQ29: 0.91933333 | FR29: =FQ29*8 -> 7.3546667 | FS29: =YEAR(FU29) -> 2009 | FT29: =WEEKNUM(FU29) -> 5 | FU29: 39844 | FV29: 0.81 | FW29: =FV29*8 -> 6.48 | FX29: =YEAR(FZ29) -> 2010 | FY29: =WEEKNUM(FZ29) -> 40 | FZ29: 40450 | GA29: 4.15 | GB29: =GA29*4 -> 16.6 | GC29: =YEAR(GE29) -> 2010 | GD29: =WEEKNUM(GE29) -> 38 | GE29: 40436 | GF29: 4.34 | GG29: =GF29*4 -> 17.36 | GH29: =YEAR(GJ29) -> 2013 | GI29: =WEEKNUM(GJ29) -> 1 | GJ29: 41276 | GK29: 2.27 | GL29: =GK29*2 -> 4.54 | GM29: =YEAR(GO29) -> 2012 | GN29: =WEEKNUM(GO29) -> 48 | GO29: 41242 | GP29: 1.59 | GQ29: =GP29*2 -> 3.18
C30: {=_xlfn.IFS(MONTH(D30)<4,1,MONTH(D30)<7,2,MONTH(D30)<10,3,MONTH(D30)>9,4)&"Q"&RIGHT(YEAR(D30),2)} -> 1Q16 | D30: =EOMONTH(E30,0) -> 42429 | E30: =+I30 -> 42426 | F30: =+L30/8 -> 0.601625 | G30: =+M30/8 -> 0.42 | I30: 42426 | J30: 5.05 | K30: 4.6 | L30: 4.813 | M30: 3.36 | Q30: =L30/M30-1 -> 0.43244048 | AH30: =WORKDAY(AH29,6) -> 42436 | AI30: =IFERROR(VLOOKUP(AH30,$I:$L,4,FALSE),VLOOKUP(AH30,$I:$L,4,TRUE)) -> 4.707 | AJ30: =AI30/AI29-1 -> -0.022023686 | AQ30: {=_xlfn.IFS(MONTH(AR30)<4,1,MONTH(AR30)<7,2,MONTH(AR30)<10,3,MONTH(AR30)>9,4)&"Q"&RIGHT(YEAR(AR30),2)} -> 1Q19 | AR30: =EOMONTH(AS30,0) -> 43496 | AS30: 43493 | AU30: {=INDEX($CE$29:$CE$1449,MATCH($AR30,$CA$29:$CA$1449,0),)} -> 232.87 | AW30: {=INDEX($CF$29:$CF$1449,MATCH($AR30,$CA$29:$CA$1449,0),)} -> 475 | BQ30: {=_xlfn.IFS(MONTH(BR30)<4,1,MONTH(BR30)<7,2,MONTH(BR30)<10,3,MONTH(BR30)>9,4)&"Q"&RIGHT(YEAR(BR30),2)} -> 3Q16 | BR30: =EOMONTH(BS30,0) -> 42582 | BS30: =EOMONTH(BS29,1) -> 42582 | BT30: 3.06 | BU30: 2.94 | BV30: 3 | EA30: 4Q17 | EF30: 28.1 | EG30: 50.9 | FI30: =$EA30 -> 4Q17 | FL30: 32 | FN30: =YEAR(FP30) -> 2009 | FO30: =WEEKNUM(FP30) -> 9 | FP30: 39872 | FQ30: 1.0365 | FR30: =FQ30*8 -> 8.292 | FS30: =YEAR(FU30) -> 2009 | FT30: =WEEKNUM(FU30) -> 9 | FU30: 39872 | FV30: 0.88 | FW30: =FV30*8 -> 7.04 | FX30: =YEAR(FZ30) -> 2010 | FY30: =WEEKNUM(FZ30) -> 40 | FZ30: 40451 | GA30: 4.1 | GB30: =GA30*4 -> 16.4 | GC30: =YEAR(GE30) -> 2010 | GD30: =WEEKNUM(GE30) -> 40 | GE30: 40451 | GF30: 4.09 | GG30: =GF30*4 -> 16.36 | GH30: =YEAR(GJ30) -> 2013 | GI30: =WEEKNUM(GJ30) -> 1 | GJ30: 41277 | GK30: 2.291 | GL30: =GK30*2 -> 4.582 | GM30: =YEAR(GO30) -> 2012 | GN30: =WEEKNUM(GO30) -> 50 | GO30: 41257 | GP30: 1.63 | GQ30: =GP30*2 -> 3.26
C31: {=_xlfn.IFS(MONTH(D31)<4,1,MONTH(D31)<7,2,MONTH(D31)<10,3,MONTH(D31)>9,4)&"Q"&RIGHT(YEAR(D31),2)} -> 1Q16 | D31: =EOMONTH(E31,0) -> 42429 | E31: =+I31 -> 42429 | F31: =+L31/8 -> 0.599375 | G31: =+M31/8 -> 0.42 | I31: 42429 | J31: 5 | K31: 4.6 | L31: 4.795 | M31: 3.36 | Q31: =L31/M31-1 -> 0.42708333 | AH31: =WORKDAY(AH30,6) -> 42444 | AI31: =IFERROR(VLOOKUP(AH31,$I:$L,4,FALSE),VLOOKUP(AH31,$I:$L,4,TRUE)) -> 4.695 | AJ31: =AI31/AI30-1 -> -0.0025493945 | AK31: =AI31/AI29-1 -> -0.024516933 | AQ31: {=_xlfn.IFS(MONTH(AR31)<4,1,MONTH(AR31)<7,2,MONTH(AR31)<10,3,MONTH(AR31)>9,4)&"Q"&RIGHT(YEAR(AR31),2)} -> 1Q19 | AR31: =EOMONTH(AS31,0) -> 43524 | AS31: 43507 | AU31: {=INDEX($CE$29:$CE$1449,MATCH($AR31,$CA$29:$CA$1449,0),)} -> 209.58 | AW31: {=INDEX($CF$29:$CF$1449,MATCH($AR31,$CA$29:$CA$1449,0),)} -> 420 | BQ31: {=_xlfn.IFS(MONTH(BR31)<4,1,MONTH(BR31)<7,2,MONTH(BR31)<10,3,MONTH(BR31)>9,4)&"Q"&RIGHT(YEAR(BR31),2)} -> 3Q16 | BR31: =EOMONTH(BS31,0) -> 42613 | BS31: =EOMONTH(BS30,1) -> 42613 | BT31: 3.19 | BU31: 2.94 | BV31: 3.06 | EA31: 1Q18 | EF31: 29.6 | EG31: 53 | EN31: =EF31/EF30-1 -> 0.053380783 | EO31: =EG31/EG30-1 -> 0.041257367 | FI31: =$EA31 -> 1Q18 | FL31: 33.6 | FN31: =YEAR(FP31) -> 2009 | FO31: =WEEKNUM(FP31) -> 14 | FP31: 39903 | FQ31: 0.85636364 | FR31: =FQ31*8 -> 6.8509091 | FS31: =YEAR(FU31) -> 2009 | FT31: =WEEKNUM(FU31) -> 14 | FU31: 39903 | FV31: 0.88 | FW31: =FV31*8 -> 7.04 | FX31: =YEAR(FZ31) -> 2010 | FY31: =WEEKNUM(FZ31) -> 40 | FZ31: 40452 | GA31: 4.09 | GB31: =GA31*4 -> 16.36 | GC31: =YEAR(GE31) -> 2010 | GD31: =WEEKNUM(GE31) -> 42 | GE31: 40465 | GF31: 3.78 | GG31: =GF31*4 -> 15.12 | GH31: =YEAR(GJ31) -> 2013 | GI31: =WEEKNUM(GJ31) -> 1 | GJ31: 41278 | GK31: 2.294 | GL31: =GK31*2 -> 4.588 | GM31: =YEAR(GO31) -> 2012 | GN31: =WEEKNUM(GO31) -> 52 | GO31: 41271 | GP31: 1.66 | GQ31: =GP31*2 -> 3.32
C32: {=_xlfn.IFS(MONTH(D32)<4,1,MONTH(D32)<7,2,MONTH(D32)<10,3,MONTH(D32)>9,4)&"Q"&RIGHT(YEAR(D32),2)} -> 1Q16 | D32: =EOMONTH(E32,0) -> 42460 | E32: =+I32 -> 42430 | F32: =+L32/8 -> 0.58875 | G32: =+M32/8 -> 0.4032 | I32: 42430 | J32: 4.9 | K32: 4.6 | L32: 4.71 | M32: 3.2256 | Q32: =L32/M32-1 -> 0.46019345 | AH32: =WORKDAY(AH31,6) -> 42452 | AI32: =IFERROR(VLOOKUP(AH32,$I:$L,4,FALSE),VLOOKUP(AH32,$I:$L,4,TRUE)) -> 4.693 | AJ32: =AI32/AI31-1 -> -0.00042598509 | AK32: =AI32/AI30-1 -> -0.0029742936 | AQ32: {=_xlfn.IFS(MONTH(AR32)<4,1,MONTH(AR32)<7,2,MONTH(AR32)<10,3,MONTH(AR32)>9,4)&"Q"&RIGHT(YEAR(AR32),2)} -> 1Q19 | AR32: =EOMONTH(AS32,0) -> 43524 | AS32: 43514 | AU32: {=INDEX($CE$29:$CE$1449,MATCH($AR32,$CA$29:$CA$1449,0),)} -> 209.58 | AW32: {=INDEX($CF$29:$CF$1449,MATCH($AR32,$CA$29:$CA$1449,0),)} -> 420 | BQ32: {=_xlfn.IFS(MONTH(BR32)<4,1,MONTH(BR32)<7,2,MONTH(BR32)<10,3,MONTH(BR32)>9,4)&"Q"&RIGHT(YEAR(BR32),2)} -> 3Q16 | BR32: =EOMONTH(BS32,0) -> 42643 | BS32: =EOMONTH(BS31,1) -> 42643 | BT32: 3.44 | BU32: 3.19 | BV32: 3.31 | EA32: 2Q18 | EF32: 29.7 | EG32: 51 | EN32: =EF32/EF31-1 -> 0.0033783784 | EO32: =EG32/EG31-1 -> -0.037735849 | FI32: =$EA32 -> 2Q18 | FL32: 32.5 | FN32: =YEAR(FP32) -> 2009 | FO32: =WEEKNUM(FP32) -> 18 | FP32: 39933 | FQ32: 1.0977273 | FR32: =FQ32*8 -> 8.7818182 | FS32: =YEAR(FU32) -> 2009 | FT32: =WEEKNUM(FU32) -> 18 | FU32: 39933 | FV32: 0.91 | FW32: =FV32*8 -> 7.28 | FX32: =YEAR(FZ32) -> 2010 | FY32: =WEEKNUM(FZ32) -> 41 | FZ32: 40455 | GA32: 4.04 | GB32: =GA32*4 -> 16.16 | GC32: =YEAR(GE32) -> 2010 | GD32: =WEEKNUM(GE32) -> 44 | GE32: 40480 | GF32: 3.22 | GG32: =GF32*4 -> 12.88 | GH32: =YEAR(GJ32) -> 2013 | GI32: =WEEKNUM(GJ32) -> 2 | GJ32: 41281 | GK32: 2.296 | GL32: =GK32*2 -> 4.592 | GM32: =YEAR(GO32) -> 2013 | GN32: =WEEKNUM(GO32) -> 3 | GO32: 41289 | GP32: 1.84 | GQ32: =GP32*2 -> 3.68
C33: {=_xlfn.IFS(MONTH(D33)<4,1,MONTH(D33)<7,2,MONTH(D33)<10,3,MONTH(D33)>9,4)&"Q"&RIGHT(YEAR(D33),2)} -> 1Q16 | D33: =EOMONTH(E33,0) -> 42460 | E33: =+I33 -> 42431 | F33: =+L33/8 -> 0.5885 | G33: =+M33/8 -> 0.4032 | I33: 42431 | J33: 4.9 | K33: 4.6 | L33: 4.708 | M33: 3.2256 | Q33: =L33/M33-1 -> 0.45957341 | AH33: =WORKDAY(AH32,6) -> 42460 | AI33: =IFERROR(VLOOKUP(AH33,$I:$L,4,FALSE),VLOOKUP(AH33,$I:$L,4,TRUE)) -> 4.691 | AJ33: =AI33/AI32-1 -> -0.00042616663 | AK33: =AI33/AI31-1 -> -0.00085197018 | AQ33: {=_xlfn.IFS(MONTH(AR33)<4,1,MONTH(AR33)<7,2,MONTH(AR33)<10,3,MONTH(AR33)>9,4)&"Q"&RIGHT(YEAR(AR33),2)} -> 1Q19 | AR33: =EOMONTH(AS33,0) -> 43524 | AS33: 43521 | AU33: {=INDEX($CE$29:$CE$1449,MATCH($AR33,$CA$29:$CA$1449,0),)} -> 209.58 | AW33: {=INDEX($CF$29:$CF$1449,MATCH($AR33,$CA$29:$CA$1449,0),)} -> 420 | BQ33: {=_xlfn.IFS(MONTH(BR33)<4,1,MONTH(BR33)<7,2,MONTH(BR33)<10,3,MONTH(BR33)>9,4)&"Q"&RIGHT(YEAR(BR33),2)} -> 4Q16 | BR33: =EOMONTH(BS33,0) -> 42674 | BS33: =EOMONTH(BS32,1) -> 42674 | BT33: 4.13 | BU33: 3.94 | BV33: 4.06 | EA33: 3Q18 | EF33: 29.7 | EG33: 51 | EN33: =EF33/EF32-1 -> 0 | EO33: =EG33/EG32-1 -> 0 | FI33: =$EA33 -> 3Q18 | FL33: 31.6 | FN33: =YEAR(FP33) -> 2009 | FO33: =WEEKNUM(FP33) -> 23 | FP33: 39964 | FQ33: 1.2321053 | FR33: =FQ33*8 -> 9.8568421 | FS33: =YEAR(FU33) -> 2009 | FT33: =WEEKNUM(FU33) -> 23 | FU33: 39964 | FV33: 1.095 | FW33: =FV33*8 -> 8.76 | FX33: =YEAR(FZ33) -> 2010 | FY33: =WEEKNUM(FZ33) -> 41 | FZ33: 40456 | GA33: 4.02 | GB33: =GA33*4 -> 16.08 | GC33: =YEAR(GE33) -> 2010 | GD33: =WEEKNUM(GE33) -> 47 | GE33: 40497 | GF33: 2.97 | GG33: =GF33*4 -> 11.88 | GH33: =YEAR(GJ33) -> 2013 | GI33: =WEEKNUM(GJ33) -> 2 | GJ33: 41282 | GK33: 2.296 | GL33: =GK33*2 -> 4.592 | GM33: =YEAR(GO33) -> 2013 | GN33: =WEEKNUM(GO33) -> 5 | GO33: 41303 | GP33: 1.91 | GQ33: =GP33*2 -> 3.82
C34: {=_xlfn.IFS(MONTH(D34)<4,1,MONTH(D34)<7,2,MONTH(D34)<10,3,MONTH(D34)>9,4)&"Q"&RIGHT(YEAR(D34),2)} -> 1Q16 | D34: =EOMONTH(E34,0) -> 42460 | E34: =+I34 -> 42432 | F34: =+L34/8 -> 0.588375 | G34: =+M34/8 -> 0.4032 | I34: 42432 | J34: 4.9 | K34: 4.6 | L34: 4.707 | M34: 3.2256 | Q34: =L34/M34-1 -> 0.45926339 | AH34: =WORKDAY(AH33,6) -> 42468 | AI34: =IFERROR(VLOOKUP(AH34,$I:$L,4,FALSE),VLOOKUP(AH34,$I:$L,4,TRUE)) -> 4.688 | AJ34: =AI34/AI33-1 -> -0.00063952249 | AK34: =AI34/AI32-1 -> -0.0010654166 | AQ34: {=_xlfn.IFS(MONTH(AR34)<4,1,MONTH(AR34)<7,2,MONTH(AR34)<10,3,MONTH(AR34)>9,4)&"Q"&RIGHT(YEAR(AR34),2)} -> 1Q19 | AR34: =EOMONTH(AS34,0) -> 43555 | AS34: 43528 | AU34: {=INDEX($CE$29:$CE$1449,MATCH($AR34,$CA$29:$CA$1449,0),)} -> 167.67 | AW34: {=INDEX($CF$29:$CF$1449,MATCH($AR34,$CA$29:$CA$1449,0),)} -> 340 | BQ34: {=_xlfn.IFS(MONTH(BR34)<4,1,MONTH(BR34)<7,2,MONTH(BR34)<10,3,MONTH(BR34)>9,4)&"Q"&RIGHT(YEAR(BR34),2)} -> 4Q16 | BR34: =EOMONTH(BS34,0) -> 42704 | BS34: =EOMONTH(BS33,1) -> 42704 | BT34: 4.31 | BU34: 4.06 | BV34: 4.19 | EA34: 4Q18 | EE34: 56.7 | EF34: 29 | EG34: 47.5 | EN34: =EF34/EF33-1 -> -0.023569024 | EO34: =EG34/EG33-1 -> -0.068627451 | FI34: =$EA34 -> 4Q18 | FL34: 30.5 | FN34: =YEAR(FP34) -> 2009 | FO34: =WEEKNUM(FP34) -> 27 | FP34: 39994 | FQ34: 1.125 | FR34: =FQ34*8 -> 9 | FS34: =YEAR(FU34) -> 2009 | FT34: =WEEKNUM(FU34) -> 27 | FU34: 39994 | FV34: 1.16 | FW34: =FV34*8 -> 9.28 | FX34: =YEAR(FZ34) -> 2010 | FY34: =WEEKNUM(FZ34) -> 41 | FZ34: 40457 | GA34: 3.98 | GB34: =GA34*4 -> 15.92 | GC34: =YEAR(GE34) -> 2010 | GD34: =WEEKNUM(GE34) -> 49 | GE34: 40512 | GF34: 2.59 | GG34: =GF34*4 -> 10.36 | GH34: =YEAR(GJ34) -> 2013 | GI34: =WEEKNUM(GJ34) -> 2 | GJ34: 41283 | GK34: 2.296 | GL34: =GK34*2 -> 4.592 | GM34: =YEAR(GO34) -> 2013 | GN34: =WEEKNUM(GO34) -> 9 | GO34: 41330 | GP34: 2.16 | GQ34: =GP34*2 -> 4.32
C35: {=_xlfn.IFS(MONTH(D35)<4,1,MONTH(D35)<7,2,MONTH(D35)<10,3,MONTH(D35)>9,4)&"Q"&RIGHT(YEAR(D35),2)} -> 1Q16 | D35: =EOMONTH(E35,0) -> 42460 | E35: =+I35 -> 42433 | F35: =+L35/8 -> 0.588375 | G35: =+M35/8 -> 0.4032 | I35: 42433 | J35: 4.9 | K35: 4.6 | L35: 4.707 | M35: 3.2256 | Q35: =L35/M35-1 -> 0.45926339 | AH35: =WORKDAY(AH34,6) -> 42478 | AI35: =IFERROR(VLOOKUP(AH35,$I:$L,4,FALSE),VLOOKUP(AH35,$I:$L,4,TRUE)) -> 4.686 | AJ35: =AI35/AI34-1 -> -0.00042662116 | AK35: =AI35/AI33-1 -> -0.0010658708 | AQ35: {=_xlfn.IFS(MONTH(AR35)<4,1,MONTH(AR35)<7,2,MONTH(AR35)<10,3,MONTH(AR35)>9,4)&"Q"&RIGHT(YEAR(AR35),2)} -> 1Q19 | AR35: =EOMONTH(AS35,0) -> 43555 | AS35: 43535 | AU35: {=INDEX($CE$29:$CE$1449,MATCH($AR35,$CA$29:$CA$1449,0),)} -> 167.67 | AW35: {=INDEX($CF$29:$CF$1449,MATCH($AR35,$CA$29:$CA$1449,0),)} -> 340 | BQ35: {=_xlfn.IFS(MONTH(BR35)<4,1,MONTH(BR35)<7,2,MONTH(BR35)<10,3,MONTH(BR35)>9,4)&"Q"&RIGHT(YEAR(BR35),2)} -> 4Q16 | BR35: =EOMONTH(BS35,0) -> 42735 | BS35: =EOMONTH(BS34,1) -> 42735 | BT35: 4.31 | BU35: 4.06 | BV35: 4.19 | EA35: 1Q19 | EE35: 50 | EF35: 25.5 | EG35: 37.6 | EM35: =EE35/EE34-1 -> -0.11816578 | EN35: =EF35/EF34-1 -> -0.12068966 | EO35: =EG35/EG34-1 -> -0.20842105 | FI35: =$EA35 -> 1Q19 | FL35: 25.6 | FN35: =YEAR(FP35) -> 2009 | FO35: =WEEKNUM(FP35) -> 31 | FP35: 40025 | FQ35: 1.1717391 | FR35: =FQ35*8 -> 9.373913 | FS35: =YEAR(FU35) -> 2009 | FT35: =WEEKNUM(FU35) -> 31 | FU35: 40025 | FV35: 1.19 | FW35: =FV35*8 -> 9.52 | FX35: =YEAR(FZ35) -> 2010 | FY35: =WEEKNUM(FZ35) -> 41 | FZ35: 40458 | GA35: 3.93 | GB35: =GA35*4 -> 15.72 | GC35: =YEAR(GE35) -> 2010 | GD35: =WEEKNUM(GE35) -> 50 | GE35: 40522 | GF35: 2.34 | GG35: =GF35*4 -> 9.36 | GH35: =YEAR(GJ35) -> 2013 | GI35: =WEEKNUM(GJ35) -> 2 | GJ35: 41284 | GK35: 2.293 | GL35: =GK35*2 -> 4.586 | GM35: =YEAR(GO35) -> 2013 | GN35: =WEEKNUM(GO35) -> 11 | GO35: 41348 | GP35: 2.56 | GQ35: =GP35*2 -> 5.12
C36: {=_xlfn.IFS(MONTH(D36)<4,1,MONTH(D36)<7,2,MONTH(D36)<10,3,MONTH(D36)>9,4)&"Q"&RIGHT(YEAR(D36),2)} -> 1Q16 | D36: =EOMONTH(E36,0) -> 42460 | E36: =+I36 -> 42436 | F36: =+L36/8 -> 0.588375 | G36: =+M36/8 -> 0.4032 | I36: 42436 | J36: 4.9 | K36: 4.6 | L36: 4.707 | M36: 3.2256 | Q36: =L36/M36-1 -> 0.45926339 | AH36: =WORKDAY(AH35,6) -> 42486 | AI36: =IFERROR(VLOOKUP(AH36,$I:$L,4,FALSE),VLOOKUP(AH36,$I:$L,4,TRUE)) -> 4.676 | AJ36: =AI36/AI35-1 -> -0.0021340162 | AK36: =AI36/AI34-1 -> -0.002559727 | AQ36: {=_xlfn.IFS(MONTH(AR36)<4,1,MONTH(AR36)<7,2,MONTH(AR36)<10,3,MONTH(AR36)>9,4)&"Q"&RIGHT(YEAR(AR36),2)} -> 1Q19 | AR36: =EOMONTH(AS36,0) -> 43555 | AS36: 43542 | AU36: {=INDEX($CE$29:$CE$1449,MATCH($AR36,$CA$29:$CA$1449,0),)} -> 167.67 | AW36: {=INDEX($CF$29:$CF$1449,MATCH($AR36,$CA$29:$CA$1449,0),)} -> 340 | BQ36: {=_xlfn.IFS(MONTH(BR36)<4,1,MONTH(BR36)<7,2,MONTH(BR36)<10,3,MONTH(BR36)>9,4)&"Q"&RIGHT(YEAR(BR36),2)} -> 1Q17 | BR36: =EOMONTH(BS36,0) -> 42766 | BS36: =EOMONTH(BS35,1) -> 42766 | BT36: 5.94 | BU36: 5.44 | BV36: 5.69 | EA36: 2Q19 | EE36: 42.9 | EF36: 22 | EG36: 29.5 | EM36: =EE36/EE35-1 -> -0.142 | EN36: =EF36/EF35-1 -> -0.1372549 | EO36: =EG36/EG35-1 -> -0.21542553 | FI36: =$EA36 -> 2Q19 | FL36: 20.6 | FN36: =YEAR(FP36) -> 2009 | FO36: =WEEKNUM(FP36) -> 36 | FP36: 40056 | FQ36: 1.47 | FR36: =FQ36*8 -> 11.76 | FS36: =YEAR(FU36) -> 2009 | FT36: =WEEKNUM(FU36) -> 36 | FU36: 40056 | FV36: 1.375 | FW36: =FV36*8 -> 11 | FX36: =YEAR(FZ36) -> 2010 | FY36: =WEEKNUM(FZ36) -> 41 | FZ36: 40459 | GA36: 3.89 | GB36: =GA36*4 -> 15.56 | GC36: =YEAR(GE36) -> 2010 | GD36: =WEEKNUM(GE36) -> 52 | GE36: 40533 | GF36: 2.09 | GG36: =GF36*4 -> 8.36 | GH36: =YEAR(GJ36) -> 2013 | GI36: =WEEKNUM(GJ36) -> 2 | GJ36: 41285 | GK36: 2.296 | GL36: =GK36*2 -> 4.592 | GM36: =YEAR(GO36) -> 2013 | GN36: =WEEKNUM(GO36) -> 13 | GO36: 41362 | GP36: 2.63 | GQ36: =GP36*2 -> 5.26
C37: {=_xlfn.IFS(MONTH(D37)<4,1,MONTH(D37)<7,2,MONTH(D37)<10,3,MONTH(D37)>9,4)&"Q"&RIGHT(YEAR(D37),2)} -> 1Q16 | D37: =EOMONTH(E37,0) -> 42460 | E37: =+I37 -> 42437 | F37: =+L37/8 -> 0.588375 | G37: =+M37/8 -> 0.4032 | I37: 42437 | J37: 4.9 | K37: 4.6 | L37: 4.707 | M37: 3.2256 | Q37: =L37/M37-1 -> 0.45926339 | AH37: =WORKDAY(AH36,6) -> 42494 | AI37: =IFERROR(VLOOKUP(AH37,$I:$L,4,FALSE),VLOOKUP(AH37,$I:$L,4,TRUE)) -> 4.67 | AJ37: =AI37/AI36-1 -> -0.001283148 | AK37: =AI37/AI35-1 -> -0.0034144259 | AQ37: {=_xlfn.IFS(MONTH(AR37)<4,1,MONTH(AR37)<7,2,MONTH(AR37)<10,3,MONTH(AR37)>9,4)&"Q"&RIGHT(YEAR(AR37),2)} -> 1Q19 | AR37: =EOMONTH(AS37,0) -> 43555 | AS37: 43549 | AU37: {=INDEX($CE$29:$CE$1449,MATCH($AR37,$CA$29:$CA$1449,0),)} -> 167.67 | AW37: {=INDEX($CF$29:$CF$1449,MATCH($AR37,$CA$29:$CA$1449,0),)} -> 340 | BQ37: {=_xlfn.IFS(MONTH(BR37)<4,1,MONTH(BR37)<7,2,MONTH(BR37)<10,3,MONTH(BR37)>9,4)&"Q"&RIGHT(YEAR(BR37),2)} -> 1Q17 | BR37: =EOMONTH(BS37,0) -> 42794 | BS37: =EOMONTH(BS36,1) -> 42794 | BT37: 6.06 | BU37: 5.56 | BV37: 5.81 | EA37: 3Q19 | EE37: 36.1 | EF37: 18.4 | EG37: 23.5 | EM37: =EE37/EE36-1 -> -0.15850816 | EN37: =EF37/EF36-1 -> -0.16363636 | EO37: =EG37/EG36-1 -> -0.20338983 | FI37: =$EA37 -> 3Q19 | FL37: 17.9 | FN37: =YEAR(FP37) -> 2009 | FO37: =WEEKNUM(FP37) -> 40 | FP37: 40086 | FQ37: 1.7936364 | FR37: =FQ37*8 -> 14.349091 | FS37: =YEAR(FU37) -> 2009 | FT37: =WEEKNUM(FU37) -> 40 | FU37: 40086 | FV37: 1.595 | FW37: =FV37*8 -> 12.76 | FX37: =YEAR(FZ37) -> 2010 | FY37: =WEEKNUM(FZ37) -> 42 | FZ37: 40462 | GA37: 3.88 | GB37: =GA37*4 -> 15.52 | GC37: =YEAR(GE37) -> 2011 | GD37: =WEEKNUM(GE37) -> 3 | GE37: 40553 | GF37: 1.97 | GG37: =GF37*4 -> 7.88 | GH37: =YEAR(GJ37) -> 2013 | GI37: =WEEKNUM(GJ37) -> 3 | GJ37: 41288 | GK37: 2.299 | GL37: =GK37*2 -> 4.598 | GM37: =YEAR(GO37) -> 2013 | GN37: =WEEKNUM(GO37) -> 15 | GO37: 41376 | GP37: 2.88 | GQ37: =GP37*2 -> 5.76
C38: {=_xlfn.IFS(MONTH(D38)<4,1,MONTH(D38)<7,2,MONTH(D38)<10,3,MONTH(D38)>9,4)&"Q"&RIGHT(YEAR(D38),2)} -> 1Q16 | D38: =EOMONTH(E38,0) -> 42460 | E38: =+I38 -> 42438 | F38: =+L38/8 -> 0.588 | G38: =+M38/8 -> 0.4032 | I38: 42438 | J38: 4.9 | K38: 4.6 | L38: 4.704 | M38: 3.2256 | Q38: =L38/M38-1 -> 0.45833333 | AH38: =WORKDAY(AH37,6) -> 42502 | AI38: =IFERROR(VLOOKUP(AH38,$I:$L,4,FALSE),VLOOKUP(AH38,$I:$L,4,TRUE)) -> 4.255 | AJ38: =AI38/AI37-1 -> -0.088865096 | AK38: =AI38/AI36-1 -> -0.090034217 | AQ38: {=_xlfn.IFS(MONTH(AR38)<4,1,MONTH(AR38)<7,2,MONTH(AR38)<10,3,MONTH(AR38)>9,4)&"Q"&RIGHT(YEAR(AR38),2)} -> 2Q19 | AR38: =EOMONTH(AS38,0) -> 43585 | AS38: 43556 | AU38: {=INDEX($CE$29:$CE$1449,MATCH($AR38,$CA$29:$CA$1449,0),)} -> 152.58 | AW38: {=INDEX($CF$29:$CF$1449,MATCH($AR38,$CA$29:$CA$1449,0),)} -> 320 | BQ38: {=_xlfn.IFS(MONTH(BR38)<4,1,MONTH(BR38)<7,2,MONTH(BR38)<10,3,MONTH(BR38)>9,4)&"Q"&RIGHT(YEAR(BR38),2)} -> 1Q17 | BR38: =EOMONTH(BS38,0) -> 42825 | BS38: =EOMONTH(BS37,1) -> 42825 | BT38: 6.06 | BU38: 5.56 | BV38: 5.81 | EA38: 4Q19 | EE38: 32.8 | EG38: 22.4 | EH38: 44.5 | EM38: =EE38/EE37-1 -> -0.091412742 | EO38: =EG38/EG37-1 -> -0.046808511 | FI38: =$EA38 -> 4Q19 | FL38: 17 | FN38: =YEAR(FP38) -> 2009 | FO38: =WEEKNUM(FP38) -> 44 | FP38: 40117 | FQ38: 2.4481818 | FR38: =FQ38*8 -> 19.585455 | FS38: =YEAR(FU38) -> 2009 | FT38: =WEEKNUM(FU38) -> 44 | FU38: 40117 | FV38: 1.92 | FW38: =FV38*8 -> 15.36 | FX38: =YEAR(FZ38) -> 2010 | FY38: =WEEKNUM(FZ38) -> 42 | FZ38: 40463 | GA38: 3.87 | GB38: =GA38*4 -> 15.48 | GC38: =YEAR(GE38) -> 2011 | GD38: =WEEKNUM(GE38) -> 5 | GE38: 40567 | GF38: 1.84 | GG38: =GF38*4 -> 7.36 | GH38: =YEAR(GJ38) -> 2013 | GI38: =WEEKNUM(GJ38) -> 3 | GJ38: 41289 | GK38: 2.337 | GL38: =GK38*2 -> 4.674 | GM38: =YEAR(GO38) -> 2013 | GN38: =WEEKNUM(GO38) -> 18 | GO38: 41394 | GP38: 3 | GQ38: =GP38*2 -> 6
C39: {=_xlfn.IFS(MONTH(D39)<4,1,MONTH(D39)<7,2,MONTH(D39)<10,3,MONTH(D39)>9,4)&"Q"&RIGHT(YEAR(D39),2)} -> 1Q16 | D39: =EOMONTH(E39,0) -> 42460 | E39: =+I39 -> 42439 | F39: =+L39/8 -> 0.588 | G39: =+M39/8 -> 0.4032 | I39: 42439 | J39: 4.9 | K39: 4.6 | L39: 4.704 | M39: 3.2256 | Q39: =L39/M39-1 -> 0.45833333 | AH39: =WORKDAY(AH38,6) -> 42510 | AI39: =IFERROR(VLOOKUP(AH39,$I:$L,4,FALSE),VLOOKUP(AH39,$I:$L,4,TRUE)) -> 3.936 | AJ39: =AI39/AI38-1 -> -0.074970623 | AK39: =AI39/AI37-1 -> -0.15717345 | AQ39: {=_xlfn.IFS(MONTH(AR39)<4,1,MONTH(AR39)<7,2,MONTH(AR39)<10,3,MONTH(AR39)>9,4)&"Q"&RIGHT(YEAR(AR39),2)} -> 2Q19 | AR39: =EOMONTH(AS39,0) -> 43585 | AS39: 43563 | AU39: {=INDEX($CE$29:$CE$1449,MATCH($AR39,$CA$29:$CA$1449,0),)} -> 152.58 | AW39: {=INDEX($CF$29:$CF$1449,MATCH($AR39,$CA$29:$CA$1449,0),)} -> 320 | BQ39: {=_xlfn.IFS(MONTH(BR39)<4,1,MONTH(BR39)<7,2,MONTH(BR39)<10,3,MONTH(BR39)>9,4)&"Q"&RIGHT(YEAR(BR39),2)} -> 2Q17 | BR39: =EOMONTH(BS39,0) -> 42855 | BS39: =EOMONTH(BS38,1) -> 42855 | BT39: 6.56 | BU39: 6.44 | BV39: 6.5 | EA39: 1Q20 | EE39: 31.6 | EG39: 22.4 | EH39: 44 | EM39: =EE39/EE38-1 -> -0.036585366 | EO39: =EG39/EG38-1 -> 0 | EP39: =EH39/EH38-1 -> -0.011235955 | FI39: =$EA39 -> 1Q20 | FL39: 16.6 | FN39: =YEAR(FP39) -> 2009 | FO39: =WEEKNUM(FP39) -> 49 | FP39: 40147 | FQ39: 2.6319048 | FR39: =FQ39*8 -> 21.055238 | FS39: =YEAR(FU39) -> 2009 | FT39: =WEEKNUM(FU39) -> 49 | FU39: 40147 | FV39: 2.38 | FW39: =FV39*8 -> 19.04 | FX39: =YEAR(FZ39) -> 2010 | FY39: =WEEKNUM(FZ39) -> 42 | FZ39: 40464 | GA39: 3.87 | GB39: =GA39*4 -> 15.48 | GC39: =YEAR(GE39) -> 2011 | GD39: =WEEKNUM(GE39) -> 8 | GE39: 40589 | GF39: 1.84 | GG39: =GF39*4 -> 7.36 | GH39: =YEAR(GJ39) -> 2013 | GI39: =WEEKNUM(GJ39) -> 3 | GJ39: 41290 | GK39: 2.317 | GL39: =GK39*2 -> 4.634 | GM39: =YEAR(GO39) -> 2013 | GN39: =WEEKNUM(GO39) -> 20 | GO39: 41409 | GP39: 3.06 | GQ39: =GP39*2 -> 6.12
C40: {=_xlfn.IFS(MONTH(D40)<4,1,MONTH(D40)<7,2,MONTH(D40)<10,3,MONTH(D40)>9,4)&"Q"&RIGHT(YEAR(D40),2)} -> 1Q16 | D40: =EOMONTH(E40,0) -> 42460 | E40: =+I40 -> 42440 | F40: =+L40/8 -> 0.588 | G40: =+M40/8 -> 0.4032 | I40: 42440 | J40: 4.9 | K40: 4.6 | L40: 4.704 | M40: 3.2256 | Q40: =L40/M40-1 -> 0.45833333 | AH40: =WORKDAY(AH39,6) -> 42520 | AI40: =IFERROR(VLOOKUP(AH40,$I:$L,4,FALSE),VLOOKUP(AH40,$I:$L,4,TRUE)) -> 3.755 | AJ40: =AI40/AI39-1 -> -0.045985772 | AK40: =AI40/AI38-1 -> -0.11750881 | AQ40: {=_xlfn.IFS(MONTH(AR40)<4,1,MONTH(AR40)<7,2,MONTH(AR40)<10,3,MONTH(AR40)>9,4)&"Q"&RIGHT(YEAR(AR40),2)} -> 2Q19 | AR40: =EOMONTH(AS40,0) -> 43585 | AS40: 43570 | AU40: {=INDEX($CE$29:$CE$1449,MATCH($AR40,$CA$29:$CA$1449,0),)} -> 152.58 | AW40: {=INDEX($CF$29:$CF$1449,MATCH($AR40,$CA$29:$CA$1449,0),)} -> 320 | BQ40: {=_xlfn.IFS(MONTH(BR40)<4,1,MONTH(BR40)<7,2,MONTH(BR40)<10,3,MONTH(BR40)>9,4)&"Q"&RIGHT(YEAR(BR40),2)} -> 2Q17 | BR40: =EOMONTH(BS40,0) -> 42886 | BS40: =EOMONTH(BS39,1) -> 42886 | BT40: 6.56 | BU40: 6.44 | BV40: 6.5 | EA40: 2Q20 | EE40: 32.3 | EG40: 23 | EH40: 44.5 | EM40: =EE40/EE39-1 -> 0.022151899 | EO40: =EG40/EG39-1 -> 0.026785714 | EP40: =EH40/EH39-1 -> 0.011363636 | FI40: =$EA40 -> 2Q20 | FL40: 17.1 | FN40: =YEAR(FP40) -> 2009 | FO40: =WEEKNUM(FP40) -> 53 | FP40: 40178 | FQ40: 2.4308696 | FR40: =FQ40*8 -> 19.446957 | FS40: =YEAR(FU40) -> 2009 | FT40: =WEEKNUM(FU40) -> 53 | FU40: 40178 | FV40: 2.38 | FW40: =FV40*8 -> 19.04 | FX40: =YEAR(FZ40) -> 2010 | FY40: =WEEKNUM(FZ40) -> 42 | FZ40: 40465 | GA40: 3.87 | GB40: =GA40*4 -> 15.48 | GC40: =YEAR(GE40) -> 2011 | GD40: =WEEKNUM(GE40) -> 9 | GE40: 40597 | GF40: 1.84 | GG40: =GF40*4 -> 7.36 | GH40: =YEAR(GJ40) -> 2013 | GI40: =WEEKNUM(GJ40) -> 3 | GJ40: 41291 | GK40: 2.317 | GL40: =GK40*2 -> 4.634 | GM40: =YEAR(GO40) -> 2013 | GN40: =WEEKNUM(GO40) -> 22 | GO40: 41425 | GP40: 3.06 | GQ40: =GP40*2 -> 6.12
C41: {=_xlfn.IFS(MONTH(D41)<4,1,MONTH(D41)<7,2,MONTH(D41)<10,3,MONTH(D41)>9,4)&"Q"&RIGHT(YEAR(D41),2)} -> 1Q16 | D41: =EOMONTH(E41,0) -> 42460 | E41: =+I41 -> 42443 | F41: =+L41/8 -> 0.588 | G41: =+M41/8 -> 0.4032 | I41: 42443 | J41: 4.9 | K41: 4.6 | L41: 4.704 | M41: 3.2256 | Q41: =L41/M41-1 -> 0.45833333 | AH41: =WORKDAY(AH40,6) -> 42528 | AI41: =IFERROR(VLOOKUP(AH41,$I:$L,4,FALSE),VLOOKUP(AH41,$I:$L,4,TRUE)) -> 3.705 | AJ41: =AI41/AI40-1 -> -0.013315579 | AK41: =AI41/AI39-1 -> -0.058689024 | AQ41: {=_xlfn.IFS(MONTH(AR41)<4,1,MONTH(AR41)<7,2,MONTH(AR41)<10,3,MONTH(AR41)>9,4)&"Q"&RIGHT(YEAR(AR41),2)} -> 2Q19 | AR41: =EOMONTH(AS41,0) -> 43585 | AS41: 43577 | AU41: {=INDEX($CE$29:$CE$1449,MATCH($AR41,$CA$29:$CA$1449,0),)} -> 152.58 | AW41: {=INDEX($CF$29:$CF$1449,MATCH($AR41,$CA$29:$CA$1449,0),)} -> 320 | BQ41: {=_xlfn.IFS(MONTH(BR41)<4,1,MONTH(BR41)<7,2,MONTH(BR41)<10,3,MONTH(BR41)>9,4)&"Q"&RIGHT(YEAR(BR41),2)} -> 2Q17 | BR41: =EOMONTH(BS41,0) -> 42916 | BS41: =EOMONTH(BS40,1) -> 42916 | BT41: 6.56 | BU41: 6.44 | BV41: 6.5 | EA41: 3Q20 | EE41: 29.5 | EG41: 22 | EH41: 40.8 | EM41: =EE41/EE40-1 -> -0.086687307 | EO41: =EG41/EG40-1 -> -0.043478261 | EP41: =EH41/EH40-1 -> -0.083146067 | FI41: =$EA41 -> 3Q20 | FL41: 16.4 | FN41: =YEAR(FP41) -> 2010 | FO41: =WEEKNUM(FP41) -> 6 | FP41: 40209 | FQ41: 2.429 | FR41: =FQ41*8 -> 19.432 | FS41: =YEAR(FU41) -> 2010 | FT41: =WEEKNUM(FU41) -> 6 | FU41: 40209 | FV41: 2.38 | FW41: =FV41*8 -> 19.04 | FX41: =YEAR(FZ41) -> 2010 | FY41: =WEEKNUM(FZ41) -> 42 | FZ41: 40466 | GA41: 3.87 | GB41: =GA41*4 -> 15.48 | GC41: =YEAR(GE41) -> 2011 | GD41: =WEEKNUM(GE41) -> 11 | GE41: 40613 | GF41: 1.84 | GG41: =GF41*4 -> 7.36 | GH41: =YEAR(GJ41) -> 2013 | GI41: =WEEKNUM(GJ41) -> 3 | GJ41: 41292 | GK41: 2.317 | GL41: =GK41*2 -> 4.634 | GM41: =YEAR(GO41) -> 2013 | GN41: =WEEKNUM(GO41) -> 24 | GO41: 41439 | GP41: 3.09 | GQ41: =GP41*2 -> 6.18
