Workbook
Name africa: 0.01
Name africaCountries: #REF!
Name allRegions: #REF!
Name americaRegion: #REF!
Name americas: 0.16
Name americasStates: #REF!
Name AppVersion: "GEG-1.0"
Name asiaPacific: 0.73
Name asiaPacificExJapan: 0.26
Name asiaPacificExJapanCountries: #REF!
Name asiaPacificRegion: #REF!
Name asiaPacificStates: #REF!
Name australasia: 0.02
Name BRICS: 0.47
Name BSMethod: 2
Name Button_1: "TFT_report_data_share_prices_List"
Name cc_ReportCurrency: "NTD"
Name cc_ReportCurrencyUnit: "NT$"
Name cc_ReportCurrencyUnitFactor: 1
Name centralEasternEurope: 0.02
Name centralEasternEuropeCountries: #REF!
Name china: 0.4
Name Choices_Wrapper: Choices_Wrapper
Name consumerDemandExposure: #REF!
Name consumersExposure: 0
Name Conv_ITL: 1.93627
Name Conv_mark: 0
Name countryList: "Country Mapping"
Name DB: "WIREHKPROD"
Name developedEuropeExUK: 0.05
Name developedEuropeExUKCountries: #REF!
Name domesticAndForeignExposure: #REF!
Name domesticCostExposure: #REF!
Name DummyEstYears: 3
Name EEMEA: 0.04
Name endDemandExposure: #REF!
Name europe: 0.09
Name europeRegion: #REF!
Name europeStates: #REF!
Name EurosFRF: 1
Name EurosITL: 1
Name FINCriteriaType: 1
Name FR_COM_ABBR: "1122.HK"
Name FR_COU_ABBR: "chn"
Name FR_END_DATE: "'31 Dec 2001"
Name FR_START_DATE: "'1 Jan 2001"
Name FR_SYBASE_SERVER: "PTKFBVDF01"
Name FR_TEMPLATE_KEY: "110952|1"
Name ICP: 0
Name ictsymbol: "NT$"
Name icusymbol: "NT$"
Name india: 0.05
Name instructions: #REF!
Name ISMethod: 1
Name italy: 0.01
Name iue: 1
Name iuesymbol: "NT$"
Name iun: 1000000
Name iunsymbol: "NT$m"
Name ius: 1000000

Sheet ImportantDisclosures
A2: 1 Austin Road West
A3: Kowloon
A4: Hong Kong
A5: Tel: +852 2848 5200
A7: Authors: Daniel Yen,Charlie Chan
A8: Date: 16 Jul 2026
A10: Ticker: 688008.SS
A11: Stock Rating: Overweight
A12: Industry: Greater China Technology Semiconductors
A13: Industry View: Attractive
A14: Price as of 16 Jul 2026: 233.50
A15: Target Price: 377.00
... A143: Equal-weight and Not-Rated to hold and Underweight to sell recommendations, respectively.
B145: Coverage Universe | D145: Investment Banking Clients (IBC) | G145: Other Material Investment Services Clients (MISC)
A146: Stock Rating Category | B146: Count | C146: % of Total | D146: Count | E146: % of Total IBC | F146: % of Rating Category | G146: Count | H146: % of Total Other MISC
A147: Overweight/Buy | B147: 1544 | C147: 0.42 | D147: 453 | E147: 0.49 | F147: 0.29 | G147: 757 | H147: 0.44
A148: Equal-weight/Hold | B148: 1577 | C148: 0.43 | D148: 390 | E148: 0.42 | F148: 0.25 | G148: 769 | H148: 0.44
A149: Not-Rated/Hold | B149: 3 | C149: 0 | D149: 1 | E149: 0 | F149: 0.33 | G149: 1 | H149: 0
A150: Underweight/Sell | B150: 544 | C150: 0.15 | D150: 89 | E150: 0.1 | F150: 0.16 | G150: 204 | H150: 0.12
A151: Total | B151: 3668 | D151: 933 | G151: 1731
A153: Data include common stock and ADRs currently assigned ratings. Investment Banking Clients are companies
A154: from whom Morgan Stanley received investment banking compensation in the last 12 months. Due to rounding
A155: off of decimals, the percentages provided in the "% of total" column may not add up to exactly 100
A156: percent.
A158: Analyst Stock Ratings
A160: Overweight (O). The stock's total return is expected to exceed the average total return of the analyst's
A161: industry (or industry team's) coverage universe, on a risk-adjusted basis, over the next 12-18 months.
A163: Equal-weight (E). The stock's total return is expected to be in line with the average total return of
A164: the analyst's industry (or industry team's) coverage universe, on a risk-adjusted basis, over the next
A165: 12-18 months.
A167: Not-Rated (NR). Currently the analyst does not have adequate conviction about the stock's total return
A168: relative to the average total return of the analyst's industry (or industry team's) coverage universe,
... A454: © Copyright 2026 Morgan Stanley

Sheet Earnings Model
A1: Montage Technology (688008.SS, 6809.HK)
C2: Quarterly Earnings Model
C3: FY Ends: Dec
A8: Rmb$ in million | D8: 1Q16 | E8: 2Q16 | F8: 3Q16 | G8: 4Q16 | H8: 1Q17 | I8: 2Q17 | J8: 3Q17 | K8: 4Q17 | L8: 1Q18 | M8: 2Q18 | N8: 3Q18 | O8: 4Q18 | P8: 1Q19 | Q8: 2Q19 | R8: 3Q19 | S8: 4Q19 | T8: 1Q20 | U8: 2Q20 | V8: 3Q20 | W8: 4Q20 | X8: 1Q21 | Y8: 2Q21 | Z8: 3Q21 | AA8: 4Q21 | AB8: 1Q22 | AC8: 2Q22 | AD8: 3Q22 | AE8: 4Q22 | AF8: 1Q23 | AG8: 2Q23 | AH8: 3Q23 | AI8: 4Q23 | AJ8: 1Q24 | AK8: 2Q24 | AL8: 3Q24 | AM8: 4Q24 | AN8: 1Q25 | AO8: 2Q25 | AP8: 3Q25 | AQ8: 4Q25 | AR8: 1Q26 | AS8: 2Q26E | AT8: 3Q26E | AU8: 4Q26E | AV8: 1Q27E | AW8: 2Q27E | AX8: 3Q27E | AY8: 4Q27E | AZ8: 1Q28E | BA8: 2Q28E | BB8: 3Q28E | BC8: 4Q28E | BG8: 2016 | BH8: 2017 | BI8: 2018 | BJ8: 2019 | BK8: 2020 | BL8: 2021 | BM8: 2022 | BN8: 2023 | BO8: 2024 | BP8: 2025 | BQ8: 2026E | BR8: 2027E | BS8: 2028E
A10: Total Revenues | P10: 404.7171 | Q10: 474.46152 | R10: 505.167 | S10: =+BJ10-SUM(P10:R10) -> 353.38938 | T10: 495.75248 | U10: =1089.57666842-T10 -> 593.82419 | V10: 378.87465 | W10: =BK10-SUM(T10:V10) -> 355.21424 | X10: 299.53 | Y10: 424.933 | Z10: 868.233 | AA10: 969.321 | AB10: 900.423 | AC10: 1026.911 | AD10: 953.493 | AE10: 791.431 | AF10: 419.528 | AG10: 508.088 | AH10: 597.55 | AI10: 760.572 | AJ10: 737.263 | AK10: 927.715 | AL10: 905.892 | AM10: 1068.041 | AN10: 1222.209 | AO10: 1411.247 | AP10: =4057.68849-SUM(AN10:AO10) -> 1424.2325 | AQ10: =4057.68849-SUM(AO10:AP10) -> 1222.209 | AR10: 1460.718 | AS10: =AS128 -> 1773.9752 | AT10: =AT128 -> 1981.7557 | AU10: =AU128 -> 2300.23 | AV10: =AV128 -> 2575.9876 | AW10: =AW128 -> 3387.1186 | AX10: =AX128 -> 3766.2363 | AY10: =AY128 -> 4185.7417 | AZ10: =AZ128 -> 4425.0626 | ... BC10: =BC128 -> 5342.0619 | BG10: 844.945 | BH10: 1227.515 | BI10: 1757.665 | BJ10: 1737.735 | BK10: 1823.6656 | BL10: 2562.017 | BM10: 3672.258 | BN10: 2285.738 | BO10: 3638.911 | BP10: =SUM(AN10:AQ10) -> 5279.8975 | BQ10: =SUM(AR10:AU10) -> 7516.6789 | BR10: =SUM(AV10:AY10) -> 13915.084 | BS10: =SUM(AZ10:BC10) -> 19505.882 | BT10: =+(BS10/BP10)^(1/3)-1 -> 0.54589515 | CB10: =SUM(AY10:BF10) -> 23691.624
C11: Sequential Change | Q11: =Q10/P10-1 -> 0.17232884 | R11: =R10/Q10-1 -> 0.064716473 | S11: =S10/R10-1 -> -0.30045039 | T11: =T10/S10-1 -> 0.40285052 | U11: =U10/T10-1 -> 0.19782396 | V11: =V10/U10-1 -> -0.36197506 | W11: =W10/V10-1 -> -0.062449165 | X11: =X10/W10-1 -> -0.15676241 | ... BC11: =BC10/BB10-1 -> 0.063730423
C12: Change vs Year Ago | T12: =(T10/P10)-1 -> 0.22493584 | U12: =(U10/Q10)-1 -> 0.25157502 | V12: =(V10/R10)-1 -> -0.2500012 | W12: =(W10/S10)-1 -> 0.0051638837 | X12: =(X10/T10)-1 -> -0.39580735 | Y12: =(Y10/U10)-1 -> -0.28441278 | Z12: =(Z10/V10)-1 -> 1.2916102 | AA12: =(AA10/W10)-1 -> 1.7288349 | ... BC12: =(BC10/AY10)-1 -> 0.27625217 | BH12: =(BH10/BG10)-1 -> 0.45277503 | BI12: =(BI10/BH10)-1 -> 0.43188882 | BJ12: =(BJ10/BI10)-1 -> -0.011338907 | BK12: =(BK10/BJ10)-1 -> 0.049449747 | BL12: =(BL10/BK10)-1 -> 0.40487218 | BM12: =(BM10/BL10)-1 -> 0.43334646 | BN12: =(BN10/BM10)-1 -> -0.37756606 | BO12: =(BO10/BN10)-1 -> 0.59200705 | ... BS12: =(BS10/BR10)-1 -> 0.40177966
A14: Cost of Sales | P14: =96.2987357+0.0649224 -> 96.363658 | Q14: =232.11660141+0.081407-P14 -> 135.83435 | R14: 124.581 | S14: =+BJ14-SUM(P14:R14) -> 95.720992 | T14: =136.18547499+0.0481512 -> 136.23363 | U14: =286.60896514+0.71466679-T14 -> 151.09001 | V14: =111.43112144+0.34000907 -> 111.77113 | W14: =W10-W17 -> 108.59024 | X14: 106.571 | Y14: 165.872 | Z14: 544.91 | AA14: 522.55 | AB14: 511.572 | AC14: 592.189 | AD14: 518.224 | AE14: 344.762 | AF14: 195.955 | AG14: 209.184 | AH14: 210.361 | AI14: 323.717 | AJ14: 311.832 | AK14: 391.193 | AL14: 373.779 | AM14: 446.81 | AN14: 483.387 | AO14: 558.436 | AP14: =1563.885615-SUM(AN14:AO14) -> 522.06262 | AQ14: =1563.885615-SUM(AO14:AP14) -> 483.387 | AR14: 441.309 | AS14: =AS10-AS17 -> 572.72862 | AT14: =AT10-AT17 -> 626.5307 | AU14: =AU10-AU17 -> 708.35397 | AV14: =AV10-AV17 -> 779.45922 | AW14: =AW10-AW17 -> 985.08661 | AX14: =AX10-AX17 -> 1083.6408 | AY14: =AY10-AY17 -> 1193.5518 | AZ14: =AZ10-AZ17 -> 1254.7284 | ... BC14: =BC10-BC17 -> 1488.4563 | BG14: 412.309 | BH14: 570.952 | BI14: 517.734 | BJ14: 452.5 | BK14: =SUM(T14:W14) -> 507.685 | BL14: 1330.197 | BM14: 1966.747 | BN14: 939.216 | BO14: 1523.615 | BP14: =BP10-BP17 -> 2047.2726 | BQ14: =BQ10-BQ17 -> 2348.9223 | BR14: =BR10-BR17 -> 4041.7384 | BS14: =BS10-BS17 -> 5479.0973
C15: Percent of Revenues | P15: =P14/P10 -> 0.23810128 | Q15: =Q14/Q10 -> 0.2862916 | R15: =R14/R10 -> 0.2466135 | S15: =S14/S10 -> 0.2708655 | T15: =T14/T10 -> 0.27480171 | U15: =U14/U10 -> 0.25443558 | V15: =V14/V10 -> 0.29500821 | W15: =W14/W10 -> 0.3057035 | ... BC15: =BC14/BC10 -> 0.27862954 | BG15: =BG14/BG10 -> 0.48797141 | BH15: =BH14/BH10 -> 0.46512833 | BI15: =BI14/BI10 -> 0.29455784 | BJ15: =BJ14/BJ10 -> 0.26039644 | BK15: =BK14/BK10 -> 0.27838712 | BL15: =BL14/BL10 -> 0.51919913 | BM15: =BM14/BM10 -> 0.53556885 | BN15: =BN14/BN10 -> 0.41090274 | ... BS15: =BS14/BS10 -> 0.28089462
A17: Gross Profit | P17: =P10-P14 -> 308.35344 | Q17: =Q10-Q14 -> 338.62717 | R17: =R10-R14 -> 380.586 | S17: =S10-S14 -> 257.66839 | T17: =+T10-T14 -> 359.51885 | U17: =+U10-U14 -> 442.73419 | V17: =+V10-V14 -> 267.10352 | W17: =1823.665555-505.751-1.934-SUM(T17:V17) -> 246.624 | X17: =+X10-X14 -> 192.959 | Y17: =+Y10-Y14 -> 259.061 | Z17: =+Z10-Z14 -> 323.323 | AA17: =+AA10-AA14 -> 446.771 | AB17: =+AB10-AB14 -> 388.851 | AC17: =+AC10-AC14 -> 434.722 | AD17: =+AD10-AD14 -> 435.269 | AE17: =+AE10-AE14 -> 446.669 | ... AR17: =+AR10-AR14 -> 1019.409 | AS17: =+AS313 -> 1201.2466 | AT17: =+AT313 -> 1355.225 | AU17: =+AU313 -> 1591.876 | AV17: =+AV313 -> 1796.5284 | AW17: =+AW313 -> 2402.032 | AX17: =+AX313 -> 2682.5955 | AY17: =+AY313 -> 2992.1899 | AZ17: =+AZ313 -> 3170.3341 | ... BC17: =+BC313 -> 3853.6056 | BG17: =+BG10-BG14 -> 432.636 | BH17: =+BH10-BH14 -> 656.563 | BI17: =+BI10-BI14 -> 1239.931 | BJ17: =+BJ10-BJ14 -> 1285.235 | BK17: =SUM(T17:W17) -> 1315.9806 | BL17: =+BL10-BL14 -> 1231.82 | BM17: =+BM10-BM14 -> 1705.511 | BN17: =+BN10-BN14 -> 1346.522 | BO17: =+BO10-BO14 -> 2115.296 | BP17: =SUM(AN17:AQ17) -> 3232.6249 | BQ17: =SUM(AR17:AU17) -> 5167.7566 | BR17: =SUM(AV17:AY17) -> 9873.3458 | BS17: =SUM(AZ17:BC17) -> 14026.785
C18: Percent of Revenues | P18: =P17/P10 -> 0.76189872 | Q18: =Q17/Q10 -> 0.7137084 | R18: =R17/R10 -> 0.7533865 | S18: =S17/S10 -> 0.7291345 | T18: =T17/T10 -> 0.72519829 | U18: =U17/U10 -> 0.74556442 | V18: =V17/V10 -> 0.70499179 | W18: =W17/W10 -> 0.6942965 | ... BC18: =BC17/BC10 -> 0.72137046 | BG18: =BG17/BG10 -> 0.51202859 | BH18: =BH17/BH10 -> 0.53487167 | BI18: =BI17/BI10 -> 0.70544216 | BJ18: =BJ17/BJ10 -> 0.73960356 | BK18: =BK17/BK10 -> 0.72161288 | BL18: =BL17/BL10 -> 0.48080087 | BM18: =BM17/BM10 -> 0.46443115 | BN18: =BN17/BN10 -> 0.58909726 | ... BS18: =BS17/BS10 -> 0.71910538
C19: Incremental Margin | P19: =IF(P10-O10<=0," NM",(P17-O17)/(P10-O10)) -> 0.76189872 | Q19: =IF(Q10-P10<=0," NM",(Q17-P17)/(Q10-P10)) -> 0.43406672 | R19: =IF(R10-Q10<=0," NM",(R17-Q17)/(R10-Q10)) -> 1.3664933 | S19: =IF(S10-R10<=0," NM",(S17-R17)/(S10-R10)) -> NM | T19: =IF(T10-S10<=0," NM",(T17-S17)/(T10-S10)) -> 0.71542741 | U19: =IF(U10-T10<=0," NM",(U17-T17)/(U10-T10)) -> 0.84851515 | V19: =IF(V10-U10<=0," NM",(V17-U17)/(V10-U10)) -> NM | W19: =IF(W10-V10<=0," NM",(W17-V17)/(W10-V10)) -> NM | ... BC19: =IF(BC10-BB10<=0," NM",(BC17-BB17)/(BC10-BB10)) -> 0.74504252 | BJ19: =IF(BJ10-BI10<=0," NM",(BJ17-BI17)/(BJ10-BI10)) -> NM | BK19: =IF(BK10-BJ10<=0," NM",(BK17-BJ17)/(BK10-BJ10)) -> 0.35779537 | BL19: =IF(BL10-BK10<=0," NM",(BL17-BK17)/(BL10-BK10)) -> -0.11398441 | BM19: =IF(BM10-BL10<=0," NM",(BM17-BL17)/(BM10-BL10)) -> 0.42665601 | BN19: =IF(BN10-BM10<=0," NM",(BN17-BM17)/(BN10-BM10)) -> NM | BO19: =IF(BO10-BN10<=0," NM",(BO17-BN17)/(BO10-BN10)) -> 0.56812691 | BP19: =IF(BP10-BO10<=0," NM",(BP17-BO17)/(BP10-BO10)) -> 0.68088853 | BQ19: =IF(BQ10-BP10<=0," NM",(BQ17-BP17)/(BQ10-BP10)) -> 0.86514119 | ... BS19: =IF(BS10-BR10<=0," NM",(BS17-BR17)/(BS10-BR10)) -> 0.74290631
A21: Total Opex | P21: =SUM(P24,P27,P30) -> 64.346519 | Q21: =SUM(Q24,Q27,Q30) -> 188.14604 | R21: =SUM(R24,R27,R30) -> 80.331 | S21: =S24+S27+S30 -> 103.67444 | T21: =T24+T27+T30 -> 162.8856 | U21: =U24+U27+U30 -> 133.51274 | V21: =V24+V27+V30 -> 120.98195 | W21: =W24+W27+W30 -> 152.04138 | X21: =X24+X27+X30 -> 124.545 | Y21: =Y24+Y27+Y30 -> 139.587 | Z21: =Z24+Z27+Z30 -> 184.658 | ... BC21: =BC24+BC27+BC30 -> 729.91546 | BG21: =+BG24+BG27+BG30 -> 298.218 | BH21: =+BH24+BH27+BH30 -> 308.986 | BI21: =+BI24+BI27+BI30 -> 516.695 | BJ21: =BJ24+BJ27+BJ30 -> 436.498 | BK21: =BK24+BK27+BK30 -> 569.58594 | BL21: =BL24+BL27+BL30 -> 645.187 | BM21: =BM24+BM27+BM30 -> 852.042 | BN21: =BN24+BN27+BN30 -> 944.906 | BO21: =BO24+BO27+BO30 -> 1055.739 | BP21: =BP24+BP27+BP30 -> 1485.4573 | BQ21: =BQ24+BQ27+BQ30 -> 1520.0822 | ... BS21: =BS24+BS27+BS30 -> 2704.675
C22: Percent of Revenues | P22: =P21/P10 -> 0.15899135 | Q22: =Q21/Q10 -> 0.39654646 | R22: =R21/R10 -> 0.1590187 | S22: =S21/S10 -> 0.29337169 | T22: =T21/T10 -> 0.32856236 | U22: =U21/U10 -> 0.22483547 | V22: =V21/V10 -> 0.31931921 | W22: =W21/W10 -> 0.42802727 | ... BC22: =BC21/BC10 -> 0.13663553 | BG22: =BG21/BG10 -> 0.35294368 | BH22: =BH21/BH10 -> 0.25171668 | BI22: =BI21/BI10 -> 0.29396671 | BJ22: =BJ21/BJ10 -> 0.2511879 | BK22: =BK21/BK10 -> 0.31233026 | BL22: =BL21/BL10 -> 0.25182776 | BM22: =BM21/BM10 -> 0.23202128 | BN22: =BN21/BN10 -> 0.41339209 | ... BS22: =BS21/BS10 -> 0.13865945
C24: R&D | P24: 36.901363 | Q24: =150.11152879-P24 -> 113.21017 | R24: 46.824 | S24: =+BJ24-SUM(P24:R24) -> 69.919471 | T24: 97.089211 | U24: =164.33915917-T24 -> 67.249948 | V24: 54.531076 | W24: =299.881-SUM(T24:V24) -> 81.010765 | X24: 66.116 | Y24: 77.624 | Z24: 98.91 | AA24: 127.2 | AB24: 88.518 | AC24: 117.344 | AD24: 117.905 | AE24: 239.721 | AF24: 134.045 | AG24: 168.634 | AH24: 184.25 | AI24: 194.884 | AJ24: 176.044 | AK24: 190.672 | AL24: 185.566 | AM24: 211.188 | AN24: 153.058 | AO24: 204.014 | AP24: =533.160918-SUM(AN24:AO24) -> 176.08892 | AQ24: =533.160918-SUM(AO24:AP24) -> 153.058 | AR24: 188.139 | AS24: =+AR24+10 -> 198.139 | AT24: =+AS24+10 -> 208.139 | AU24: =+AT24+10 -> 218.139 | AV24: =+AU24+18 -> 236.139 | AW24: =+AV24+18 -> 254.139 | AX24: =+AW24+18 -> 272.139 | AY24: =+AX24+18 -> 290.139 | AZ24: =+AY24+18 -> 308.139 | BA24: =+AZ24+18 -> 326.139 | BB24: =+BA24+18 -> 344.139 | BC24: =+BB24+18 -> 362.139 | BG24: 198.227 | BH24: 188.269 | BI24: 276.695 | BJ24: 266.855 | BK24: =SUM(T24:W24) -> 299.881 | BL24: 369.85 | BM24: 563.487 | BN24: 681.812 | BO24: 763.47 | BP24: =SUM(AN24:AQ24) -> 686.21892 | BQ24: =SUM(AR24:AU24) -> 812.556 | BR24: =SUM(AV24:AY24) -> 1052.556 | BS24: =SUM(AZ24:BC24) -> 1340.556
C25: Percent of Revenues | P25: =P24/P10 -> 0.091178167 | Q25: =Q24/Q10 -> 0.23860768 | R25: =R24/R10 -> 0.09269014 | S25: =S24/S10 -> 0.19785391 | T25: =T24/T10 -> 0.19584211 | U25: =U24/U10 -> 0.11324892 | V25: =V24/V10 -> 0.14392907 | W25: =W24/W10 -> 0.2280617 | ... BC25: =BC24/BC10 -> 0.067790117 | BG25: =BG24/BG10 -> 0.23460344 | BH25: =BH24/BH10 -> 0.15337409 | BI25: =BI24/BI10 -> 0.15742192 | BJ25: =BJ24/BJ10 -> 0.15356484 | BK25: =BK24/BK10 -> 0.16443859 | BL25: =BL24/BL10 -> 0.14435892 | BM25: =BM24/BM10 -> 0.15344428 | BN25: =BN24/BN10 -> 0.29828966 | ... BS25: =BS24/BS10 -> 0.068725731
C27: General & administrative | P27: 14.729894 | Q27: =55.93711588-P27 -> 41.207221 | R27: 17.898 | S27: =+BJ27-SUM(P27:R27) -> 21.295884 | T27: 44.039237 | U27: =91.12973771-T27 -> 47.0905 | V27: 39.674929 | W27: =187.70494-SUM(T27:V27) -> 56.900273 | X27: 43.461 | Y27: 45.752 | Z27: 65.966 | AA27: 43.576 | AB27: 36.742 | AC27: 40.107 | AD27: 41.864 | AE27: 83.693 | AF27: 38.373 | AG27: 48.398 | AH27: 39.667 | AI27: 46.695 | AJ27: 39.768 | AK27: 39.787 | AL27: 42.315 | AM27: 74.393 | AN27: 101.875 | AO27: 119.744 | AP27: =591.436679-SUM(AN27:AO27) -> 369.81768 | AQ27: =591.436679-SUM(AO27:AP27) -> 101.875 | AR27: 127.382 | AS27: =+AS28*AS10 -> 138.99659 | AT27: =+AT28*AT10 -> 150.32246 | AU27: =+AU28*AU10 -> 168.72917 | AV27: =+AV28*AV10 -> 181.2289 | AW27: =+AW28*AW10 -> 228.13319 | AX27: =+AX28*AX10 -> 253.66797 | AY27: =+AY28*AY10 -> 281.92299 | AZ27: =+AZ28*AZ10 -> 284.76682 | ... BC27: =+BC28*BC10 -> 327.75246 | BG27: 47.754 | BH27: 51.79 | BI27: 112.784 | BJ27: 95.131 | BK27: =SUM(T27:W27) -> 187.70494 | BL27: 198.755 | BM27: 202.408 | BN27: 173.133 | BO27: 196.262 | BP27: =SUM(AN27:AQ27) -> 693.31168 | BQ27: =SUM(AR27:AU27) -> 585.43022 | BR27: =SUM(AV27:AY27) -> 944.95306 | BS27: =SUM(AZ27:BC27) -> 1210.023
C28: Percent of Revenues | P28: =P27/P10 -> 0.036395533 | Q28: =Q27/Q10 -> 0.086850502 | R28: =R27/R10 -> 0.035429868 | S28: =S27/S10 -> 0.060261811 | T28: =T27/T10 -> 0.088833116 | U28: =U27/U10 -> 0.079300408 | V28: =V27/V10 -> 0.10471783 | W28: =W27/W10 -> 0.16018579 | ... AQ28: =AQ27/AQ10 -> 0.083353174 | AR28: =+AQ28-0.25% -> 0.080853174 | AS28: =+AR28-0.25% -> 0.078353174 | AT28: =+AS28-0.25% -> 0.075853174 | AU28: =+AT28-0.25% -> 0.073353174 | AV28: =+AU28-0.3% -> 0.070353174 | AW28: =+AV28-0.3% -> 0.067353174 | AX28: =+AW28 -> 0.067353174 | AY28: =+AX28 -> 0.067353174 | AZ28: =+AY28-0.3% -> 0.064353174 | BA28: =+AZ28-0.3% -> 0.061353174 | BB28: =+BA28 -> 0.061353174 | BC28: =+BB28 -> 0.061353174 | BG28: =BG27/BG10 -> 0.056517288 | BH28: =BH27/BH10 -> 0.04219093 | BI28: =BI27/BI10 -> 0.064166949 | BJ28: =BJ27/BJ10 -> 0.05474425 | BK28: =BK27/BK10 -> 0.10292728 | BL28: =BL27/BL10 -> 0.077577549 | BM28: =BM27/BM10 -> 0.055118132 | BN28: =BN27/BN10 -> 0.075744902 | ... BS28: =BS27/BS10 -> 0.062033748
C30: Selling & marketing | P30: 12.715262 | Q30: =46.44391461-P30 -> 33.728653 | R30: 15.609 | S30: =+BJ30-SUM(P30:R30) -> 12.459085 | T30: 21.757154 | U30: =40.92944941-T30 -> 19.172296 | V30: 26.775946 | W30: =81.83573992-SUM(T30:V30) -> 14.130345 | X30: 14.968 | Y30: 16.211 | Z30: 19.782 | AA30: 25.621 | AB30: 15.058 | AC30: 21.272 | AD30: 22.986 | AE30: 26.832 | AF30: 20.645 | AG30: 24.859 | AH30: 20.497 | AI30: 23.96 | AJ30: 21.6 | AK30: 21.833 | AL30: 25.832 | AM30: 26.742 | AN30: 24.057 | AO30: 27.235 | AP30: =81.869692-SUM(AN30:AO30) -> 30.577692 | AQ30: =81.869692-SUM(AO30:AP30) -> 24.057 | AR30: 29.024 | AS30: =+AR30+1 -> 30.024 | AT30: =+AS30+1 -> 31.024 | AU30: =+AT30+1 -> 32.024 | AV30: =+AU30+1 -> 33.024 | AW30: =+AV30+1 -> 34.024 | AX30: =+AW30+1 -> 35.024 | AY30: =+AX30+1 -> 36.024 | AZ30: =+AY30+1 -> 37.024 | ... BC30: =+BB30+1 -> 40.024 | BG30: 52.237 | BH30: 68.927 | BI30: 127.216 | BJ30: 74.512 | BK30: 82 | BL30: 76.582 | BM30: 86.147 | BN30: 89.961 | BO30: 96.007 | BP30: =SUM(AN30:AQ30) -> 105.92669 | BQ30: =SUM(AR30:AU30) -> 122.096 | BR30: =SUM(AV30:AY30) -> 138.096 | BS30: =SUM(AZ30:BC30) -> 154.096
C31: Percent of Revenues | P31: =P30/P10 -> 0.031417654 | Q31: =Q30/Q10 -> 0.071088278 | R31: =R30/R10 -> 0.030898693 | S31: =S30/S10 -> 0.03525597 | T31: =T30/T10 -> 0.043887131 | U31: =U30/U10 -> 0.032286148 | V31: =V30/V10 -> 0.070672309 | W31: =W30/W10 -> 0.039779781 | ... BC31: =BC30/BC10 -> 0.0074922381 | BG31: =BG30/BG10 -> 0.061822959 | BH31: =BH30/BH10 -> 0.056151656 | BI31: =BI30/BI10 -> 0.072377842 | BJ31: =BJ30/BJ10 -> 0.042878805 | BK31: =BK30/BK10 -> 0.044964385 | BL31: =BL30/BL10 -> 0.029891293 | BM31: =BM30/BM10 -> 0.023458864 | BN31: =BN30/BN10 -> 0.039357529 | ... BS31: =BS30/BS10 -> 0.007899976
A33: Operating Income | P33: =P17-P21 -> 244.00692 | Q33: =Q17-Q21 -> 150.48113 | R33: =R17-R21 -> 300.255 | S33: =S17-S21 -> 153.99395 | T33: =T17-T21 -> 196.63325 | U33: =U17-U21 -> 309.22144 | V33: =V17-V21 -> 146.12156 | W33: =W17-W21 -> 94.582621 | ... BC33: =BC17-BC21 -> 3123.6902 | BG33: =BG17-BG21 -> 134.418 | BH33: =BH17-BH21 -> 347.577 | BI33: =BI17-BI21 -> 723.236 | BJ33: =BJ17-BJ21 -> 848.737 | BK33: =BK17-BK21 -> 746.39462 | BL33: =BL17-BL21 -> 586.633 | BM33: =BM17-BM21 -> 853.469 | BN33: =BN17-BN21 -> 401.616 | ... BS33: =BS17-BS21 -> 11322.11
C34: Percent of Revenues | P34: =P33/P10 -> 0.60290737 | Q34: =Q33/Q10 -> 0.31716193 | R34: =R33/R10 -> 0.5943678 | S34: =S33/S10 -> 0.4357628 | T34: =T33/T10 -> 0.39663594 | U34: =U33/U10 -> 0.52072894 | V34: =V33/V10 -> 0.38567259 | W34: =W33/W10 -> 0.26626922 | ... BC34: =BC33/BC10 -> 0.58473493 | BG34: =BG33/BG10 -> 0.15908491 | BH34: =BH33/BH10 -> 0.28315499 | BI34: =BI33/BI10 -> 0.41147545 | BJ34: =BJ33/BJ10 -> 0.48841567 | BK34: =BK33/BK10 -> 0.40928262 | BL34: =BL33/BL10 -> 0.22897311 | BM34: =BM33/BM10 -> 0.23240987 | BN34: =BN33/BN10 -> 0.17570518 | ... BS34: =BS33/BS10 -> 0.58044593
C35: Change vs Year Ago | T35: =IF((T33/P33)-1>0,(T33/P33)-1,"nm") -> nm | U35: =IF((U33/Q33)-1>0,(U33/Q33)-1,"nm") -> 1.0548851 | V35: =IF((V33/R33)-1>0,(V33/R33)-1,"nm") -> nm | W35: =IF((W33/S33)-1>0,(W33/S33)-1,"nm") -> nm | X35: =(X33/T33)-1 -> -0.65207308 | Y35: =(Y33/U33)-1 -> -0.61362964 | Z35: =(Z33/V33)-1 -> -0.05102987 | AA35: =(AA33/W33)-1 -> 1.6471459 | AB35: =(AB33/X33)-1 -> 2.6327798 | AC35: =(AC33/Y33)-1 -> 1.1427172 | AD35: =(AD33/Z33)-1 -> 0.82103631 | AE35: =(AE33/AA33)-1 -> -0.61488413 | ... BC35: =(BC33/AY33)-1 -> 0.31021561 | BJ35: =BJ33/BI33-1 -> 0.17352704 | BK35: =BK33/BJ33-1 -> -0.12058198 | BL35: =BL33/BK33-1 -> -0.21404444 | BM35: =BM33/BL33-1 -> 0.45486019 | BN35: =BN33/BM33-1 -> -0.52943106 | BO35: =BO33/BN33-1 -> 1.638234 | BP35: =BP33/BO33-1 -> 0.64896045 | BQ35: =BQ33/BP33-1 -> 1.0877644 | ... BS35: =BS33/BR33-1 -> 0.463232
A37: Total Non-operating Income(Loss) | P37: =P46-P33 -> -9.4626048 | Q37: =Q46-Q33 -> 73.221531 | R37: =R46-R33 -> 6.458 | S37: =S46-S33 -> 59.793074 | T37: =+T46-T33 -> 79.972019 | U37: =+U46-U33 -> 39.749125 | V37: =+V46-V33 -> 165.77896 | W37: =+W46-W33 -> 172.58451 | X37: =+X46-X33 -> 84.54 | Y37: =+Y46-Y33 -> 79.972 | Z37: =+Z46-Z33 -> 58.954 | AA37: =+AA46-AA33 -> 114.614 | ... AR37: =+AR46-AR33 -> 202.259 | AS37: =SUM(AS38:AS44) -> -24.966 | AT37: =SUM(AT38:AT44) -> -24.966 | AU37: =SUM(AU38:AU44) -> -24.966 | AV37: =SUM(AV38:AV44) -> 45 | AW37: =SUM(AW38:AW44) -> 45 | AX37: =SUM(AX38:AX44) -> 45 | AY37: =SUM(AY38:AY44) -> 45 | AZ37: =SUM(AZ38:AZ44) -> 45 | ... BC37: =SUM(BC38:BC44) -> 45 | BG37: =+BG46-BG33 -> -35.325 | BH37: =+BH46-BH33 -> 14.793 | BI37: =+BI46-BI33 -> 62.996 | BJ37: =+BJ46-BJ33 -> 130.01 | BK37: =+BK46-BK33 -> 458.24888 | BL37: =+BL46-BL33 -> 328.374 | BM37: =+BM46-BM33 -> 560.397 | BN37: =+BN46-BN33 -> 70.603 | BO37: =+BO46-BO33 -> 353.061 | BP37: =SUM(BP38:BP44) -> 476.59689 | BQ37: =SUM(BQ38:BQ44) -> 127.361 | BR37: =SUM(BR38:BR44) -> 180 | BS37: =SUM(BS38:BS44) -> 180
C38: Interest income | P38: 9.7631738 | Q38: =31.95472418-P38 -> 22.19155 | R38: =+Q38 -> 22.19155 | S38: =+BJ38-SUM(P38:R38) -> 25.495866 | T38: 13.756094 | U38: =20.14199021-T38 -> 6.3858962 | V38: 24.504982 | W38: =BK38-SUM(T38:V38) -> 34.938641 | X38: 12.951 | Y38: =22.62-X38 -> 9.669 | Z38: =49.731-X38-Y38 -> 27.111 | AA38: =+BL38-X38-Y38-Z38 -> 23.442 | AB38: 17.609 | AC38: 23.839 | AD38: 23.924 | AE38: 15.908 | AF38: 27.544 | AG38: 45.815 | AH38: 58.107 | AI38: 48.792 | AJ38: 53.984 | AK38: 67.596 | AL38: 73.493 | AM38: 45.431 | AN38: 40.541 | AO38: 85.145 | AP38: 74.565 | AQ38: 28.066 | AR38: -24.966 | AS38: =+AR38 -> -24.966 | AT38: =+AS38 -> -24.966 | AU38: =+AT38 -> -24.966 | AV38: 45 | AW38: =+AV38 -> 45 | AX38: =+AW38 -> 45 | AY38: =+AX38 -> 45 | AZ38: 45 | BA38: =+AZ38 -> 45 | BB38: =+BA38 -> 45 | BC38: =+BB38 -> 45 | BG38: 0 | BH38: 0 | BI38: 21.097004 | BJ38: 79.642141 | BK38: 79.585613 | BL38: 73.173 | BM38: =SUM(AB38:AE38) -> 81.28 | BN38: =SUM(AC38:AF38) -> 91.215 | BO38: =SUM(AD38:AG38) -> 113.191 | BP38: =SUM(AN38:AQ38) -> 228.317 | BQ38: =SUM(AR38:AU38) -> -99.864 | BR38: =SUM(AV38:AY38) -> 180 | BS38: =SUM(AZ38:BC38) -> 180
C39: Interest expense | P39: 0 | Q39: 0 | R39: 0 | S39: =AVERAGE(O39:R39) -> 0 | T39: 0 | U39: =AVERAGE(Q39:T39) -> 0 | V39: =AVERAGE(R39:U39) -> 0 | W39: =BK39-SUM(T39:V39) -> 0 | X39: 0 | Y39: 0 | Z39: 0 | AA39: 0 | AB39: 0 | AC39: 0 | AD39: 0 | AE39: 0 | AF39: 0 | AG39: 0 | AH39: 0 | AI39: 0 | AJ39: 0 | AK39: 0 | AL39: 1 | AM39: 1 | AN39: 1 | AO39: 1 | AP39: 0 | AQ39: 0 | AR39: 0 | AS39: 0 | AT39: 0 | AU39: 0 | AV39: 0 | AW39: 0 | AX39: 0 | AY39: 0 | AZ39: 0 | BA39: 0 | BB39: 0 | BC39: 0 | BG39: 0 | BH39: 0 | BI39: 0 | BJ39: 0 | BK39: 0 | BL39: =SUM(X39:AA39) -> 0 | BM39: =SUM(AB39:AE39) -> 0 | BN39: =SUM(AC39:AF39) -> 0 | BO39: =SUM(AD39:AG39) -> 0 | BP39: =SUM(AN39:AQ39) -> 2 | BQ39: =SUM(AR39:AU39) -> 0 | BR39: =SUM(AV39:AY39) -> 0 | BS39: =SUM(AZ39:BC39) -> 0
C40: Investment Income(loss) | P40: 0 | Q40: 0 | R40: 7.106 | S40: =AVERAGE(O40:R40) -> 2.3686667 | T40: 32.911078 | U40: =60.10369041-T40 -> 27.192613 | V40: 40.193753 | W40: =BK40-SUM(T40:V40) -> 2.1925566 | X40: 15.108 | Y40: 17.695 | Z40: 228.278 | AA40: 17.033 | AB40: 11.708 | AC40: 13.229 | AD40: 16.707 | AE40: 332.974 | AF40: 12.937 | AG40: 13.748 | AH40: 49.898 | AI40: 14.395 | AJ40: 12.126 | AK40: 4.219 | AL40: 19.54 | AM40: 12.714 | AN40: 9.547 | AO40: 10.435 | AP40: 5 | AQ40: 5 | AR40: 0 | AS40: 0 | AT40: 0 | AU40: 0 | AV40: 0 | AW40: 0 | AX40: 0 | AY40: 0 | AZ40: 0 | BA40: 0 | BB40: 0 | BC40: 0 | BG40: 0.473 | BH40: 6.196 | BI40: 17.305 | BJ40: 71.905 | BK40: 102.49 | BL40: 278.114 | BM40: 374.618 | BN40: 90.978 | BO40: 48.599 | BP40: =SUM(AN40:AQ40) -> 29.982 | BQ40: =SUM(AR40:AU40) -> 0 | BR40: =SUM(AV40:AY40) -> 0 | BS40: =SUM(AZ40:BC40) -> 0
C41: Investment disposal gain(loss) | P41: 0 | Q41: 0 | R41: 0 | S41: 0 | T41: 0 | U41: 0 | V41: 0 | W41: =BK41-SUM(T41:V41) -> 0 | X41: 0 | Y41: 0 | Z41: 0 | AA41: 0 | AB41: 0 | AC41: 0 | AD41: 0 | AE41: 0 | AF41: 0 | AG41: 0 | AH41: 0 | AI41: 0 | AJ41: 0 | AK41: 0 | AL41: 0 | AM41: 0 | AN41: 0 | AO41: 0 | AP41: 0 | AQ41: 0 | AR41: 0 | AS41: 0 | AT41: 0 | AU41: 0 | AV41: 0 | AW41: 0 | AX41: 0 | AY41: · | AZ41: 0 | BA41: 0 | BB41: 0 | BC41: · | BG41: 0 | BH41: -193 | BI41: 0 | BJ41: -124 | BK41: 0 | BL41: -3 | BM41: 0 | BN41: -41 | BO41: 0 | BP41: =SUM(AN41:AQ41) -> 0 | BQ41: =SUM(AR41:AU41) -> 0 | BR41: =SUM(AV41:AY41) -> 0 | BS41: =SUM(AZ41:BC41) -> 0
C42: Forex gain(loss) | P42: 0 | Q42: 0 | R42: 0 | S42: 0 | T42: =39.80282436-13.75609404 -> 26.04673 | U42: =27.86259441-T42 -> 1.8158641 | V42: 0 | W42: =BK42-SUM(T42:V42) -> -51.314701 | X42: 0 | Y42: 0 | Z42: 0 | AA42: 0 | AB42: 0 | AC42: 0 | AD42: 0 | AE42: 0 | AF42: 0 | AG42: 0 | AH42: 0 | AI42: 0 | AJ42: 0 | AK42: 0 | AL42: 0 | AM42: 0 | AN42: 0 | AO42: 0 | AP42: 0 | AQ42: 0 | AR42: 0 | AS42: 0 | AT42: 0 | AU42: 0 | AV42: 0 | AW42: 0 | AX42: 0 | AY42: 0 | AZ42: 0 | BA42: 0 | BB42: 0 | BC42: 0 | BG42: 0 | BH42: 0 | BI42: 0 | BJ42: 21.948618 | BK42: -23.452107 | BL42: =SUM(X42:AA42) -> 0 | BM42: =SUM(AB42:AE42) -> 0 | BN42: =SUM(AC42:AF42) -> 0 | BO42: =SUM(AD42:AG42) -> 0 | BP42: =SUM(AN42:AQ42) -> 0 | BQ42: =SUM(AR42:AU42) -> 0 | BR42: =SUM(AV42:AY42) -> 0 | BS42: =SUM(AZ42:BC42) -> 0
C43: Asset impairment gain (loss) | P43: 0 | Q43: 0 | R43: -70.282 | S43: 0 | T43: -9.8115508 | U43: =-17.99192042-T43 -> -8.1803696 | V43: 18.357 | W43: -12.94 | X43: 2.888 | Y43: -13.173 | Z43: 8.792 | AA43: 0.967 | AB43: -0.228 | AC43: 0.109 | AD43: -0.447 | AE43: -26.176 | AF43: -52.765 | AG43: -91.239 | AH43: -36.234 | AI43: -12.146 | AJ43: -1.508 | AK43: -0.28 | AL43: -0.555 | AM43: -42.564 | AN43: 8.976 | AO43: 21.845 | AP43: 0 | AQ43: 0 | AR43: 0 | AS43: 0 | AT43: 0 | AU43: 0 | AV43: 0 | AW43: 0 | AX43: 0 | AY43: 0 | AZ43: 0 | BA43: 0 | BB43: 0 | BC43: 0 | BG43: -55.4 | BH43: -53.743 | BI43: -13.314 | BJ43: -87.978676 | BK43: -12.728942 | BL43: -0.526 | BM43: -26.742 | BN43: -192.385 | BO43: -44.908 | BP43: =SUM(AN43:AQ43) -> 30.821 | BQ43: =SUM(AR43:AU43) -> 0 | BR43: =SUM(AV43:AY43) -> 0 | BS43: =SUM(AZ43:BC43) -> 0
C44: Others | P44: =P37-SUM(P39:P43) -> -9.4626048 | Q44: =Q37-SUM(Q39:Q43) -> 73.221531 | R44: =R37-SUM(R39:R43) -> 69.634 | S44: =S37-SUM(S39:S43) -> 57.424407 | T44: =T37-SUM(T39:T43) -> 30.825762 | U44: =U37-SUM(U39:U43) -> 18.921018 | V44: =V37-SUM(V39:V43) -> 107.2282 | W44: =W37-SUM(W39:W43) -> 234.64666 | ... AA44: =AA37-SUM(AA39:AA43) -> 96.614 | AB44: =AB37-SUM(AB38:AB43) -> 78.329 | AC44: =AC37-SUM(AC38:AC43) -> 133.308 | AD44: =AD37-SUM(AD38:AD43) -> 14.272 | AE44: =AE37-SUM(AE38:AE43) -> -94.669 | AF44: =AF37-SUM(AF38:AF43) -> 5.808 | AG44: =AG37-SUM(AG38:AG43) -> 46.277 | AH44: =AH37-SUM(AH38:AH43) -> -53.464 | AI44: =AI37-SUM(AI38:AI43) -> -6.868 | ... AO44: =AO37-SUM(AO38:AO43) -> 35.163 | AP44: =+AP37-SUM(AP38:AP43) -> 101.54789 | AQ44: =+AQ37-SUM(AQ38:AQ43) -> 37.882 | AR44: =+AR37-SUM(AR38:AR43) -> 227.225 | AS44: 0 | AT44: 0 | AU44: 0 | AV44: 0 | AW44: 0 | AX44: 0 | AY44: 0 | AZ44: 0 | BA44: 0 | BB44: 0 | BC44: 0 | BG44: =+BG37-SUM(BG38:BG43) -> 19.602 | BH44: =+BH37-SUM(BH38:BH43) -> 255.34 | BI44: =+BI37-SUM(BI38:BI43) -> 37.907996 | BJ44: =+BJ37-SUM(BJ38:BJ43) -> 168.49292 | BK44: =BK37-SUM(BK38:BK43) -> 312.35431 | BL44: =BL37-SUM(BL38:BL43) -> -19.387 | BM44: =BM37-SUM(BM38:BM43) -> 131.241 | BN44: =BN37-SUM(BN38:BN43) -> 121.795 | BO44: =BO37-SUM(BO38:BO43) -> 236.179 | BP44: =SUM(AN44:AQ44) -> 185.47689 | BQ44: =SUM(AR44:AU44) -> 227.225 | BR44: =SUM(AV44:AY44) -> 0 | BS44: =SUM(AZ44:BC44) -> 0
A46: Profit Before Taxes | P46: 234.54431 | Q46: =458.24697934-P46 -> 223.70266 | R46: 306.713 | S46: =+BJ46-SUM(P46:R46) -> 213.78702 | T46: 276.60527 | U46: =625.57583443-T46 -> 348.97057 | V46: 311.90052 | W46: =1204.643491-SUM(T46:V46) -> 267.16714 | X46: 152.954 | Y46: 199.446 | Z46: 197.619 | AA46: 364.988 | AB46: 355.951 | AC46: 426.484 | AD46: 306.97 | AE46: 324.46 | AF46: 24.034 | AG46: 71.614 | AH46: 161.082 | AI46: 215.489 | AJ46: 240.507 | AK46: 399.179 | AL46: 402.017 | AM46: 370.916 | AN46: 530.78 | AO46: 655.406 | AP46: =1692.984472-SUM(AN46:AO46) -> 506.79847 | AQ46: =1692.984472-SUM(AO46:AP46) -> 530.78 | AR46: 877.123 | AS46: =AS33+AS37 -> 809.12098 | AT46: =AT33+AT37 -> 940.77353 | AU46: =AU33+AU37 -> 1148.0178 | AV46: =AV33+AV37 -> 1391.1365 | AW46: =AW33+AW37 -> 1930.7358 | AX46: =AX33+AX37 -> 2166.7645 | AY46: =AY33+AY37 -> 2429.1039 | AZ46: =AZ33+AZ37 -> 2585.4043 | ... BC46: =BC33+BC37 -> 3168.6902 | BG46: 99.093 | BH46: 362.37 | BI46: 786.232 | BJ46: 978.747 | BK46: 1204.6435 | BL46: 915.007 | BM46: 1413.866 | BN46: 472.219 | BO46: 1412.618 | BP46: =BP33+BP37 -> 2223.7645 | BQ46: =BQ33+BQ37 -> 3775.0354 | BR46: =BR33+BR37 -> 7917.7407 | BS46: =BS33+BS37 -> 11502.11
C47: Percent of Revenues | P47: =P46/P10 -> 0.57952658 | Q47: =Q46/Q10 -> 0.47148747 | R47: =R46/R10 -> 0.60715169 | S47: =S46/S10 -> 0.60496165 | T47: =T46/T10 -> 0.55795035 | U47: =U46/U10 -> 0.58766647 | V47: =V46/V10 -> 0.8232288 | W47: =W46/W10 -> 0.75212957 | ... BC47: =BC46/BC10 -> 0.59315864 | BG47: =BG46/BG10 -> 0.11727746 | BH47: =BH46/BH10 -> 0.29520617 | BI47: =BI46/BI10 -> 0.44731618 | BJ47: =BJ46/BJ10 -> 0.56323145 | BK47: =BK46/BK10 -> 0.66056163 | BL47: =BL46/BL10 -> 0.35714322 | BM47: =BM46/BM10 -> 0.38501271 | BN47: =BN46/BN10 -> 0.20659367 | ... BS47: =BS46/BS10 -> 0.58967392
A49: Taxes | P49: 8.8038863 | Q49: =7.41977878-P49 -> -1.3841076 | R49: 14.03 | S49: =+BJ49-SUM(P49:R49) -> 24.439221 | T49: 13.616949 | U49: =24.05116747-T49 -> 10.434218 | V49: 35.656776 | W49: =100.92-SUM(T49:V49) -> 41.212056 | X49: 18.837 | Y49: 25.716 | Z49: -6.984 | AA49: 48.301 | AB49: 49.852 | AC49: 51.626 | AD49: -11.039 | AE49: 24.055 | AF49: 4.313 | AG49: 9.386 | AH49: 9.036 | AI49: -1.664 | AJ49: 17.098 | AK49: 29.433 | AL49: 18.792 | AM49: 6.558 | AN49: 27.061 | AO49: 46.749 | AP49: =116.62-SUM(AN49:AO49) -> 42.81 | AQ49: =116.62-SUM(AO49:AP49) -> 27.061 | AR49: 47.398 | AS49: =AS50*AS46 -> 57.713229 | AT49: =AT50*AT46 -> 67.103783 | AU49: =AU50*AU46 -> 81.886168 | AV49: =AV50*AV46 -> 99.227407 | AW49: =AW50*AW46 -> 137.71612 | AX49: =AX50*AX46 -> 154.55164 | AY49: =AY50*AY46 -> 173.26387 | AZ49: =AZ50*AZ46 -> 184.41251 | ... BC49: =BC50*BC46 -> 226.0173 | BG49: 6.288 | BH49: 15.454 | BI49: 49.354 | BJ49: 45.889 | BK49: =SUM(T49:W49) -> 100.92 | BL49: 85.87 | BM49: 114.494 | BN49: 21.071 | BO49: 71.882 | BP49: =SUM(AN49:AQ49) -> 143.681 | BQ49: =SUM(AR49:AU49) -> 254.10118 | BR49: =SUM(AV49:AY49) -> 564.75904 | BS49: =SUM(AZ49:BC49) -> 820.42602
C50: Tax Rate | P50: =P49/P46 -> 0.037536132 | Q50: =Q49/Q46 -> -0.0061872645 | R50: =R49/R46 -> 0.045743089 | S50: =S49/S46 -> 0.11431574 | T50: =T49/T46 -> 0.049228814 | U50: =U49/U46 -> 0.029899995 | V50: =V49/V46 -> 0.11432099 | W50: =W49/W46 -> 0.15425571 | ... AO50: =AO49/AO46 -> 0.071328306 | AP50: =AO50 -> 0.071328306 | AQ50: =AP50 -> 0.071328306 | AR50: =AQ50 -> 0.071328306 | AS50: =AR50 -> 0.071328306 | AT50: =AS50 -> 0.071328306 | AU50: =AT50 -> 0.071328306 | AV50: =AU50 -> 0.071328306 | AW50: =AV50 -> 0.071328306 | ... BC50: =BB50 -> 0.071328306 | BG50: =BG49/BG46 -> 0.063455542 | BH50: =BH49/BH46 -> 0.042647018 | BI50: =BI49/BI46 -> 0.06277282 | BJ50: =BJ49/BJ46 -> 0.046885457 | BK50: =BK49/BK46 -> 0.083775823 | BL50: =BL49/BL46 -> 0.093846277 | BM50: =BM49/BM46 -> 0.080979386 | BN50: =BN49/BN46 -> 0.044621246 | ... BS50: =BS49/BS46 -> 0.071328306
A52: Net Income | P52: =P46-P49 -> 225.74043 | Q52: =Q46-Q49 -> 225.08677 | R52: =R46-R49 -> 292.683 | S52: =S46-S49 -> 189.3478 | T52: =T46-T49 -> 262.98832 | U52: =U46-U49 -> 338.53635 | V52: =V46-V49 -> 276.24374 | W52: =W46-W49 -> 225.95508 | ... BC52: =BC46-BC49 -> 2942.6729 | BG52: =+BG46-BG49 -> 92.805 | BH52: =+BH46-BH49 -> 346.916 | BI52: =+BI46-BI49 -> 736.878 | BJ52: =BJ46-BJ49 -> 932.858 | BK52: =BK46-BK49 -> 1103.7235 | BL52: =BL46-BL49 -> 829.137 | BM52: =BM46-BM49 -> 1299.372 | BN52: =BN46-BN49 -> 451.148 | BO52: =BO46-BO49 -> 1340.736 | BP52: =BP46-BP49 -> 2080.0835 | BQ52: =BQ46-BQ49 -> 3520.9342 | ... BS52: =BS46-BS49 -> 10681.684
C53: Percent of Revenues | P53: =P52/P10 -> 0.55777339 | Q53: =Q52/Q10 -> 0.47440469 | R53: =R52/R10 -> 0.5793787 | S53: =S52/S10 -> 0.53580501 | T53: =T52/T10 -> 0.53048311 | U53: =U52/U10 -> 0.57009525 | V53: =V52/V10 -> 0.72911647 | W53: =W52/W10 -> 0.63610929 | ... BC53: =BC52/BC10 -> 0.55084964 | BJ53: =BJ52/BJ10 -> 0.53682408 | BK53: =BK52/BK10 -> 0.60522254 | BL53: =BL52/BL10 -> 0.32362666 | BM53: =BM52/BM$10 -> 0.35383462 | BN53: =BN52/BN$10 -> 0.1973752 | BO53: =BO52/BO$10 -> 0.3684443 | BP53: =BP52/BP$10 -> 0.39396285 | BQ53: =BQ52/BQ$10 -> 0.4684162 | BR53: =BR52/BR$10 -> 0.52841805 | BS53: =BS52/BS$10 -> 0.54761347
A55: Minority Interests | P55: 0 | Q55: 0 | R55: 0 | S55: =R55 -> 0 | T55: =S55 -> 0 | U55: =T55 -> 0 | V55: 0 | W55: 0 | X55: 0 | Y55: 0 | Z55: 0 | AA55: 0 | AB55: 0 | AC55: 0.001 | AD55: 0.01 | AE55: -0.017 | AF55: 0 | AG55: 0.093 | AH55: 0.144 | AI55: 0 | AJ55: 0 | AK55: 0 | AL55: -1.699 | AM55: -69.344 | AN55: -21.607 | AO55: -25.087 | AP55: =-55.919487-SUM(AN55:AO55) -> -9.225487 | AQ55: =-55.919487-SUM(AO55:AP55) -> -21.607 | AR55: -17.65 | AS55: =AR55 -> -17.65 | AT55: =AS55 -> -17.65 | AU55: =AT55 -> -17.65 | AV55: =AU55 -> -17.65 | AW55: =AV55 -> -17.65 | AX55: =AW55 -> -17.65 | AY55: =AX55 -> -17.65 | AZ55: =AY55 -> -17.65 | ... BC55: =BB55 -> -17.65 | BG55: =+BG57-BG52 -> -0.001 | BH55: =+BH57-BH52 -> 0 | BI55: =+BI57-BI52 -> 0 | BJ55: =SUM(P55:S55) -> 0 | BK55: =SUM(T55:W55) -> 0 | BL55: =SUM(X55:AA55) -> 0 | BM55: =SUM(AB55:AE55) -> -0.006 | BN55: =SUM(AF55:AI55) -> 0.237 | BO55: =SUM(AJ55:AM55) -> -71.043 | BP55: =SUM(AN55:AQ55) -> -77.526487 | BQ55: =SUM(AR55:AU55) -> -70.6 | BR55: =SUM(AV55:AY55) -> -70.6 | BS55: =SUM(AZ55:BC55) -> -70.6
A57: Reported Income (attributable to parent) | P57: =+P52+P55 -> 225.74043 | Q57: =Q52+Q55 -> 225.08677 | R57: 292.683 | S57: =S52+S55 -> 189.3478 | T57: =T52+T55 -> 262.98832 | U57: =U52+U55 -> 338.53635 | V57: =V52+V55 -> 276.24374 | W57: =W52+W55 -> 225.95508 | X57: =X52+X55 -> 134.117 | Y57: =Y52+Y55 -> 173.73 | Z57: =Z52+Z55 -> 204.603 | ... AH57: =AH52+AH55 -> 152.19 | AI57: =AI52-AI55 -> 217.153 | AJ57: =AJ52-AJ55 -> 223.409 | AK57: =AK52-AK55 -> 369.746 | AL57: =AL52-AL55 -> 384.924 | AM57: =AM52-AM55 -> 433.702 | AN57: =AN52-AN55 -> 525.326 | AO57: =AO52-AO55 -> 633.744 | AP57: =AP52-AP55 -> 473.21396 | ... BC57: =BC52-BC55 -> 2960.3229 | BG57: 92.804 | BH57: 346.916 | BI57: 736.878 | BJ57: 932.858 | BK57: =BK52-BK55 -> 1103.7235 | BL57: 829.138 | BM57: 1299.378 | BN57: 450.91 | BO57: 1411.779 | BP57: =BP52-BP55 -> 2157.61 | BQ57: =BQ52-BQ55 -> 3591.5342 | BR57: =BR52-BR55 -> 7423.5817 | BS57: =BS52-BS55 -> 10752.284 | BT57: =+(BS57/BQ57)^(1/2)-1 -> 0.73025598
C58: Percent of Revenues | P58: =P57/P10 -> 0.55777339 | Q58: =Q57/Q10 -> 0.47440469 | R58: =R57/R10 -> 0.5793787 | S58: =S57/S10 -> 0.53580501 | T58: =T57/T10 -> 0.53048311 | U58: =U57/U10 -> 0.57009525 | V58: =V57/V10 -> 0.72911647 | W58: =W57/W10 -> 0.63610929 | ... BC58: =BC57/BC10 -> 0.55415361 | BG58: =BG57/BG10 -> 0.10983437 | BH58: =BH57/BH10 -> 0.28261651 | BI58: =BI57/BI10 -> 0.41923689 | BJ58: =BJ57/BJ10 -> 0.53682408 | BK58: =BK57/BK10 -> 0.60522254 | BL58: =BL57/BL10 -> 0.32362705 | BM58: =BM57/BM10 -> 0.35383625 | BN58: =BN57/BN10 -> 0.19727108 | ... BS58: =BS57/BS10 -> 0.55123289
...

Sheet Balance Sheet
A1: ='Earnings Model'!A1 -> Montage Technology (688008.SS, 6809.HK)
B2: Bottom-Up Model ($ in million)
B3: FY Ends: Dec
A5: ='Earnings Model'!A8 -> Rmb$ in million | C5: 4Q16 | D5: 1Q17 | E5: 2Q17 | F5: 3Q17 | G5: 4Q17 | H5: 1Q18 | I5: 2Q18 | J5: 3Q18 | K5: 4Q18 | L5: 1Q19 | M5: 2Q19 | N5: 3Q19 | O5: 4Q19 | P5: 1Q20 | Q5: 2Q20 | R5: 3Q20 | S5: 4Q20 | T5: 1Q21 | U5: 2Q21 | V5: 3Q21 | W5: 4Q21 | X5: 1Q22 | Y5: 2Q22 | Z5: 3Q22 | AA5: 4Q22 | AB5: 1Q23 | AC5: 2Q23 | AD5: 3Q23 | AE5: 4Q23 | AF5: 1Q24 | AG5: 2Q24 | AH5: 3Q24 | AI5: 4Q24 | AJ5: 1Q25 | AK5: 2Q25 | AL5: 3Q25 | AM5: 4Q25 | AO5: 2016 | AP5: 2017 | AQ5: 2018 | AR5: 2019 | AS5: 2020 | AT5: 2021 | AU5: 2022 | AV5: 2023 | AW5: 2024 | AX5: 2025 | AY5: 2026E | AZ5: 2027E | BA5: 2028E
A8: Assets
B9: Cash & Securities | C9: =SUM(C10:C11) -> 0 | D9: =SUM(D10:D11) -> 0 | E9: =SUM(E10:E11) -> 0 | F9: =SUM(F10:F11) -> 0 | G9: =SUM(G10:G11) -> 0 | H9: =SUM(H10:H11) -> 0 | I9: =SUM(I10:I11) -> 0 | J9: =SUM(J10:J11) -> 0 | ... AM9: =SUM(AM10:AM11) -> 9302.288 | AO9: 454.351 | AP9: 687.786 | AQ9: 3679.991 | AR9: =+AR10+AR11 -> 7357.8446 | AS9: =SUM(AS10:AS12) -> 6345.992 | AT9: =+AT10+AT11 -> 6666.491 | AU9: =+AU10+AU11 -> 7480.528 | AV9: =+AV10+AV11 -> 7446.842 | AW9: =+AW10+AW11 -> 7400.152 | AX9: =+AX10+AX11 -> 7364.08 | AY9: =SUM(AY10:AY12) -> 17407.123 | AZ9: =SUM(AZ10:AZ12) -> 23937.581 | BA9: =SUM(BA10:BA12) -> 33913.698
B10: Cash & Cash Equivalents | C10: 0 | D10: 0 | E10: 0 | F10: 0 | G10: 0 | H10: 0 | I10: 0 | J10: 0 | K10: 3679.9913 | L10: 0 | M10: 4030.3676 | N10: 7133.001 | O10: 7257.0637 | P10: 7582.2988 | Q10: 7320.8061 | R10: 6806.7686 | S10: 5474.592 | T10: 5668.54 | U10: 5842.794 | V10: 5722.253 | W10: 5104.338 | X10: 4879.758 | Y10: 5476.76 | Z10: 5119.689 | AA10: 5870.438 | AB10: 5388.085 | AC10: 5861.541 | AD10: 5726.784 | AE10: 5743.575 | AF10: 5723.346 | AG10: 5851.634 | AH10: 6242.95 | AI10: 6843.297 | AJ10: 7174.73 | AK10: 8353.452 | AL10: 8898.71 | AM10: 8478.984 | AO10: =+AO9-AO11-AO12 -> 454.351 | AP10: =+AP9-AP11-AP12 -> 687.786 | AQ10: =+AQ9-AQ11-AQ12 -> 3679.991 | AR10: =+O10 -> 7257.0637 | AS10: =S10 -> 5474.592 | AT10: =W10 -> 5104.338 | AU10: =+AA10 -> 5870.438 | AV10: =+AE10 -> 5743.575 | AW10: =+AF10 -> 5723.346 | AX10: =+AG10 -> 5851.634 | AY10: ='Cash Flow'!O46 -> 15894.677 | AZ10: ='Cash Flow'!P46 -> 22425.135 | BA10: ='Cash Flow'!Q46 -> 32401.252
B11: Marketable securities | C11: 0 | D11: 0 | E11: 0 | F11: 0 | G11: 0 | H11: 0 | I11: 0 | J11: 0 | K11: 0 | L11: 0 | M11: 0 | N11: 0 | O11: 100.78082 | P11: 114.72822 | Q11: 388.40642 | R11: 65.168767 | S11: 871.4 | T11: 799.737 | U11: 412.86 | V11: 1012.425 | W11: 1562.153 | X11: 2070.325 | Y11: 2280.461 | Z11: 2139.308 | AA11: 1610.09 | AB11: 1563.525 | AC11: 1784.75 | AD11: 1630.029 | AE11: 1703.267 | AF11: 1676.806 | AG11: 1512.446 | AH11: 1493.089 | AI11: 1783.495 | AJ11: 1573.106 | AK11: 666.888 | AL11: 545.849 | AM11: 823.304 | AO11: 0 | AP11: 0 | AQ11: 0 | AR11: =+O11 -> 100.78082 | AS11: =S11 -> 871.4 | AT11: =+W11 -> 1562.153 | AU11: =+AA11 -> 1610.09 | AV11: =+AE11 -> 1703.267 | AW11: =+AF11 -> 1676.806 | AX11: =+AG11 -> 1512.446 | AY11: =AX11-'Cash Flow'!O26 -> 1512.446 | AZ11: =AY11-'Cash Flow'!P26 -> 1512.446 | BA11: =AZ11-'Cash Flow'!Q26 -> 1512.446
B12: Restricted Cash and Cash Equivalents | AY12: =AX12 -> 0 | AZ12: =AY12 -> 0 | BA12: =AZ12 -> 0
B13: Accounts and Notes Receivable | C13: 0 | D13: 0 | E13: 0 | F13: 0 | G13: 0 | H13: 0 | I13: 0 | J13: 0 | K13: =241.14922121 -> 241.14922 | L13: 0 | M13: =191.9930483 -> 191.99305 | N13: 238.942 | O13: 131.86482 | P13: =177.25627846 -> 177.25628 | Q13: =122.0480395 -> 122.04804 | R13: 120.37637 | S13: 87.453 | T13: 104.934 | U13: 163.68 | V13: 414.739 | W13: 172.433 | X13: 212.29 | Y13: 196.307 | Z13: 280.93 | AA13: 322.379 | AB13: 169.069 | AC13: 185.44 | AD13: 256.438 | AE13: 294.254 | AF13: 218.392 | AG13: 248.611 | AH13: 260.825 | AI13: 387.792 | AJ13: 463.919 | AK13: 391.064 | AL13: 568.204 | AM13: 567.532 | AO13: 58.796 | AP13: 119.258 | AQ13: 241.149 | AR13: =+O13 -> 131.86482 | AS13: =S13 -> 87.453 | AT13: 172.433 | AU13: 322.379 | AV13: 294.254 | AW13: 387.792 | AX13: 567.532 | AY13: =AY62*'Earnings Model'!BQ10/365 -> 704.43063 | AZ13: =AZ62*'Earnings Model'!BR10/365 -> 1304.0615 | BA13: =BA62*'Earnings Model'!BS10/365 -> 1828.0069
B14: Inventories | C14: 0 | D14: 0 | E14: 0 | F14: 0 | G14: 0 | H14: 0 | I14: 0 | J14: 0 | K14: 120.67354 | L14: 0 | M14: 132.83984 | N14: 82.425 | O14: 156.80486 | P14: 142.66072 | Q14: 176.92772 | R14: 198.72442 | S14: 186.542 | T14: 195.267 | U14: 281.206 | V14: 293.633 | W14: 375.292 | X14: 405.564 | Y14: 670.709 | Z14: 662.437 | AA14: 738.433 | AB14: 819.031 | AC14: 736.426 | AD14: 632.683 | AE14: 482.386 | AF14: 476.777 | AG14: 400.825 | AH14: 393.622 | AI14: 352.196 | AJ14: 310.734 | AK14: 400.616 | AL14: 795.747 | AM14: 896.135 | AO14: 256.069 | AP14: 132.513 | AQ14: 120.674 | AR14: 156.805 | AS14: =S14 -> 186.542 | AT14: 375.292 | AU14: 738.433 | AV14: 482.386 | AW14: 352.196 | AX14: 896.135 | AY14: =AY63*'Earnings Model'!BQ14/365 -> 643.32796 | AZ14: =AZ63*'Earnings Model'!BR14/365 -> 1106.9601 | BA14: =BA63*'Earnings Model'!BS14/365 -> 1500.6271
B15: Others | C15: =C16-C9-C13-C14 -> 0 | D15: =D16-D9-D13-D14 -> 0 | E15: =E16-E9-E13-E14 -> 0 | F15: =F16-F9-F13-F14 -> 0 | G15: =G16-G9-G13-G14 -> 0 | H15: =H16-H9-H13-H14 -> 0 | I15: =I16-I9-I13-I14 -> 0 | J15: =J16-J9-J13-J14 -> 0 | ... AM15: =AM16-AM9-AM13-AM14 -> 268.12 | AO15: =AO16-AO9-AO13-AO14 -> 309.26 | AP15: =AP16-AP9-AP13-AP14 -> 486.647 | AQ15: =AQ16-AQ9-AQ13-AQ14 -> 44.718 | AR15: =AR16-AR9-AR13-AR14 -> 32.231634 | AS15: =S15 -> 39.76 | AT15: =W15 -> 208.84 | AU15: =AU16-AU9-AU13-AU14 -> 95.138 | AV15: =AV16-AV9-AV13-AV14 -> 72.645 | AW15: =AW16-AW9-AW13-AW14 -> 1321.164 | AX15: =AX16-AX9-AX13-AX14 -> 2206.328 | AY15: =AX15 -> 2206.328 | AZ15: =AY15 -> 2206.328 | BA15: =AZ15 -> 2206.328
B16: Total Current Assets | C16: 0 | D16: 0 | E16: 0 | F16: 0 | G16: 0 | H16: 0 | I16: 0 | J16: 0 | K16: 4086.5323 | L16: 0 | M16: 4382.9412 | N16: 7475.609 | O16: 7678.7462 | P16: 8045.3918 | Q16: 8043.0098 | R16: 7741.658 | S16: 6659.747 | T16: 6814.135 | U16: 6743.272 | V16: 7512.269 | W16: 7423.056 | X16: 7789.609 | Y16: 8714.779 | Z16: 8367.635 | AA16: 8636.478 | AB16: 8239.979 | AC16: 8625.566 | AD16: 8324.469 | AE16: 8296.127 | AF16: 8183.803 | AG16: 8105.686 | AH16: 8496.421 | AI16: 9461.304 | AJ16: 9882.72 | AK16: 10119.816 | AL16: 10961.154 | AM16: 11034.075 | AO16: 1078.476 | AP16: 1426.204 | AQ16: 4086.532 | AR16: 7678.746 | AS16: =S16 -> 6659.747 | AT16: 7423.056 | AU16: 8636.478 | AV16: 8296.127 | AW16: 9461.304 | AX16: 11034.075 | AY16: =AY9+SUM(AY13:AY15) -> 20961.209 | AZ16: =AZ9+SUM(AZ13:AZ15) -> 28554.93 | BA16: =BA9+SUM(BA13:BA15) -> 39448.66
B17: Long-term investments | C17: 0 | D17: 0 | E17: 0 | F17: 0 | G17: 0 | H17: 0 | I17: 0 | J17: 0 | K17: 0 | L17: 0 | M17: 0 | N17: 0 | O17: 0 | P17: 0 | Q17: 0 | R17: 0.8502165 | S17: 72.737 | T17: 72.487 | U17: 69.546 | V17: 67.969 | W17: 67.91 | X17: 66.335 | Y17: 64.71 | Z17: 64.083 | AA17: 64.349 | AB17: 63.568 | AC17: 62.081 | AD17: 70.89 | AE17: 70.714 | AF17: 69.723 | AG17: 74.956 | AH17: 107.863 | AI17: 109.225 | AJ17: 105.168 | AK17: 99.319 | AL17: 95.614 | AM17: 91.96 | AO17: 0 | AP17: 0 | AQ17: 0 | AR17: 0 | AS17: =S17 -> 72.737 | AT17: 67.91 | AU17: 64.349 | AV17: 70.714 | AW17: 109.225 | AX17: 91.96 | AY17: =AX17 -> 91.96 | AZ17: =AY17 -> 91.96 | BA17: =AZ17 -> 91.96
B18: Gross PPE | C18: 0 | D18: =C18 -> 0 | E18: 0 | F18: =E18 -> 0 | G18: 0 | H18: =G18 -> 0 | I18: 0 | J18: =I18 -> 0 | K18: 0 | L18: =K18 -> 0 | M18: =L18 -> 0 | N18: =M18 -> 0 | O18: 0 | P18: 0 | Q18: 0 | AO18: 42.496 | AP18: 21.936 | AQ18: 43.877 | AR18: 57.785 | AS18: 1034.281 | AT18: 105.872 | AU18: 609.928 | AV18: 752.45 | AW18: 790.301 | AX18: 1005.8 | AY18: nd | AZ18: nd | BA18: nd
B19: Accumulated Depreciation | C19: =C20-C18 -> 0 | D19: =D20-D18 -> 0 | E19: =E20-E18 -> 0 | F19: =F20-F18 -> 0 | G19: =G20-G18 -> 0 | H19: =H20-H18 -> 0 | I19: =I20-I18 -> 0 | J19: =J20-J18 -> 0 | K19: =+K20-K18 -> 23.150272 | L19: =+L20-L18 -> 0 | M19: =+M20-M18 -> 25.877296 | N19: =+N20-N18 -> 29.876 | O19: =+O20-O18 -> 27.669965 | P19: =+P20-P18 -> 27.386551 | Q19: =+Q20-Q18 -> 32.796069 | AO19: =+AO20-AO18 -> -30.332 | AP19: =+AP20-AP18 -> -14.612 | AQ19: =+AQ20-AQ18 -> -20.727 | AR19: =+AR20-AR18 -> -30.115 | AS19: =+AS20-AS18 -> -48.778 | AT19: =+AT20-AT18 -> -67.224 | AU19: =+AU20-AU18 -> -89.428 | AV19: =+AV20-AV18 -> -140.643 | ... AX19: =+AX20-AX18 -> -289.733 | AY19: nd | AZ19: nd | BA19: nd
B20: Net PP&E | C20: 0 | D20: 0 | E20: 0 | F20: 0 | G20: 0 | H20: 0 | I20: 0 | J20: 0 | K20: =23.15027153 -> 23.150272 | L20: 0 | M20: 25.877296 | N20: 29.876 | O20: =27.6699652 -> 27.669965 | P20: =27.38655086 -> 27.386551 | Q20: =32.79606893 -> 32.796069 | R20: 30.356324 | S20: 985.503 | T20: 978.833 | U20: 982.349 | V20: 972.782 | W20: 38.648 | X20: 37.32 | Y20: 39.311 | Z20: 38.279 | AA20: 520.5 | AB20: 536.353 | AC20: 582.344 | AD20: 584.767 | AE20: 611.807 | AF20: 602.734 | AG20: 591.572 | AH20: 579.069 | AI20: 582.259 | AJ20: 566.366 | AK20: 685.302 | AL20: 720.955 | AM20: 716.067 | AO20: 12.164 | AP20: 7.324 | AQ20: 23.15 | AR20: 27.67 | AS20: =S20 -> 985.503 | AT20: 38.648 | AU20: 520.5 | AV20: 611.807 | AW20: 582.259 | AX20: 716.067 | AY20: =+AX20+20 -> 736.067 | AZ20: =+AY20+20 -> 756.067 | BA20: =+AZ20+20 -> 776.067
B21: Intangible Assets | C21: 0 | D21: 0 | E21: 0 | F21: 0 | G21: 0 | H21: 0 | I21: 0 | J21: 0 | K21: 25.970719 | L21: 0 | M21: 24.916662 | N21: 20.465 | O21: 16.22184 | P21: 12.54741 | Q21: 8.8281565 | R21: 6.8403509 | S21: 10.247 | T21: 9.859 | U21: 8.177 | V21: 22.77 | W21: 124.605 | X21: 123.525 | Y21: 121.183 | Z21: 120.689 | AA21: 131.081 | AB21: 128.666 | AC21: 147.719 | AD21: 142.791 | AE21: 137.486 | AF21: 131.436 | AG21: 125.784 | AH21: 123.195 | AI21: 133.755 | AJ21: 127.459 | AK21: 120.969 | AL21: 119.693 | AM21: 113.433 | AO21: 17.948 | AP21: 20.788 | AQ21: 25.971 | AR21: 16.222 | AS21: =S21 -> 10.247 | AT21: 124.605 | AU21: 131.081 | AV21: 137.486 | AW21: 133.755 | AX21: 113.433 | AY21: =AX21 -> 113.433 | AZ21: =AY21 -> 113.433 | BA21: =AZ21 -> 113.433
B22: Deffered Tax Assets | C22: 0 | D22: 0 | E22: 0 | F22: 0 | G22: 0 | H22: 0 | I22: 0 | J22: 0 | K22: 39.946689 | L22: 0 | M22: 47.403383 | N22: 59.338 | O22: 54.513501 | P22: 64.571283 | Q22: 71.674498 | R22: 70.087985 | S22: 43.075 | T22: 49.811 | U22: 57.355 | V22: 64.773 | W22: 64.532 | X22: 59.296 | Y22: 70.883 | Z22: 82.707 | AA22: 92.404 | AB22: 86.385 | AC22: 78.431 | AD22: 80.03 | AE22: 90.578 | AF22: 89.209 | AG22: 87.432 | AH22: 81.353 | AI22: 83.097 | AJ22: 94.115 | AK22: 79.582 | AL22: 90.532 | AM22: 43.299 | AO22: 10.753 | AP22: 17.032 | AQ22: 39.947 | AR22: 54.514 | AS22: =S22 -> 43.075 | AT22: 64.532 | AU22: 92.404 | AV22: 90.578 | AW22: 83.097 | AX22: 43.299 | AY22: =AX22 -> 43.299 | AZ22: =AY22 -> 43.299 | BA22: =AZ22 -> 43.299
B23: Other Assets | C23: =C24-C16-C17-C20-C21-C22 -> 0 | D23: =D24-D16-D17-D20-D21-D22 -> 0 | E23: =E24-E16-E17-E20-E21-E22 -> 0 | F23: =F24-F16-F17-F20-F21-F22 -> 0 | G23: =G24-G16-G17-G20-G21-G22 -> 0 | H23: =H24-H16-H17-H20-H21-H22 -> 0 | I23: =I24-I16-I17-I20-I21-I22 -> 0 | J23: =J24-J16-J17-J20-J21-J22 -> 0 | ... AM23: =AM24-AM16-AM17-AM20-AM21-AM22 -> 1749.313 | AO23: =AO24-AO16-AO17-AO20-AO21-AO22 -> 2.003 | AP23: =AP24-AP16-AP17-AP20-AP21-AP22 -> 3.345 | AQ23: =AQ24-AQ16-AQ17-AQ20-AQ21-AQ22 -> 5.057 | AR23: =AR24-AR16-AR17-AR20-AR21-AR22 -> 3.601 | AS23: =S23 -> 648.133 | AT23: =AT24-AT16-AT17-AT20-AT21-AT22 -> 1239.811 | AU23: =AU24-AU16-AU17-AU20-AU21-AU22 -> 1241.234 | AV23: =AV24-AV16-AV17-AV20-AV21-AV22 -> 1490.829 | AW23: =AW24-AW16-AW17-AW20-AW21-AW22 -> 1849.271 | AX23: =AX24-AX16-AX17-AX20-AX21-AX22 -> 1749.313 | AY23: =AX23 -> 1749.313 | AZ23: =AY23 -> 1749.313 | BA23: =AZ23 -> 1749.313
A24: Total Assets | C24: 0 | D24: 0 | E24: 0 | F24: 0 | G24: 0 | H24: 0 | I24: 0 | J24: 0 | K24: 4180.6574 | L24: 0 | M24: 4484.8242 | N24: 7589.091 | O24: 7780.7535 | P24: 8174.8453 | Q24: 8540.9198 | R24: 8378.5118 | S24: 8419.442 | T24: 8685.978 | U24: 8620.2 | V24: 9009.717 | W24: 8958.562 | X24: 9391.582 | Y24: 10354.43 | Z24: 10264.186 | AA24: 10686.046 | AB24: 10519.681 | AC24: 10943.151 | AD24: 10619.712 | AE24: 10697.541 | AF24: 10707.524 | AG24: 10660.783 | AH24: 11181.976 | AI24: 12218.911 | AJ24: 12665.661 | AK24: 12878.881 | AL24: 13751.629 | AM24: 13748.147 | AO24: 1121.344 | AP24: 1474.693 | AQ24: 4180.657 | AR24: 7780.753 | AS24: =S24 -> 8419.442 | AT24: 8958.562 | AU24: 10686.046 | AV24: 10697.541 | AW24: 12218.911 | AX24: 13748.147 | AY24: =AY16+AY17+SUM(AY20:AY23) -> 23695.281 | AZ24: =AZ16+AZ17+SUM(AZ20:AZ23) -> 31309.002 | BA24: =BA16+BA17+SUM(BA20:BA23) -> 42222.732
A26: Liabilities & Shareholders' Equity
B27: Short-Term Debt | C27: 0 | D27: 0 | E27: 0 | F27: 0 | G27: 0 | H27: 0 | I27: 0 | J27: 0 | K27: 0 | L27: 0 | M27: 0 | N27: 0 | O27: 0 | P27: 0 | Q27: 0 | R27: 0 | S27: 0 | T27: 0 | U27: 0 | V27: 0 | W27: 0 | X27: 0 | Y27: 0 | Z27: 0 | AA27: 0 | AB27: 0 | AC27: 0 | AD27: 0 | AE27: 0 | AF27: 0 | AG27: 0 | AH27: 0 | AI27: 0 | AJ27: 0 | AK27: 0 | AL27: 0 | AM27: 0 | AO27: 0 | AP27: 0 | AQ27: 0 | AR27: 0 | AS27: =S27 -> 0 | AT27: 0 | AU27: 0 | AV27: 0 | AW27: 0 | AX27: 0 | AY27: =AX27+'Cash Flow'!O33 -> 0 | AZ27: =AY27+'Cash Flow'!P33 -> 0 | BA27: =AZ27+'Cash Flow'!Q33 -> 0
B28: Accounts Payable | C28: 0 | D28: 0 | E28: 0 | F28: 0 | G28: 0 | H28: 0 | I28: 0 | J28: 0 | K28: =74.3775691 -> 74.377569 | L28: 0 | M28: =113.25534615 -> 113.25535 | N28: 72.038 | O28: =91.29405784 -> 91.294058 | P28: =118.59080495 -> 118.5908 | Q28: =120.01846117 -> 120.01846 | R28: 78.692974 | S28: 85.844 | T28: 108.305 | U28: 208.124 | V28: 312.074 | W28: 206.707 | X28: 259.157 | Y28: 478.604 | Z28: 167.261 | AA28: 197.166 | AB28: 126.626 | AC28: 79.187 | AD28: 103.185 | AE28: 131.115 | AF28: 171.013 | AG28: 115.143 | AH28: 158.523 | AI28: 211.154 | AJ28: 204.301 | AK28: 145.093 | AL28: 304.965 | AM28: 208.234 | AO28: 112.21 | AP28: 107.313 | AQ28: 74.378 | AR28: 91.294 | AS28: =S28 -> 85.844 | AT28: 206.707 | AU28: 197.166 | AV28: 131.115 | AW28: 211.154 | AX28: 208.234 | AY28: =AY64*'Earnings Model'!BQ14/365 -> 263.83413 | AZ28: =AZ64*'Earnings Model'!BR14/365 -> 453.97353 | BA28: =BA64*'Earnings Model'!BS14/365 -> 615.41962
B29: Others | C29: =C30-C27-C28 -> 0 | D29: =D30-D27-D28 -> 0 | E29: =E30-E27-E28 -> 0 | F29: =F30-F27-F28 -> 0 | G29: =G30-G27-G28 -> 0 | H29: =H30-H27-H28 -> 0 | I29: =I30-I27-I28 -> 0 | J29: =J30-J27-J28 -> 0 | ... AM29: =AM30-AM27-AM28 -> 561.409 | AO29: =AO30-AO27-AO28 -> 108.022 | AP29: =AP30-AP27-AP28 -> 160.545 | AQ29: =AQ30-AQ27-AQ28 -> 352.646 | AR29: =AR30-AR27-AR28 -> 188.419 | AS29: =S29 -> 150.588 | AT29: =AT30-AT27-AT28 -> 230.59 | AU29: =AU30-AU27-AU28 -> 442.263 | AV29: =AV30-AV27-AV28 -> 260.058 | AW29: =AW30-AW27-AW28 -> 468.724 | AX29: =AX30-AX27-AX28 -> 561.409 | AY29: =AX29 -> 561.409 | AZ29: =AY29 -> 561.409 | BA29: =AZ29 -> 561.409
B30: Current Liabilities | C30: 0 | D30: 0 | E30: 0 | F30: 0 | G30: 0 | H30: 0 | I30: 0 | J30: 0 | K30: 427.02387 | L30: 0 | M30: 268.46659 | N30: 259.907 | O30: 279.71266 | P30: 317.30442 | Q30: 630.23546 | R30: 236.55965 | S30: 236.432 | T30: 246.414 | U30: 338.419 | V30: 526.037 | W30: 437.297 | X30: 478.959 | Y30: 1105.617 | Z30: 459.916 | AA30: 639.429 | AB30: 423.31 | AC30: 706.981 | AD30: 386.273 | AE30: 391.173 | AF30: 369.801 | AG30: 377.776 | AH30: 520.687 | AI30: 679.878 | AJ30: 527.27 | AK30: 591.945 | AL30: 961.35 | AM30: 769.643 | AO30: 220.232 | AP30: 267.858 | AQ30: 427.024 | AR30: 279.713 | AS30: =S30 -> 236.432 | AT30: 437.297 | AU30: 639.429 | AV30: 391.173 | AW30: 679.878 | AX30: 769.643 | AY30: =SUM(AY27:AY29) -> 825.24313 | AZ30: =SUM(AZ27:AZ29) -> 1015.3825 | BA30: =SUM(BA27:BA29) -> 1176.8286
B31: Long-Term Debt | C31: 0 | D31: 0 | E31: 0 | F31: 0 | G31: 0 | H31: 0 | I31: 0 | J31: 0 | K31: 0 | L31: 0 | M31: 0 | N31: 0 | O31: 0 | P31: 0 | Q31: 0 | R31: 0 | S31: 0 | T31: 0 | U31: 0 | V31: 0 | W31: 0 | X31: 0 | Y31: 0 | Z31: 0 | AA31: 0 | AB31: 0 | AC31: 0 | AD31: 0 | AE31: 0 | AF31: 0 | AG31: 0 | AH31: 0 | AI31: 0 | AJ31: 0 | AK31: 0 | AL31: 0 | AM31: 0 | AO31: 0 | AP31: 0 | AQ31: 0 | AR31: 0 | AS31: =S31 -> 0 | AT31: 0 | AU31: 0 | AV31: 0 | AW31: 0 | AX31: 0 | AY31: =AX31+'Cash Flow'!O34 -> 0 | AZ31: =AY31+'Cash Flow'!P34 -> 0 | BA31: =AZ31+'Cash Flow'!Q34 -> 0
B32: Other Liabilities | C32: =C33-C30-C31 -> 0 | D32: =D33-D30-D31 -> 0 | E32: =E33-E30-E31 -> 0 | F32: =F33-F30-F31 -> 0 | G32: =G33-G30-G31 -> 0 | H32: =H33-H30-H31 -> 0 | I32: =I33-I30-I31 -> 0 | J32: =J33-J30-J31 -> 0 | ... Q32: =Q33-Q30-Q31 -> 174.35968 | R32: 172.65484 | S32: 172.65484 | T32: 173.65484 | U32: 174.65484 | V32: 174.65484 | W32: 174.65484 | X32: 174.65484 | Y32: 175.65484 | Z32: 176.65484 | AA32: 177.65484 | AB32: 178.65484 | AC32: 179.65484 | AD32: 180.65484 | AE32: 181.65484 | AF32: 182.65484 | AG32: 183.65484 | AH32: 184.65484 | AI32: 184.65484 | AJ32: 184.65484 | AK32: 184.65484 | AL32: 184.65484 | AM32: 184.65484 | AO32: =AO33-AO30-AO31 -> 18.088 | AP32: =AP33-AP30-AP31 -> 19.828 | AQ32: =AQ33-AQ30-AQ31 -> 137.884 | AR32: =AR33-AR30-AR31 -> 171.316 | AS32: =AS33-AS30-AS31 -> 112.759 | AT32: =AT33-AT30-AT31 -> 130.566 | AU32: =AU33-AU30-AU31 -> 119.362 | AV32: =AV33-AV30-AV31 -> 99.749 | ... AX32: =AX33-AX30-AX31 -> 107.349 | AY32: =AX32 -> 107.349 | AZ32: =AY32 -> 107.349 | BA32: =AZ32 -> 107.349
B33: Total Liabilities | C33: 0 | D33: 0 | E33: 0 | F33: 0 | G33: 0 | H33: 0 | I33: 0 | J33: 0 | K33: 564.90763 | L33: 0 | M33: 407.95641 | N33: 426.29 | O33: 451.02911 | P33: 493.17666 | Q33: 804.59514 | R33: 435.24491 | S33: 349.191 | T33: 378.378 | U33: 492.414 | V33: 629.901 | W33: 567.863 | X33: 624.798 | Y33: 1307.371 | Z33: 611.548 | AA33: 758.791 | AB33: 538.151 | AC33: 813.221 | AD33: 484.821 | AE33: 490.922 | AF33: 493.057 | AG33: 490.774 | AH33: 634.945 | AI33: 822.406 | AJ33: 723.952 | AK33: 818.532 | AL33: 1494.538 | AM33: 876.992 | AO33: 238.32 | AP33: 287.686 | AQ33: 564.908 | AR33: 451.029 | AS33: =S33 -> 349.191 | AT33: 567.863 | AU33: 758.791 | AV33: 490.922 | AW33: 822.406 | AX33: 876.992 | AY33: =SUM(AY30:AY32) -> 932.59213 | AZ33: =SUM(AZ30:AZ32) -> 1122.7315 | BA33: =SUM(BA30:BA32) -> 1284.1776
B35: Issued Capital | C35: 0 | D35: 0 | E35: 0 | F35: 0 | G35: 0 | H35: 0 | I35: 0 | J35: 0 | K35: 1016.8325 | L35: 0 | M35: 1016.8325 | N35: 1129.814 | O35: 1129.8139 | P35: 1129.8139 | Q35: 1129.8139 | R35: 1129.8139 | S35: 1129.814 | T35: 1131.03 | U35: 1131.03 | V35: 1131.03 | W35: 1131.307 | X35: 1132.824 | Y35: 1132.824 | Z35: 1133.657 | AA35: 1134.068 | AB35: 1136.078 | AC35: 1137.357 | AD35: 1138.008 | AE35: 1138.74 | AF35: 1141.461 | AG35: 1141.461 | AH35: 1142.538 | AI35: 1144.789 | AJ35: 1144.789 | AK35: 1144.789 | AL35: 1145.151 | AM35: 1146.427 | AO35: 757.032 | AP35: 757.032 | AQ35: 1016.833 | AR35: 1129.814 | AS35: =S35 -> 1129.814 | AT35: 1131.307 | AU35: 1134.068 | AV35: 1138.74 | AW35: 1144.789 | AX35: 1146.427 | AY35: =AX35 -> 1146.427 | AZ35: =AY35 -> 1146.427 | BA35: =AZ35 -> 1146.427
B36: Additional Capital | C36: 0 | D36: 0 | E36: 0 | F36: 0 | G36: 0 | H36: 0 | I36: 0 | J36: 0 | K36: 1831.0733 | L36: 0 | M36: 2065.9065 | N36: 4699.483 | O36: 4699.4832 | P36: 4754.0833 | Q36: 4811.7697 | R36: 4866.7057 | S36: 4901.652 | T36: 4978.936 | U36: 5025.642 | V36: 5068.586 | W36: 5113.492 | X36: 5179.278 | Y36: 5215.371 | Z36: 5279.672 | AA36: 5329.258 | AB36: 5412.181 | AC36: 5342.457 | AD36: 5393.062 | AE36: 5432.387 | AF36: 5508.174 | AG36: 5519.012 | AH36: 5556.229 | AI36: 5625.97 | AJ36: 5673.134 | AK36: 5717.509 | AL36: 5777.616 | AM36: 6114.018 | AO36: 66.185 | AP36: 66.185 | AQ36: 1831.073 | AR36: 4699.483 | AS36: =S36 -> 4901.652 | AT36: 5113.492 | AU36: 5329.258 | AV36: 5432.387 | AW36: 5625.97 | AX36: 6114.018 | AY36: =AX36+'Cash Flow'!O35 -> 12414.018 | AZ36: =AY36+'Cash Flow'!P35 -> 12414.018 | BA36: =AZ36+'Cash Flow'!Q35 -> 12414.018
B37: Treasury Stocks | C37: 0 | D37: 0 | E37: 0 | F37: 0 | G37: 0 | H37: 0 | I37: 0 | J37: 0 | K37: 0 | L37: 0 | M37: 0 | N37: 0 | O37: 0 | P37: 0 | Q37: 0 | R37: 0 | S37: 0 | T37: 0 | U37: 0 | V37: 0 | W37: -300.083 | X37: -300.083 | Y37: -300.083 | Z37: -300.083 | AA37: -300.083 | AB37: -300.083 | AC37: 0 | AD37: -173.871 | AE37: -300.031 | AF37: -602.478 | AG37: -709.089 | AH37: -709.089 | AI37: -427.558 | AJ37: -427.558 | AK37: -506.621 | AL37: -628.081 | AM37: -848.359 | AO37: 0 | AP37: 0 | AQ37: 0 | AR37: 0 | AS37: =S37 -> 0 | AT37: -300.083 | AU37: -300.083 | AV37: -300.031 | AW37: -427.558 | AX37: -848.359 | AY37: =AX37 -> -848.359 | AZ37: =AY37 -> -848.359 | BA37: =AZ37 -> -848.359
B38: Retained earnings | C38: 0 | D38: 0 | E38: 0 | F38: 0 | G38: 0 | H38: 0 | I38: 0 | J38: 0 | K38: 664.0965 | L38: 0 | M38: 881.05222 | N38: 1173.735 | O38: 1306.6763 | P38: 1569.6646 | Q38: 1569.2568 | R38: 1845.5006 | S38: 2021.29 | T38: 2154.385 | U38: 1988.82 | V38: 2193.423 | W38: 2461.879 | X38: 2767.846 | Y38: 2803.43 | Z38: 3137.781 | AA38: 3386.154 | AB38: 3405.875 | AC38: 3126.802 | AD38: 3278.751 | AE38: 3478.054 | AF38: 3701.462 | AG38: 3733.014 | AH38: 4117.938 | AI38: 4518.383 | AJ38: 5043.709 | AK38: 5234.313 | AL38: 5480.671 | AM38: 6018.558 | AO38: -17.148 | AP38: 312.375 | AQ38: 664.096 | AR38: 1306.676 | AS38: =S38 -> 2021.29 | AT38: 2461.879 | AU38: 3386.154 | AV38: 3478.054 | AW38: 4518.383 | AX38: 6018.558 | AY38: =AX38+'Earnings Model'!BQ57+'Cash Flow'!O36 -> 9610.0922 | AZ38: =AY38+'Earnings Model'!BR57+'Cash Flow'!P36 -> 17033.674 | BA38: =AZ38+'Earnings Model'!BS57+'Cash Flow'!Q36 -> 27785.958
B39: Others | C39: =C40-SUM(C35:C38) -> 1121.344 | D39: =D40-SUM(D35:D38) -> -2146826265 | E39: =E40-SUM(E35:E38) -> -2146826265 | F39: =F40-SUM(F35:F38) -> -2146826265 | G39: =G40-SUM(G35:G38) -> 1474.693 | H39: =H40-SUM(H35:H38) -> -2146826265 | I39: =I40-SUM(I35:I38) -> -2146826265 | J39: =J40-SUM(J35:J38) -> -2146826265 | ... AM39: =AM40-SUM(AM35:AM38) -> 440.512 | AO39: =AO40-SUM(AO35:AO38) -> 76.955 | AP39: =AP40-SUM(AP35:AP38) -> 51.415 | AQ39: =AQ40-SUM(AQ35:AQ38) -> 103.747 | AR39: =AR40-SUM(AR35:AR38) -> 193.751 | AS39: =AS40-SUM(AS35:AS38) -> 17.495 | AT39: =AT40-SUM(AT35:AT38) -> -15.896 | AU39: =AU40-SUM(AU35:AU38) -> 377.858 | AV39: =AV40-SUM(AV35:AV38) -> 457.469 | ... AX39: =AX40-SUM(AX35:AX38) -> 440.511 | AY39: =AX39 -> 440.511 | AZ39: =AY39 -> 440.511 | BA39: =AZ39 -> 440.511
