Workbook
Name A_ALL_000050.SZ: #REF!
Name A_ALL_000413.SZ: #REF!
Name A_ALL_000725.SZ: #REF!
Name A_ALL_002371.SZ: #REF!
Name A_ALL_002415.SZ: #REF!
Name A_ALL_002415.SZ_: #REF!
Name A_ALL_002456.SZ: #REF!
Name A_ALL_002876.SZ: #REF!
Name A_ALL_2018.HK: #REF!
Name A_ALL_2303.TW: '[1]2303.TW_Annotation_Sheet'!$A$1:$CD$384
Name A_ALL_2303.TW: #REF!
Name A_ALL_2324.TW: #REF!
Name A_ALL_300502.SZ: #REF!
Name A_ALL_4966.TWO: #REF!
Name A_ALL_600584.SS: #REF!
Name A_ALL_600699.SS: #REF!
Name A_ALL_603986.SS: #REF!
Name A_ALL_6415.TW: '[2]6415.TW_Annotation_Sheet'!$A$1:$BZ$286
Name A_ALL_6415.TW: #REF!
Name A_ALL_KEYWORDS_TYPE_Breakdown_EQTY_200004222: #REF!,#REF!
Name A_ALL_KEYWORDS_TYPE_Breakdown_EQTY_200004679: #REF!,#REF!
Name A_ALL_KEYWORDS_TYPE_Breakdown_EQTY_200008919: #REF!
Name A_ALL_KEYWORDS_TYPE_ScalarContributed_EQTY_200004222: #REF!,#REF!
Name A_ALL_KEYWORDS_TYPE_ScalarContributed_EQTY_200004679: #REF!,#REF!,#REF!,#REF!
Name A_ALL_KEYWORDS_TYPE_ScalarContributed_EQTY_200006786: #REF!,#REF!,#REF!,#REF!
Name A_ALL_KEYWORDS_TYPE_ScalarContributed_EQTY_200007666: #REF!,#REF!
Name A_ALL_KEYWORDS_TYPE_ScalarContributed_EQTY_200008919: #REF!,#REF!
Name A_ALL_KEYWORDS_TYPE_ScalarContributed_EQTY_200011172: #REF!,#REF!
Name A_ALL_KEYWORDS_TYPE_ScalarContributed_EQTY_200012735: #REF!,#REF!
Name A_ALL_KEYWORDS_TYPE_ScalarContributed_EQTY_200012909: #REF!,#REF!
Name A_ALL_KEYWORDS_TYPE_ScalarContributed_EQTY_200012913: #REF!,#REF!
Name A_ALL_KEYWORDS_TYPE_ScalarContributed_EQTY_200016087: #REF!,#REF!
Name A_ALL_KEYWORDS_TYPE_ScalarContributed_EQTY_200019451: #REF!,#REF!,#REF!
Name A_ALL_KEYWORDS_TYPE_ScalarContributed_EQTY_200019558: #REF!,#REF!
Name A_ALL_KEYWORDS_TYPE_ScalarContributed_EQTY_200019559: #REF!,#REF!
Name A_ALL_KEYWORDS_TYPE_ScalarContributed_ISSR_208001202: #REF!,#REF!
Name A_ALL_KEYWORDS_TYPE_ScalarContributed_ISSR_208001316: #REF!,#REF!
Name A_ALL_KEYWORDS_TYPE_ScalarContributed_ISSR_208002015: #REF!,#REF!
Name A_ALL_KEYWORDS_TYPE_ScalarContributed_ISSR_208003261: #REF!,#REF!
Name A_ALL_KEYWORDS_TYPE_ScalarContributed_ISSR_208007067: #REF!,#REF!
Name A_ALL_KEYWORDS_TYPE_ScalarContributed_ISSR_208010212: #REF!,#REF!
Name A_ALL_KEYWORDS_TYPE_ScalarContributed_ISSR_208015000: #REF!,#REF!
Name A_ALL_KEYWORDS_TYPE_ScalarContributed_ISSR_208019081: #REF!,#REF!
Name A_ALL_KEYWORDS_TYPE_ScalarContributed_ISSR_208019322: #REF!,#REF!
Name A_ALL_KEYWORDS_TYPE_ScalarContributed_ISSR_208021173: #REF!,#REF!
Name A_ALL_KEYWORDS_TYPE_ScalarContributed_ISSR_208021175: #REF!,#REF!
Name A_ALL_KEYWORDS_TYPE_Vector_EQTY_200004222: #REF!,#REF!,#REF!,#REF!,#REF!
Name A_ALL_KEYWORDS_TYPE_Vector_EQTY_200004679: #REF!,#REF!,#REF!,#REF!,#REF!
Name A_ALL_KEYWORDS_TYPE_Vector_EQTY_200006785: #REF!,#REF!,#REF!,#REF!,#REF!
Name A_ALL_KEYWORDS_TYPE_Vector_EQTY_200006786: #REF!,#REF!,#REF!,#REF!,#REF!,#REF!
Name A_ALL_KEYWORDS_TYPE_Vector_EQTY_200007666: #REF!,#REF!,#REF!,#REF!,#REF!
Name A_ALL_KEYWORDS_TYPE_Vector_EQTY_200008918: #REF!,#REF!,#REF!,#REF!,#REF!
Name A_ALL_KEYWORDS_TYPE_Vector_EQTY_200011172: #REF!,#REF!,#REF!,#REF!,#REF!
Name A_ALL_KEYWORDS_TYPE_Vector_EQTY_200012735: #REF!,#REF!,#REF!,#REF!,#REF!
Name A_ALL_KEYWORDS_TYPE_Vector_EQTY_200012909: #REF!,#REF!,#REF!,#REF!,#REF!
Name A_ALL_KEYWORDS_TYPE_Vector_EQTY_200012913: #REF!,#REF!,#REF!,#REF!,#REF!
Name A_ALL_KEYWORDS_TYPE_Vector_EQTY_200013283: #REF!,#REF!,#REF!,#REF!,#REF!
Name A_ALL_KEYWORDS_TYPE_Vector_EQTY_200016087: #REF!,#REF!,#REF!,#REF!,#REF!
Name A_ALL_KEYWORDS_TYPE_Vector_EQTY_200017468: #REF!,#REF!,#REF!,#REF!,#REF!
Name A_ALL_KEYWORDS_TYPE_Vector_EQTY_200018245: #REF!,#REF!,#REF!,#REF!,#REF!

Sheet Cover Page 
B4: Greater China Technology Team
B6: Eoptolink (300502.SZ)
B7: Rating | C7: Buy
B8: Target Price/ Target price period/ Upside/downside to target price | C8: 633/ 12 Month/ 24.1%
B9: M&A probability (1 = high, 3 = low) | C9: 3
B10: Market Cap (US$ mn) (price as of Jul 20, 2026): | C10: 105054.36
B11: Current shares outstanding (mn): | C11: =Model!BT56 -> 1391.5613
B12: Currency: | C12: CNY
B13: Current Publication Date: | C13: 46223
B14: Previous Publication Date: | C14: 46210
B16: Team Contacts:
B17: Primary Analyst
B18: Ting Song, ting.song@gs.com, +852 2978 6466 Goldman Sachs (Asia) L.L.C.
B19: Allen Chang, allen.k.chang@gs.com, +852 2978 2930 Goldman Sachs (Asia) L.L.C.
B20: Verena Jeng, verena.jeng@gs.com, +852 2978 1681 Goldman Sachs (Asia) L.L.C.

Sheet 300502.SZ_Exchange_Sheet 
A1: Issuer: Eoptolink | F1: 2011 | G1: 2012 | H1: 2013 | I1: 2014 | J1: 2015 | K1: 2016 | L1: 2017 | M1: 2018 | N1: 2019 | O1: 2020 | P1: 2021 | Q1: 2022 | R1: 2023 | S1: 2024 | T1: 2025 | U1: 2026 | V1: 2027 | W1: 2028 | Y1: 2015 Q1 | Z1: 2015 Q2 | AA1: 2015 Q3 | AB1: 2015 Q4 | AC1: 2016 Q1 | AD1: 2016 Q2 | AE1: 2016 Q3 | AF1: 2016 Q4 | AG1: 2017 Q1 | AH1: 2017 Q2 | AI1: 2017 Q3 | AJ1: 2017 Q4 | AK1: 2018 Q1 | AL1: 2018 Q2 | AM1: 2018 Q3 | AN1: 2018 Q4 | AO1: 2019 Q1 | AP1: 2019 Q2 | AQ1: 2019 Q3 | AR1: 2019 Q4 | AS1: 2020 Q1 | AT1: 2020 Q2 | AU1: 2020 Q3 | AV1: 2020 Q4 | AW1: 2021 Q1 | AX1: 2021 Q2 | AY1: 2021 Q3 | AZ1: 2021 Q4 | BA1: 2022 Q1 | BB1: 2022 Q2 | BC1: 2022 Q3 | BD1: 2022 Q4 | BE1: 2023 Q1 | BF1: 2023 Q2 | BG1: 2023 Q3 | BH1: 2023 Q4 | BI1: 2024 Q1 | BJ1: 2024 Q2 | BK1: 2024 Q3 | BL1: 2024 Q4 | BM1: 2025 Q1 | BN1: 2025 Q2 | BO1: 2025 Q3 | BP1: 2025 Q4 | BQ1: 2026 Q1 | BR1: 2026 Q2 | BS1: 2026 Q3 | BT1: 2026 Q4 | BU1: 2027 Q1 | BV1: 2027 Q2 | BW1: 2027 Q3 | BX1: 2027 Q4
A2: ISSUER ID: 208021942 | F2: Actual | G2: Actual | H2: Actual | I2: Actual | J2: Actual | K2: Actual | L2: Actual | M2: Actual | N2: Actual | O2: Actual | P2: Actual | Q2: Actual | R2: Actual | S2: Actual | T2: Actual | U2: Estimate | V2: Estimate | W2: Estimate | Y2: Actual | Z2: Actual | AA2: Actual | AB2: Actual | AC2: Actual | AD2: Actual | AE2: Actual | AF2: Actual | AG2: Actual | AH2: Actual | AI2: Actual | AJ2: Actual | AK2: Actual | AL2: Actual | AM2: Actual | AN2: Actual | AO2: Actual | AP2: Actual | AQ2: Actual | AR2: Actual | AS2: Actual | AT2: Actual | AU2: Actual | AV2: Actual | AW2: Actual | AX2: Actual | AY2: Actual | AZ2: Actual | BA2: Actual | BB2: Actual | BC2: Actual | BD2: Actual | BE2: Actual | BF2: Actual | BG2: Actual | BH2: Actual | BI2: Actual | BJ2: Actual | BK2: Actual | BL2: Actual | BM2: Actual | BN2: Actual | BO2: Actual | BP2: Actual | BQ2: Actual | BR2: Estimate | BS2: Estimate | BT2: Estimate | BU2: Estimate | BV2: Estimate | BW2: Estimate | BX2: Estimate
F3: 40908 | G3: 41274 | H3: 41639 | I3: 42004 | J3: 42369 | K3: 42735 | L3: 43100 | M3: 43465 | N3: 43830 | O3: 44196 | P3: 44561 | Q3: 44926 | R3: 45291 | S3: 45657 | T3: 46022 | U3: 46387 | V3: 46752 | W3: 47118 | Y3: 42094 | Z3: 42185 | AA3: 42277 | AB3: 42369 | AC3: 42460 | AD3: 42551 | AE3: 42643 | AF3: 42735 | AG3: 42825 | AH3: 42916 | AI3: 43008 | AJ3: 43100 | AK3: 43190 | AL3: 43281 | AM3: 43373 | AN3: 43465 | AO3: 43555 | AP3: 43646 | AQ3: 43738 | AR3: 43830 | AS3: 43921 | AT3: 44012 | AU3: 44104 | AV3: 44196 | AW3: 44286 | AX3: 44377 | AY3: 44469 | AZ3: 44561 | BA3: 44651 | BB3: 44742 | BC3: 44834 | BD3: 44926 | BE3: 45016 | BF3: 45107 | BG3: 45199 | BH3: 45291 | BI3: 45382 | BJ3: 45473 | BK3: 45565 | BL3: 45657 | BM3: 45747 | BN3: 45838 | BO3: 45930 | BP3: 46022 | BQ3: 46112 | BR3: 46203 | BS3: 46295 | BT3: 46387 | BU3: 46477 | BV3: 46568 | BW3: 46660 | BX3: 46752
A4: Issuer: Eoptolink
A5: Reference Data
B6: Issuer Name | C6: Issuer Name | E6: Eoptolink
B7: Reporting Currency | C7: CURRENCY_ISO | E7: CNY
A8: General Information
B9: M&A probability (1 = high, 3 = low) | C9: MA_PROB | E9: 3
A10: Income Statement
B11: Sales, net revenue | C11: SALES | D11: =E_CURRENCY_ISSR_208021942_REP -> CNY | F11: =[5]Model!E7 -> 304.92843 | G11: =[5]Model!F7 -> 347.56807 | H11: =[5]Model!G7 -> 461.049 | I11: =[5]Model!H7 -> 522.63427 | J11: =[5]Model!I7 -> 615.11958 | K11: =[5]Model!J7 -> 713.93165 | L11: =[5]Model!K7 -> 877.36536 | M11: =[5]Model!L7 -> 759.95028 | ... W11: =[5]Model!V7 -> 84975.376 | Y11: =[5]Model!AB7 -> 141.26116 | Z11: =[5]Model!AC7 -> 166.47504 | AA11: =[5]Model!AD7 -> 142.20005 | AB11: =[5]Model!AE7 -> 165.18332 | AC11: =[5]Model!AF7 -> 146.321 | AD11: =[5]Model!AG7 -> 192.79163 | AE11: =[5]Model!AH7 -> 170.51717 | AF11: =[5]Model!AI7 -> 204.30185 | ... BX11: =[5]Model!CA7 -> 20276.903
B12: Compensation & benfits expense | C12: PERSONNEL | D12: =E_CURRENCY_ISSR_208021942_REP -> CNY
B13: Cost of goods sold, COGS | C13: COST_GD_SD | D13: =E_CURRENCY_ISSR_208021942_REP -> CNY | F13: =-[5]Model!E10 -> -213.53676 | G13: =-[5]Model!F10 -> -234.62009 | H13: =-[5]Model!G10 -> -330.78362 | I13: =-[5]Model!H10 -> -363.06989 | J13: =-[5]Model!I10 -> -446.55322 | K13: =-[5]Model!J10 -> -525.653 | L13: =-[5]Model!K10 -> -666.78476 | M13: =-[5]Model!L10 -> -611.69329 | ... W13: =-[5]Model!V10 -> -43619.538 | Y13: =-[5]Model!AB10 -> -101.0667 | Z13: =-[5]Model!AC10 -> -121.38813 | AA13: =-[5]Model!AD10 -> -103.18521 | AB13: =-[5]Model!AE10 -> -120.91319 | AC13: =-[5]Model!AF10 -> -110.12175 | AD13: =-[5]Model!AG10 -> -143.06903 | AE13: =-[5]Model!AH10 -> -117.13324 | AF13: =-[5]Model!AI10 -> -155.32899 | ... BX13: =-[5]Model!CA10 -> -10233.746
B14: SG&A, selling, general and admin. expense | C14: SEL_GL_AD | D14: =E_CURRENCY_ISSR_208021942_REP -> CNY | F14: =-[5]Model!E16-[5]Model!E17-[5]Model!E18 -> -13.704189 | G14: =-[5]Model!F16-[5]Model!F17-[5]Model!F18 -> -19.558636 | H14: =-[5]Model!G16-[5]Model!G17-[5]Model!G18 -> -19.32508 | I14: =-[5]Model!H16-[5]Model!H17-[5]Model!H18 -> -30.516253 | J14: =-[5]Model!I16-[5]Model!I17-[5]Model!I18 -> -31.549274 | K14: =-[5]Model!J16-[5]Model!J17-[5]Model!J18 -> -35.348699 | L14: =-[5]Model!K16-[5]Model!K17-[5]Model!K18 -> -37.046046 | M14: =-[5]Model!L16-[5]Model!L17-[5]Model!L18 -> -52.506831 | ... W14: =-[5]Model!V16-[5]Model!V17-[5]Model!V18 -> -888.51887 | Y14: =-[5]Model!AB16-[5]Model!AB17-[5]Model!AB18 -> -5.6643154 | Z14: =-[5]Model!AC16-[5]Model!AC17-[5]Model!AC18 -> -8.0558268 | AA14: =-[5]Model!AD16-[5]Model!AD17-[5]Model!AD18 -> -7.9521598 | AB14: =-[5]Model!AE16-[5]Model!AE17-[5]Model!AE18 -> -9.8611696 | AC14: =-[5]Model!AF16-[5]Model!AF17-[5]Model!AF18 -> -5.7882392 | AD14: =-[5]Model!AG16-[5]Model!AG17-[5]Model!AG18 -> -7.7444157 | AE14: =-[5]Model!AH16-[5]Model!AH17-[5]Model!AH18 -> -10.190174 | AF14: =-[5]Model!AI16-[5]Model!AI17-[5]Model!AI18 -> -11.610822 | ... BX14: =-[5]Model!CA16-[5]Model!CA17-[5]Model!CA18 -> -182.94597
B15: Total operating expense | C15: OP_COST | D15: =E_CURRENCY_ISSR_208021942_REP -> CNY | F15: =F13+F14 -> -227.24095 | G15: =G13+G14 -> -254.17873 | H15: =H13+H14 -> -350.1087 | I15: =I13+I14 -> -393.58614 | J15: =J13+J14 -> -478.10249 | K15: =K13+K14 -> -561.0017 | L15: =L13+L14 -> -703.83081 | M15: =M13+M14 -> -664.20012 | ... W15: =W13+W14 -> -44508.057 | Y15: =Y13+Y14 -> -106.73101 | Z15: =Z13+Z14 -> -129.44395 | AA15: =AA13+AA14 -> -111.13737 | AB15: =AB13+AB14 -> -130.77436 | AC15: =AC13+AC14 -> -115.90998 | AD15: =AD13+AD14 -> -150.81344 | AE15: =AE13+AE14 -> -127.32341 | AF15: =AF13+AF14 -> -166.93981 | ... BX15: =BX13+BX14 -> -10416.692
B16: R&D expense | C16: RD_EXP | D16: =E_CURRENCY_ISSR_208021942_REP -> CNY | F16: =-[5]Model!E19 -> -10.77461 | G16: =-[5]Model!F19 -> -14.292519 | H16: =-[5]Model!G19 -> -16.201662 | I16: =-[5]Model!H19 -> -18.188965 | J16: =-[5]Model!I19 -> -23.420253 | K16: =-[5]Model!J19 -> -29.256149 | L16: =-[5]Model!K19 -> -44.921107 | M16: =-[5]Model!L19 -> -52.66467 | ... W16: =-[5]Model!V19 -> -984.4 | Y16: =-[5]Model!AB19 -> -5.38205 | Z16: =-[5]Model!AC19 -> -6.3426992 | AA16: =-[5]Model!AD19 -> -5.4178219 | AB16: =-[5]Model!AE19 -> -6.2934847 | AC16: =-[5]Model!AF19 -> -5.9991611 | AD16: =-[5]Model!AG19 -> -7.9044569 | AE16: =-[5]Model!AH19 -> -6.991204 | AF16: =-[5]Model!AI19 -> -8.3763757 | ... BX16: =-[5]Model!CA19 -> -332.5
B17: Other operating income/(expense) (incl. leases) | C17: OTH_OP_INC_EXP | D17: =E_CURRENCY_ISSR_208021942_REP -> CNY
B18: Total operating expense (incl. D&A) | C18: TOT_OPS_EXP_DDA | D18: =E_CURRENCY_ISSR_208021942_REP -> CNY | F18: =F15+F16 -> -238.01556 | G18: =G15+G16 -> -268.47125 | H18: =H15+H16 -> -366.31036 | I18: =I15+I16 -> -411.7751 | J18: =J15+J16 -> -501.52274 | K18: =K15+K16 -> -590.25785 | L18: =L15+L16 -> -748.75191 | M18: =M15+M16 -> -716.86479 | ... W18: =W15+W16 -> -45492.457 | Y18: =Y15+Y16 -> -112.11306 | Z18: =Z15+Z16 -> -135.78665 | AA18: =AA15+AA16 -> -116.55519 | AB18: =AB15+AB16 -> -137.06784 | AC18: =AC15+AC16 -> -121.90915 | AD18: =AD15+AD16 -> -158.7179 | AE18: =AE15+AE16 -> -134.31462 | AF18: =AF15+AF16 -> -175.31619 | ... BX18: =BX15+BX16 -> -10749.192
B19: Total operating expense (excl. D&A) | C19: TOT_OPS_EXP | D19: =E_CURRENCY_ISSR_208021942_REP -> CNY | F19: =F18-F21-F22 -> -235.09806 | G19: =G18-G21-G22 -> -265.56485 | H19: =H18-H21-H22 -> -360.81015 | I19: =I18-I21-I22 -> -399.38829 | J19: =J18-J21-J22 -> -485.87516 | K19: =K18-K21-K22 -> -565.94531 | L19: =L18-L21-L22 -> -701.46852 | M19: =M18-M21-M22 -> -662.95614 | ... W19: =W18-W21-W22 -> -44458.69 | Y19: =Y18-Y21-Y22 -> -108.46433 | Z19: =Z18-Z21-Z22 -> -132.13792 | AA19: =AA18-AA21-AA22 -> -112.90645 | AB19: =AB18-AB21-AB22 -> -133.41911 | AC19: =AC18-AC21-AC22 -> -118.26041 | AD19: =AD18-AD21-AD22 -> -155.06917 | AE19: =AE18-AE21-AE22 -> -125.81847 | AF19: =AF18-AF21-AF22 -> -166.82004 | ... BX19: =BX18-BX21-BX22 -> -10537.294
B20: EBITDA | C20: EBITDA_CALC | D20: =E_CURRENCY_ISSR_208021942_REP -> CNY | F20: =[5]Model!E46 -> 69.83037 | G20: =[5]Model!F46 -> 82.00322 | H20: =[5]Model!G46 -> 100.23885 | I20: =[5]Model!H46 -> 123.24598 | J20: =[5]Model!I46 -> 129.24441 | K20: =[5]Model!J46 -> 147.98634 | L20: =[5]Model!K46 -> 175.89684 | M20: =[5]Model!L46 -> 96.994142 | ... W20: =[5]Model!V46 -> 40516.685 | Y20: =[5]Model!AB46 -> 32.79683 | Z20: =[5]Model!AC46 -> 34.337127 | AA20: =[5]Model!AD46 -> 29.293594 | AB20: =[5]Model!AE46 -> 31.764219 | AC20: =[5]Model!AF46 -> 28.060592 | AD20: =[5]Model!AG46 -> 37.722466 | AE20: =[5]Model!AH46 -> 44.698701 | AF20: =[5]Model!AI46 -> 37.481809 | ... BX20: =[5]Model!CA46 -> 9739.609
B21: Depreciation | C21: DEPREC | D21: =E_CURRENCY_ISSR_208021942_REP -> CNY | F21: =-[5]Model!E44 -> -2.7811 | G21: =-[5]Model!F44 -> -2.8049 | H21: =-[5]Model!G44 -> -5.2721238 | I21: =-[5]Model!H44 -> -12.068054 | J21: =-[5]Model!I44 -> -15.214017 | K21: =-[5]Model!J44 -> -23.896633 | L21: =-[5]Model!K44 -> -46.862284 | M21: =-[5]Model!L44 -> -53.2327 | ... W21: =-[5]Model!V44 -> -1018.9813 | Y21: =-[5]Model!AB44 -> -3.5434411 | Z21: =-[5]Model!AC44 -> -3.5434411 | AA21: =-[5]Model!AD44 -> -3.5434411 | AB21: =-[5]Model!AE44 -> -3.5434411 | AC21: =-[5]Model!AF44 -> -3.5434411 | AD21: =-[5]Model!AG44 -> -3.5434411 | AE21: =-[5]Model!AH44 -> -8.3934916 | AF21: =-[5]Model!AI44 -> -8.3934916 | ... BX21: =-[5]Model!CA44 -> -207.5998
B22: Amortization | C22: GOODWILL_AMORT | D22: =E_CURRENCY_ISSR_208021942_REP -> CNY | F22: =-[5]Model!E45 -> -0.1364 | G22: =-[5]Model!F45 -> -0.1015 | H22: =-[5]Model!G45 -> -0.22808715 | I22: =-[5]Model!H45 -> -0.31876193 | J22: =-[5]Model!I45 -> -0.43356578 | K22: =-[5]Model!J45 -> -0.41590236 | L22: =-[5]Model!K45 -> -0.42110674 | M22: =-[5]Model!L45 -> -0.67595024 | ... W22: =-[5]Model!V45 -> -14.785555 | Y22: =-[5]Model!AB45 -> -0.105294 | Z22: =-[5]Model!AC45 -> -0.105294 | AA22: =-[5]Model!AD45 -> -0.105294 | AB22: =-[5]Model!AE45 -> -0.105294 | AC22: =-[5]Model!AF45 -> -0.105294 | AD22: =-[5]Model!AG45 -> -0.105294 | AE22: =-[5]Model!AH45 -> -0.10265718 | AF22: =-[5]Model!AI45 -> -0.10265718 | ... BX22: =-[5]Model!CA45 -> -4.2981265
B23: EBIT, operating profit | C23: EBIT | D23: =E_CURRENCY_ISSR_208021942_REP -> CNY | F23: =[5]Model!E43 -> 66.91287 | G23: =[5]Model!F43 -> 79.09682 | H23: =[5]Model!G43 -> 94.738635 | I23: =[5]Model!H43 -> 110.85916 | J23: =[5]Model!I43 -> 113.59683 | K23: =[5]Model!J43 -> 123.6738 | L23: =[5]Model!K43 -> 128.61345 | M23: =[5]Model!L43 -> 43.085493 | ... W23: =[5]Model!V43 -> 39482.918 | Y23: =[5]Model!AB43 -> 29.148095 | Z23: =[5]Model!AC43 -> 30.688392 | AA23: =[5]Model!AD43 -> 25.644859 | AB23: =[5]Model!AE43 -> 28.115484 | AC23: =[5]Model!AF43 -> 24.411857 | AD23: =[5]Model!AG43 -> 34.073731 | AE23: =[5]Model!AH43 -> 36.202552 | AF23: =[5]Model!AI43 -> 28.985661 | ... BX23: =[5]Model!CA43 -> 9527.711
B24: Interest income | C24: INT_INC_IND | D24: =E_CURRENCY_ISSR_208021942_REP -> CNY | F24: =[5]Model!E24 -> 0 | G24: =[5]Model!F24 -> 0 | H24: =[5]Model!G24 -> 0 | I24: =[5]Model!H24 -> 0 | J24: =[5]Model!I24 -> 0 | K24: =[5]Model!J24 -> 0 | L24: =[5]Model!K24 -> 0 | M24: =[5]Model!L24 -> 1.6758867 | ... W24: =[5]Model!V24 -> 32 | Y24: =[5]Model!AB24 -> 0 | Z24: =[5]Model!AC24 -> 0 | AA24: =[5]Model!AD24 -> 0 | AB24: =[5]Model!AE24 -> 0 | AC24: =[5]Model!AF24 -> 0 | AD24: =[5]Model!AG24 -> 0 | AE24: =[5]Model!AH24 -> 0 | AF24: =[5]Model!AI24 -> 0 | ... BX24: =[5]Model!CA24 -> 8
B25: Interest expense | C25: INT_EXP_IND | D25: =E_CURRENCY_ISSR_208021942_REP -> CNY | F25: =[5]Model!E25 -> 0 | G25: =[5]Model!F25 -> 0 | H25: =[5]Model!G25 -> 0 | I25: =[5]Model!H25 -> 0 | J25: =[5]Model!I25 -> 0 | K25: =[5]Model!J25 -> 0 | L25: =[5]Model!K25 -> 0 | M25: =[5]Model!L25 -> -0.16884679 | ... W25: =[5]Model!V25 -> 0 | Y25: =[5]Model!AB25 -> 0 | Z25: =[5]Model!AC25 -> 0 | AA25: =[5]Model!AD25 -> 0 | AB25: =[5]Model!AE25 -> 0 | AC25: =[5]Model!AF25 -> 0 | AD25: =[5]Model!AG25 -> 0 | AE25: =[5]Model!AH25 -> 0 | AF25: =[5]Model!AI25 -> 0 | ... BX25: =[5]Model!CA25 -> 0
B26: Net interest income/(expense) | C26: NET_INT_EXP | D26: =E_CURRENCY_ISSR_208021942_REP -> CNY | F26: =[5]Model!E23 -> 0 | G26: =[5]Model!F23 -> 0 | H26: =[5]Model!G23 -> 0 | I26: =[5]Model!H23 -> 0 | J26: =[5]Model!I23 -> 0 | K26: =[5]Model!J23 -> 0 | L26: =[5]Model!K23 -> 0 | M26: =[5]Model!L23 -> 1.5070399 | ... W26: =[5]Model!V23 -> 32 | Y26: =[5]Model!AB23 -> 0 | Z26: =[5]Model!AC23 -> 0 | AA26: =[5]Model!AD23 -> 0 | AB26: =[5]Model!AE23 -> 0 | AC26: =[5]Model!AF23 -> 0 | AD26: =[5]Model!AG23 -> 0 | AE26: =[5]Model!AH23 -> 0 | AF26: =[5]Model!AI23 -> 0 | ... BX26: =[5]Model!CA23 -> 8
B27: Income/(loss) from unconsolidated subs & associates | C27: ASSOCIATE | D27: =E_CURRENCY_ISSR_208021942_REP -> CNY | F27: =[5]Model!E29+[5]Model!E30 -> 0 | G27: =[5]Model!F29+[5]Model!F30 -> 0 | H27: =[5]Model!G29+[5]Model!G30 -> 0 | I27: =[5]Model!H29+[5]Model!H30 -> 0 | J27: =[5]Model!I29+[5]Model!I30 -> 0 | K27: =[5]Model!J29+[5]Model!J30 -> 0 | L27: =[5]Model!K29+[5]Model!K30 -> 0 | M27: =[5]Model!L29+[5]Model!L30 -> -3.1526989 | ... W27: =[5]Model!V29+[5]Model!V30 -> 0 | Y27: =[5]Model!AB29+[5]Model!AB30 -> 0 | Z27: =[5]Model!AC29+[5]Model!AC30 -> 0 | AA27: =[5]Model!AD29+[5]Model!AD30 -> 0 | AB27: =[5]Model!AE29+[5]Model!AE30 -> 0 | AC27: =[5]Model!AF29+[5]Model!AF30 -> 0 | AD27: =[5]Model!AG29+[5]Model!AG30 -> 0 | AE27: =[5]Model!AH29+[5]Model!AH30 -> 0 | AF27: =[5]Model!AI29+[5]Model!AI30 -> 0 | ... BX27: =[5]Model!CA29+[5]Model!CA30 -> 0
B28: Profit/(loss) on disposals of assets, pre-tax | C28: PROFIT_ON_DISP | D28: =E_CURRENCY_ISSR_208021942_REP -> CNY | F28: =[5]Model!E27 -> 0 | G28: =[5]Model!F27 -> 0 | H28: =[5]Model!G27 -> 0 | I28: =[5]Model!H27 -> 0 | J28: =[5]Model!I27 -> 0 | K28: =[5]Model!J27 -> 0 | L28: =[5]Model!K27 -> 0.0014594 | M28: =[5]Model!L27 -> -0.00519486 | ... W28: =[5]Model!V27 -> 0 | Y28: =[5]Model!AB27 -> 0 | Z28: =[5]Model!AC27 -> 0 | AA28: =[5]Model!AD27 -> 0 | AB28: =[5]Model!AE27 -> 0 | AC28: =[5]Model!AF27 -> 0 | AD28: =[5]Model!AG27 -> 0 | AE28: =[5]Model!AH27 -> 0 | AF28: =[5]Model!AI27 -> 0 | ... BX28: =[5]Model!CA27 -> 0
B29: Other non-ops income/(expense) | C29: OTH_COST_INC | D29: =E_CURRENCY_ISSR_208021942_REP -> CNY | F29: =[5]Model!E31+[5]Model!E26+[5]Model!E28 -> -4.2849725 | G29: =[5]Model!F31+[5]Model!F26+[5]Model!F28 -> -1.5198879 | H29: =[5]Model!G31+[5]Model!G26+[5]Model!G28 -> -1.379428 | I29: =[5]Model!H31+[5]Model!H26+[5]Model!H28 -> -2.6637495 | J29: =[5]Model!I31+[5]Model!I26+[5]Model!I28 -> -3.1236165 | K29: =[5]Model!J31+[5]Model!J26+[5]Model!J28 -> 4.3547783 | L29: =[5]Model!K31+[5]Model!K26+[5]Model!K28 -> -1.0775177 | M29: =[5]Model!L31+[5]Model!L26+[5]Model!L28 -> -5.9242649 | ... T29: =[5]Model!S31+[5]Model!S26+[5]Model!S28 -> 70.50304 | U29: =[5]Model!T31+[5]Model!T26 -> 153.11671 | V29: =[5]Model!U31+[5]Model!U26 -> 0 | W29: =[5]Model!V31+[5]Model!V26 -> 0 | Y29: =[5]Model!AB31+[5]Model!AB26 -> -0.0005322 | Z29: =[5]Model!AC31+[5]Model!AC26 -> 0.77051535 | AA29: =[5]Model!AD31+[5]Model!AD26 -> -1.0370546 | AB29: =[5]Model!AE31+[5]Model!AE26 -> -1.6070271 | AC29: =[5]Model!AF31+[5]Model!AF26 -> 0.71100772 | AD29: =[5]Model!AG31+[5]Model!AG26 -> -1.9259063 | AE29: =[5]Model!AH31+[5]Model!AH26 -> 3.7583548 | AF29: =[5]Model!AI31+[5]Model!AI26 -> -0.43464277 | ... BX29: =[5]Model!CA31+[5]Model!CA26 -> 0
B30: Pre-tax profit | C30: PT_PROF | D30: =E_CURRENCY_ISSR_208021942_REP -> CNY | F30: =[5]Model!E33 -> 62.627898 | G30: =[5]Model!F33 -> 77.576932 | H30: =[5]Model!G33 -> 93.359207 | I30: =[5]Model!H33 -> 108.19541 | J30: =[5]Model!I33 -> 110.47321 | K30: =[5]Model!J33 -> 128.02858 | L30: =[5]Model!K33 -> 127.53739 | M30: =[5]Model!L33 -> 35.510374 | ... W30: =[5]Model!V33 -> 39514.918 | Y30: =[5]Model!AB33 -> 29.114392 | Z30: =[5]Model!AC33 -> 31.227481 | AA30: =[5]Model!AD33 -> 23.399505 | AB30: =[5]Model!AE33 -> 26.731837 | AC30: =[5]Model!AF33 -> 25.347175 | AD30: =[5]Model!AG33 -> 32.56913 | AE30: =[5]Model!AH33 -> 40.459621 | AF30: =[5]Model!AI33 -> 29.652653 | ... BX30: =[5]Model!CA33 -> 9535.711
A31: Additional Income Statement Items
B32: Contribution margin ratio | C32: CONTRIB_MARGIN_RATIO | D32: =E_CURRENCY_ISSR_208021942_REP -> CNY
B33: Operating lease cost | C33: LEASE_PAY | D33: =E_CURRENCY_ISSR_208021942_REP -> CNY
B34: Lease payments (deemed interest portion) | C34: LEASE_DEEM_INT | D34: =E_CURRENCY_ISSR_208021942_REP -> CNY
B35: Lease payments (deemed depreciation portion) | C35: LEASE_DEEM_DEPR | D35: =E_CURRENCY_ISSR_208021942_REP -> CNY
B36: Gross interest charge | C36: NET_INT_CH | D36: =E_CURRENCY_ISSR_208021942_REP -> CNY
B37: Income from associates (operating) | C37: ASSOCIATE_OP | D37: =E_CURRENCY_ISSR_208021942_REP -> CNY
B38: Depreciation ROU assets (applicable to IFRS cos.) | C38: DEPR_ROU_ASSETS | D38: =E_CURRENCY_ISSR_208021942_REP -> CNY
B39: Lease interest charge (applicable to IFRS cos.) | C39: LEASE_INT_CHG | D39: =E_CURRENCY_ISSR_208021942_REP -> CNY
B40: Lease standard adopted (US GAAP ASC 842/ IFRS 16) | C40: LEASE_ADOPT | E40: Y
...

Sheet Model
A2: Eoptolink (300502.SZ)
A3: In Rmb millions | X3: 2014 | Y3: 2014 | Z3: 2014 | AA3: 2014 | AB3: =X3+1 -> 2015 | AC3: =Y3+1 -> 2015 | AD3: =Z3+1 -> 2015 | AE3: =AA3+1 -> 2015 | AF3: =AB3+1 -> 2016 | AG3: =AC3+1 -> 2016 | AH3: =AD3+1 -> 2016 | AI3: =AE3+1 -> 2016 | ... CE3: =CA3+1 -> 2028
E4: 2011 | F4: 2012 | G4: 2013 | H4: 2014 | I4: 2015 | J4: 2016 | K4: 2017 | L4: =K4+1 -> 2018 | M4: =L4+1 -> 2019 | N4: =M4+1 -> 2020 | O4: =N4+1 -> 2021 | P4: =O4+1 -> 2022 | Q4: =P4+1 -> 2023 | R4: =Q4+1 -> 2024 | S4: =R4+1 -> 2025 | ... V4: =U4+1 -> 2028 | X4: 1Q14 | Y4: 2Q14 | Z4: 3Q14 | AA4: 4Q14 | AB4: 1Q15 | AC4: 2Q15 | AD4: 3Q15 | AE4: 4Q15 | AF4: 1Q16 | AG4: 2Q16 | AH4: 3Q16 | AI4: 4Q16 | AJ4: 1Q17 | AK4: 2Q17 | AL4: 3Q17 | AM4: 4Q17 | AN4: 1Q18 | AO4: 2Q18 | AP4: 3Q18 | AQ4: 4Q18 | AR4: 1Q19 | AS4: 2Q19 | AT4: 3Q19 | AU4: 4Q19 | AV4: 1Q20 | AW4: 2Q20 | AX4: 3Q20 | AY4: 4Q20 | AZ4: 1Q21 | BA4: 2Q21 | BB4: 3Q21 | BC4: 4Q21 | BD4: 1Q22 | BE4: 2Q22 | BF4: 3Q22 | BG4: 4Q22 | BH4: 1Q23 | BI4: 2Q23 | BJ4: 3Q23 | BK4: 4Q23 | BL4: 1Q24 | BM4: 2Q24 | BN4: 3Q24 | BO4: 4Q24 | BP4: 1Q25 | BQ4: 2Q25 | BR4: 3Q25 | BS4: 4Q25 | BT4: 1Q26 | BU4: 2Q26 | BV4: 3Q26 | BW4: 4Q26 | BX4: 1Q27 | BY4: 2Q27 | BZ4: 3Q27 | CA4: 4Q27 | CB4: 1Q28 | CC4: 2Q28 | CD4: 3Q28 | CE4: 4Q28
B5: Income statements | E5: =E4 -> 2011 | F5: =F4 -> 2012 | G5: =G4 -> 2013 | H5: =H4 -> 2014 | I5: =I4 -> 2015 | J5: =J4 -> 2016 | K5: =K4 -> 2017 | L5: =L4 -> 2018 | ... V5: =V4 -> 2028 | X5: =X4 -> 1Q14 | Y5: =Y4 -> 2Q14 | Z5: =Z4 -> 3Q14 | AA5: =AA4 -> 4Q14 | AB5: =AB4 -> 1Q15 | AC5: =AC4 -> 2Q15 | AD5: =AD4 -> 3Q15 | AE5: =AE4 -> 4Q15 | ... CE5: =CE4 -> 4Q28
BS6: =AVERAGE(BT6:BU6) -> 5225.8037 | BT6: =7000-BT40 -> 4225.8037 | BU6: =9000-BT40 -> 6225.8037 | BV6: =BT6/BQ40-1 -> 0.78321375 | BW6: =BU6/BQ40-1 -> 1.6271781
B7: Total sales/revenues | E7: 304.92843 | F7: 347.56807 | G7: 461.049 | H7: 522.63427 | I7: 615.11958 | J7: 713.93165 | K7: 877.36536 | L7: 759.95028 | M7: 1164.8737 | N7: 1997.9377 | O7: 2908.3761 | P7: =SUMIF($X$3:$BS$3,P$4,$X7:$BS7) -> 3310.5738 | Q7: =SUMIF($X$3:$BS$3,Q$4,$X7:$BS7) -> 3097.6058 | R7: =SUMIF($X$3:$BS$3,R$4,$X7:$BS7) -> 8646.8311 | S7: =SUMIF($X$3:$BS$3,S$4,$X7:$BS7) -> 24841.855 | T7: =SUMIF($X$3:$CA$3,T$4,$X7:$CA7) -> 51456.539 | U7: =SUMIF($X$3:$CA$3,U$4,$X7:$CA7) -> 73910.591 | V7: =SUMIF($X$3:$CE$3,V$4,$X7:$CE7) -> 84975.376 | X7: 0 | Y7: 0 | Z7: 0 | AA7: 0 | AB7: 141.26116 | AC7: 166.47504 | AD7: 142.20005 | AE7: 165.18332 | AF7: 146.321 | AG7: 192.79163 | AH7: 170.51717 | AI7: 204.30185 | AJ7: 191.53571 | AK7: 239.17685 | AL7: 231.21159 | AM7: 215.44121 | AN7: 177.50893 | AO7: 158.56943 | AP7: 197.98657 | AQ7: 225.88536 | AR7: 223.88642 | AS7: 256.45334 | AT7: 290.90559 | AU7: 393.62833 | AV7: 270.03089 | AW7: 566.52075 | AX7: 600.90347 | AY7: 560.48265 | AZ7: 624.32716 | BA7: 816.87541 | BB7: 578.08835 | BC7: 889.08514 | BD7: 738.5133 | BE7: 740.33465 | BF7: 935.65916 | BG7: 896.06668 | BH7: 600.22289 | BI7: 704.46093 | BJ7: 782.36373 | BK7: 1010.5582 | BL7: 1112.8539 | BM7: 1614.8209 | BN7: 2402.761 | BO7: 3516.3953 | BP7: 4052.2565 | BQ7: 6384.9137 | BR7: =16504.7912113-SUM(BP7:BQ7) -> 6067.6209 | BS7: =24841.85484022-SUM(BP7:BR7) -> 8337.0636 | BT7: 8337.902 | BU7: =Assumption!S5 -> 11283.248 | BV7: =Assumption!T5 -> 15163.921 | BW7: =Assumption!U5 -> 16671.468 | BX7: =Assumption!V5 -> 15172.087 | BY7: =Assumption!W5 -> 16800.28 | BZ7: =Assumption!X5 -> 21661.32 | CA7: =Assumption!Y5 -> 20276.903 | CB7: =Assumption!Z5 -> 14673.648 | ... CE7: =Assumption!AC5 -> 24684.879
B8: COGS | E8: 213.53676 | F8: 234.62009 | G8: 330.78362 | H8: 363.06989 | I8: 446.55322 | J8: 525.653 | K8: 666.78476 | L8: 611.69329 | M8: 760.4448 | N8: 1261.4845 | O8: 1972.7089 | P8: =SUMIF($X$3:$BS$3,P$4,$X8:$BS8) -> 2096.8585 | Q8: =SUMIF($X$3:$BS$3,Q$4,$X8:$BS8) -> 2137.6564 | R8: =SUMIF($X$3:$BS$3,R$4,$X8:$BS8) -> 4780.1919 | S8: =SUMIF($X$3:$BS$3,S$4,$X8:$BS8) -> 12966.05 | T8: =SUMIF($X$3:$CA$3,T$4,$X8:$CA8) -> 26649.771 | U8: =SUMIF($X$3:$CA$3,U$4,$X8:$CA8) -> 38031.235 | V8: =SUMIF($X$3:$CE$3,V$4,$X8:$CE8) -> 43619.538 | X8: 0 | Y8: 0 | Z8: 0 | AA8: 0 | AB8: 101.0667 | AC8: 121.38813 | AD8: 103.18521 | AE8: 120.91319 | AF8: 110.12175 | AG8: 143.06903 | AH8: 117.13324 | AI8: 155.32899 | AJ8: 142.59412 | AK8: 178.4853 | AL8: 171.31631 | AM8: 174.38903 | AN8: 150.9458 | AO8: 136.60422 | AP8: 155.17415 | AQ8: 168.96912 | AR8: 157.5587 | AS8: 173.87351 | AT8: 187.61455 | AU8: 241.39804 | AV8: 174.83516 | AW8: 348.03935 | AX8: 367.81341 | AY8: 370.79657 | AZ8: 433.70046 | BA8: 534.25111 | BB8: 405.85493 | BC8: 598.9024 | BD8: 493.94298 | BE8: 485.96081 | BF8: 583.91813 | BG8: 533.03662 | BH8: 395.88123 | BI8: 525.06195 | BJ8: 577.71866 | BK8: 638.99454 | BL8: 645.40063 | BM8: 908.16532 | BN8: 1404.8835 | BO8: 1821.7425 | BP8: 2080.4393 | BQ8: 3406.7652 | BR8: =8706.77662539-SUM(BP8:BQ8) -> 3219.5722 | BS8: =12966.04997921-SUM(BP8:BR8) -> 4259.2734 | BT8: =4238.90975812 -> 4238.9098 | BU8: =(BU7-BU12) -> 5899.644 | BV8: =(BV7-BV12) -> 7864.1978 | BW8: =(BW7-BW12) -> 8647.0191 | BX8: =(BX7-BX12) -> 8221.0385 | BY8: =(BY7-BY12) -> 8701.5586 | BZ8: =(BZ7-BZ12) -> 10874.892 | CA8: =(CA7-CA12) -> 10233.746 | CB8: =(CB7-CB12) -> 8375.8874 | ... CE8: =(CE7-CE12) -> 12326.371
B9: Others | BB9: 0 | BC9: 0 | BD9: 0 | BE9: 0 | BF9: 0 | BG9: 0 | BH9: 0 | BI9: 0 | BJ9: 0 | BK9: 0 | BL9: 0 | BR9: 0 | BS9: 0 | BT9: 0 | BU9: 0 | BV9: 0 | BW9: 0 | BX9: 0 | BY9: 0 | BZ9: 0 | CA9: 0 | CB9: 0 | CC9: 0 | CD9: 0 | CE9: 0
B10: Total COGS | E10: =E8+E9 -> 213.53676 | F10: =F8+F9 -> 234.62009 | G10: =G8+G9 -> 330.78362 | H10: =H8+H9 -> 363.06989 | I10: =I8+I9 -> 446.55322 | J10: =J8+J9 -> 525.653 | K10: =K8+K9 -> 666.78476 | L10: =L8+L9 -> 611.69329 | ... V10: =V8+V9 -> 43619.538 | X10: =X8+X9 -> 0 | Y10: =Y8+Y9 -> 0 | Z10: =Z8+Z9 -> 0 | AA10: =AA8+AA9 -> 0 | AB10: =AB8+AB9 -> 101.0667 | AC10: =AC8+AC9 -> 121.38813 | AD10: =AD8+AD9 -> 103.18521 | AE10: =AE8+AE9 -> 120.91319 | ... BO10: =BO8+BO9 -> 1821.7425 | BP10: =BP8+BP52 -> 2080.4393 | BQ10: =BQ8+BQ52 -> 3406.7652 | BR10: =BR8+BR9 -> 3219.5722 | BS10: =BS8+BS9 -> 4259.2734 | BT10: =BT8+BT9 -> 4238.9098 | BU10: =BU8+BU9 -> 5899.644 | BV10: =BV8+BV9 -> 7864.1978 | BW10: =BW8+BW9 -> 8647.0191 | BX10: =BX8+BX9 -> 8221.0385 | BY10: =BY8+BY9 -> 8701.5586 | ... CE10: =CE8+CE9 -> 12326.371
B12: Gross profit | E12: =+E7-E10 -> 91.39167 | F12: =+F7-F10 -> 112.94797 | G12: =+G7-G10 -> 130.26538 | H12: =+H7-H10 -> 159.56438 | I12: =+I7-I10 -> 168.56636 | J12: =+J7-J10 -> 188.27865 | K12: =+K7-K10 -> 210.5806 | L12: =+L7-L10 -> 148.25699 | ... V12: =+V7-V10 -> 41355.837 | X12: =+X7-X8 -> 0 | Y12: =+Y7-Y8 -> 0 | Z12: =+Z7-Z8 -> 0 | AA12: =+AA7-AA8 -> 0 | AB12: =+AB7-AB8 -> 40.19446 | AC12: =+AC7-AC8 -> 45.086918 | AD12: =+AD7-AD8 -> 39.014841 | AE12: =+AE7-AE8 -> 44.270139 | ... BT12: =+BT7-BT8 -> 4098.9923 | BU12: =+Assumption!S354 -> 5383.6042 | BV12: =+Assumption!T354 -> 7299.7231 | BW12: =+Assumption!U354 -> 8024.4494 | BX12: =+Assumption!V354 -> 6951.0483 | BY12: =+Assumption!W354 -> 8098.7216 | BZ12: =+Assumption!X354 -> 10786.429 | CA12: =+Assumption!Y354 -> 10043.157 | CB12: =+Assumption!Z354 -> 6297.7609 | ... CE12: =+Assumption!AC354 -> 12358.508
B13: Gross margin % | E13: =E12/E$7 -> 0.29971515 | F13: =F12/F$7 -> 0.32496649 | G13: =G12/G$7 -> 0.28254129 | H13: =H12/H$7 -> 0.30530792 | I13: =I12/I$7 -> 0.27403836 | J13: =J12/J$7 -> 0.26372083 | K13: =K12/K$7 -> 0.24001472 | L13: =L12/L$7 -> 0.19508775 | ... V13: =V12/V$7 -> 0.48668025 | AB13: =AB12/AB$7 -> 0.28454008 | AC13: =AC12/AC$7 -> 0.27083289 | AD13: =AD12/AD$7 -> 0.27436588 | AE13: =AE12/AE$7 -> 0.2680061 | AF13: =AF12/AF$7 -> 0.24739618 | AG13: =AG12/AG$7 -> 0.25790852 | AH13: =AH12/AH$7 -> 0.3130707 | AI13: =AI12/AI$7 -> 0.23970835 | ... CE13: =CE12/CE$7 -> 0.50065094
B15: Operating expense | E15: =E16+E17+E18+E19 -> 24.478799 | F15: =F16+F17+F18+F19 -> 33.851155 | G15: =G16+G17+G18+G19 -> 35.526742 | H15: =H16+H17+H18+H19 -> 48.705217 | I15: =I16+I17+I18+I19 -> 54.969527 | J15: =J16+J17+J18+J19 -> 64.604849 | K15: =K16+K17+K18+K19 -> 81.967153 | L15: =L16+L17+L18+L19 -> 105.1715 | ... S15: =S16+S17+S18+S19 -> 1167.3515 | T15: =SUMIF($X$3:$CA$3,T$4,$X15:$CA15) -> 1278.2996 | U15: =SUMIF($X$3:$CA$3,U$4,$X15:$CA15) -> 1534.6485 | V15: =SUMIF($X$3:$CE$3,V$4,$X15:$CE15) -> 1872.9189 | X15: =X16+X17+X18+X19 -> 0 | Y15: =Y16+Y17+Y18+Y19 -> 0 | Z15: =Z16+Z17+Z18+Z19 -> 0 | AA15: =AA16+AA17+AA18+AA19 -> 0 | AB15: =AB16+AB17+AB18+AB19 -> 11.046365 | AC15: =AC16+AC17+AC18+AC19 -> 14.398526 | AD15: =AD16+AD17+AD18+AD19 -> 13.369982 | AE15: =AE16+AE17+AE18+AE19 -> 16.154654 | ... CE15: =CE16+CE17+CE18+CE19 -> 776.25314
B16: Sales tax | E16: 1.0309883 | F16: 3.1413119 | G16: 1.5832431 | H16: 2.7907413 | I16: 3.6306729 | J16: 3.0253489 | K16: 2.3547487 | L16: 7.4679543 | M16: 6.1521281 | N16: 7.6608041 | O16: 7.9212035 | P16: =SUMIF($X$3:$BS$3,P$4,$X16:$BS16) -> 7.3868155 | Q16: =SUMIF($X$3:$BS$3,Q$4,$X16:$BS16) -> 16.80748 | R16: =SUMIF($X$3:$BS$3,R$4,$X16:$BS16) -> 71.857215 | S16: =SUMIF($X$3:$BS$3,S$4,$X16:$BS16) -> 74.911176 | T16: =SUMIF($X$3:$CA$3,T$4,$X16:$CA16) -> 81.486163 | U16: =SUMIF($X$3:$CA$3,U$4,$X16:$CA16) -> 61.369259 | V16: =SUMIF($X$3:$CE$3,V$4,$X16:$CE16) -> 307.13928 | X16: 0 | Y16: 0 | Z16: 0 | AA16: 0 | AB16: 1.5314792 | AC16: 1.1248105 | AD16: 0.11648197 | AE16: 0.85790132 | AF16: 0.70039975 | AG16: 0 | AH16: 0.91776698 | AI16: 1.4071822 | AJ16: 0.77571446 | AK16: 0.56946445 | AL16: 0.16460057 | AM16: 0.84496926 | AN16: 1.6107755 | AO16: 2.2172791 | AP16: 1.2419138 | AQ16: 2.3979858 | AR16: 1.0782531 | AS16: 1.8466857 | AT16: 1.4132913 | AU16: 1.813898 | AV16: 0.92888749 | AW16: 2.0577146 | AX16: 2.14177 | AY16: 2.5324319 | AZ16: 1.9915005 | BA16: 2.3494767 | BB16: 1.5592145 | BC16: 2.0210119 | BD16: 0.92598769 | BE16: 2.3907829 | BF16: 1.2308839 | BG16: 2.839161 | BH16: 2.5980494 | BI16: 5.4607112 | BJ16: 6.0369273 | BK16: 2.7117924 | BL16: 2.3094055 | BM16: 4.5301155 | BN16: 3.0626743 | BO16: 61.95502 | BP16: 3.3646597 | BQ16: 9.2938471 | BR16: =16.67433136-SUM(BP16:BQ16) -> 4.0158245 | BS16: =74.91117562-SUM(BP16:BR16) -> 58.236844 | BT16: =45.68400251 -> 45.684003 | BU16: =BU$7*BU78 -> 9.3686788 | BV16: =BV$7*BV78 -> 12.590869 | BW16: =BW$7*BW78 -> 13.842613 | BX16: =BX$7*BX78 -> 12.59765 | BY16: =BY$7*BY78 -> 13.949567 | BZ16: =BZ$7*BZ78 -> 17.985774 | CA16: =CA$7*CA78 -> 16.836268 | CB16: =CB$7*CB78 -> 14.673648 | ... CE16: =CE$7*CE78 -> 246.84879
B17: Marketing expense | E17: 4.5849908 | F17: 5.3915111 | G17: 6.9554956 | H17: 8.8869006 | I17: 9.3767561 | J17: 10.459758 | K17: 13.323467 | L17: 18.534026 | M17: 25.773565 | N17: 33.337902 | O17: 35.69091 | P17: =SUMIF($X$3:$BS$3,P$4,$X17:$BS17) -> 52.507976 | Q17: =SUMIF($X$3:$BS$3,Q$4,$X17:$BS17) -> 37.571976 | R17: =SUMIF($X$3:$BS$3,R$4,$X17:$BS17) -> 97.51957 | S17: =SUMIF($X$3:$BS$3,S$4,$X17:$BS17) -> 150.85483 | T17: =SUMIF($X$3:$CA$3,T$4,$X17:$CA17) -> 177.36132 | U17: =SUMIF($X$3:$CA$3,U$4,$X17:$CA17) -> 205.12464 | V17: =SUMIF($X$3:$CE$3,V$4,$X17:$CE17) -> 232.34682 | X17: 0 | Y17: 0 | Z17: 0 | AA17: 0 | AB17: 1.5783795 | AC17: 2.3241503 | AD17: 2.2919335 | AE17: 3.1822928 | AF17: 1.6415447 | AG17: 2.9033209 | AH17: 2.9379438 | AI17: 2.9769489 | AJ17: 2.7911682 | AK17: 2.6116458 | AL17: 2.7289171 | AM17: 5.1917361 | AN17: 3.4130193 | AO17: 4.3386544 | AP17: 3.8057829 | AQ17: 6.9765691 | AR17: 4.4209237 | AS17: 5.8629806 | AT17: 6.4967112 | AU17: 8.9929497 | AV17: 4.8875584 | AW17: 6.8180389 | AX17: 9.8500048 | AY17: 11.7823 | AZ17: 6.5554816 | BA17: 11.511421 | BB17: 9.1558312 | BC17: 8.4681769 | BD17: 6.4221203 | BE17: 14.141306 | BF17: 14.577638 | BG17: 17.366911 | BH17: 7.5350968 | BI17: 9.4922095 | BJ17: 8.411287 | BK17: 12.133382 | BL17: 20.426691 | BM17: 19.066037 | BN17: 23.14776 | BO17: 34.879081 | BP17: 37.831489 | BQ17: 47.133141 | BR17: =123.32511108-SUM(BP17:BQ17) -> 38.360481 | BS17: =150.85483325-SUM(BP17:BR17) -> 27.529722 | BT17: =35.61554813 -> 35.615548 | BU17: =+Assumption!S382 -> 41.796829 | BV17: =+Assumption!T382 -> 45.431336 | BW17: =+Assumption!U382 -> 54.517603 | BX17: =+Assumption!V382 -> 38.973682 | BY17: =+Assumption!W382 -> 41.024929 | BZ17: =+Assumption!X382 -> 51.281161 | CA17: =+Assumption!Y382 -> 73.844872 | CB17: =+Assumption!Z382 -> 44.145896 | ... CE17: =+Assumption!AC382 -> 83.644856
B18: Administrative expense | E18: 8.0882101 | F18: 11.025813 | G18: 10.786341 | H18: 18.838611 | I18: 18.541846 | J18: 21.863592 | K18: 21.367831 | L18: 26.504851 | M18: 33.66914 | N18: 31.563373 | O18: 33.888913 | P18: =SUMIF($X$3:$BS$3,P$4,$X18:$BS18) -> 84.517118 | Q18: =SUMIF($X$3:$BS$3,Q$4,$X18:$BS18) -> 76.212946 | R18: =SUMIF($X$3:$BS$3,R$4,$X18:$BS18) -> 169.0172 | S18: =SUMIF($X$3:$BS$3,S$4,$X18:$BS18) -> 239.44167 | T18: =SUMIF($X$3:$CA$3,T$4,$X18:$CA18) -> 289.14307 | U18: =SUMIF($X$3:$CA$3,U$4,$X18:$CA18) -> 318.15458 | V18: =SUMIF($X$3:$CE$3,V$4,$X18:$CE18) -> 349.03276 | X18: 0 | Y18: 0 | Z18: 0 | AA18: 0 | AB18: 2.5544568 | AC18: 4.606866 | AD18: 5.5437444 | AE18: 5.8209754 | AF18: 3.4462947 | AG18: 4.8410948 | AH18: 6.3344629 | AI18: 7.2266912 | AJ18: 2.6947803 | AK18: 3.4804127 | AL18: 2.700852 | AM18: =K18-SUM(AJ18:AL18) -> 12.491786 | AN18: 6.7830925 | AO18: 8.9636208 | AP18: 8.0879261 | AQ18: 2.6702117 | AR18: 6.2110254 | AS18: 7.9146465 | AT18: 7.6946224 | AU18: 11.848846 | AV18: 6.1076825 | AW18: 10.909877 | AX18: 7.9960088 | AY18: 6.5498047 | AZ18: 6.7433262 | BA18: 7.4346159 | BB18: 7.540505 | BC18: 12.170466 | BD18: 6.6248605 | BE18: 33.071019 | BF18: 19.983569 | BG18: 24.83767 | BH18: 17.439729 | BI18: 18.00179 | BJ18: 21.867661 | BK18: 18.903765 | BL18: 28.608848 | BM18: 39.091534 | BN18: 34.512275 | BO18: 66.804544 | BP18: 59.79066 | BQ18: 65.115232 | BR18: =187.87912994-SUM(BP18:BQ18) -> 62.973238 | BS18: =239.44167025-SUM(BP18:BR18) -> 51.56254 | BT18: =62.31596336 -> 62.315963 | BU18: =+Assumption!S383 -> 66.884915 | BV18: =+Assumption!T383 -> 72.700995 | BW18: =+Assumption!U383 -> 87.241194 | BX18: =+Assumption!V383 -> 69.994007 | BY18: =+Assumption!W383 -> 76.357098 | BZ18: =+Assumption!X383 -> 79.538644 | CA18: =+Assumption!Y383 -> 92.264827 | CB18: =+Assumption!Z383 -> 76.787208 | ... CE18: =+Assumption!AC383 -> 101.2195
B19: R&D | E19: 10.77461 | F19: 14.292519 | G19: 16.201662 | H19: 18.188965 | I19: 23.420253 | J19: 29.256149 | K19: =SUM(AJ19:AM19) -> 44.921107 | L19: 52.66467 | M19: 81.343198 | N19: 85.08282 | O19: 108.42423 | P19: =SUMIF($X$3:$BS$3,P$4,$X19:$BS19) -> 187.24136 | Q19: =SUMIF($X$3:$BS$3,Q$4,$X19:$BS19) -> 133.7745 | R19: =SUMIF($X$3:$BS$3,R$4,$X19:$BS19) -> 403.16862 | S19: =SUMIF($X$3:$BS$3,S$4,$X19:$BS19) -> 702.14385 | T19: =SUMIF($X$3:$CA$3,T$4,$X19:$CA19) -> 730.30909 | U19: =SUMIF($X$3:$CA$3,U$4,$X19:$CA19) -> 950 | V19: =SUMIF($X$3:$CE$3,V$4,$X19:$CE19) -> 984.4 | X19: 0 | Y19: 0 | Z19: 0 | AA19: 0 | AB19: 5.38205 | AC19: 6.3426992 | AD19: 5.4178219 | AE19: 6.2934847 | AF19: 5.9991611 | AG19: 7.9044569 | AH19: 6.991204 | AI19: 8.3763757 | AJ19: 9.8066283 | AK19: 12.245855 | AL19: 11.838033 | AM19: 11.03059 | AN19: 12.301369 | AO19: 16.310709 | AP19: 13.307034 | AQ19: 10.745558 | AR19: 11.85216 | AS19: 19.61628 | AT19: 23.723885 | AU19: 26.150873 | AV19: 15.025456 | AW19: 24.094791 | AX19: 25.910296 | AY19: 20.052277 | AZ19: 17.726631 | BA19: 15.523039 | BB19: 21.661675 | BC19: 53.512887 | BD19: 36.82674 | BE19: 28.363201 | BF19: 46.24608 | BG19: 75.805341 | BH19: 31.577936 | BI19: 29.23529 | BJ19: 39.469997 | BK19: 33.491279 | BL19: 53.18913 | BM19: 76.380596 | BN19: 71.286388 | BO19: 202.31251 | BP19: 117.88532 | BQ19: 215.8303 | BR19: =501.27453672-SUM(BP19:BQ19) -> 167.55892 | BS19: =702.14384824-SUM(BP19:BR19) -> 200.86931 | BT19: =119.90908567 -> 119.90909 | BU19: =+Assumption!S384 -> 160.23 | BV19: =+Assumption!T384 -> 167.86 | BW19: =+Assumption!U384 -> 282.31 | BX19: =+Assumption!V384 -> 190 | BY19: =+Assumption!W384 -> 209 | BZ19: =+Assumption!X384 -> 218.5 | CA19: =+Assumption!Y384 -> 332.5 | CB19: =+Assumption!Z384 -> 196.88 | ... CE19: =+Assumption!AC384 -> 344.54
B20: Operating income | E20: =+E12-E15 -> 66.91287 | F20: =+F12-F15 -> 79.09682 | G20: =+G12-G15 -> 94.738635 | H20: =+H12-H15 -> 110.85916 | I20: =+I12-I15 -> 113.59683 | J20: =+J12-J15 -> 123.6738 | K20: =+K12-K15 -> 128.61345 | L20: =+L12-L15 -> 43.085493 | ... V20: =+V12-V15 -> 39482.918 | X20: =X12-X15 -> 0 | Y20: =Y12-Y15 -> 0 | Z20: =Z12-Z15 -> 0 | AA20: =AA12-AA15 -> 0 | AB20: =AB12-AB15 -> 29.148095 | AC20: =AC12-AC15 -> 30.688392 | AD20: =AD12-AD15 -> 25.644859 | AE20: =AE12-AE15 -> 28.115484 | ... CE20: =CE12-CE15 -> 11582.255
B22: Other income (loss)
B23: Finance cost | E23: =E24+E25 -> 0 | F23: =F24+F25 -> 0 | G23: =G24+G25 -> 0 | H23: =H24+H25 -> 0 | I23: =I24+I25 -> 0 | J23: =J24+J25 -> 0 | K23: =K24+K25 -> 0 | L23: =L24+L25 -> 1.5070399 | ... V23: =V24+V25 -> 32 | X23: =X24+X25 -> 0 | Y23: =Y24+Y25 -> 0 | Z23: =Z24+Z25 -> 0 | AA23: =AA24+AA25 -> 0 | AB23: =AB24+AB25 -> 0 | AC23: =AC24+AC25 -> 0 | AD23: =AD24+AD25 -> 0 | AE23: =AE24+AE25 -> 0 | ... CE23: =CE24+CE25 -> 8
B24: Interest income | E24: 0 | F24: 0 | G24: 0 | H24: 0 | I24: 0 | J24: 0 | K24: 0 | L24: 1.6758867 | M24: 3.8919589 | N24: 2.6946375 | O24: 24.816541 | P24: =SUMIF($X$3:$CA$3,P$4,$X24:$CA24) -> 21.513061 | Q24: =SUMIF($X$3:$CA$3,Q$4,$X24:$CA24) -> 74.556974 | R24: =SUMIF($X$3:$CA$3,R$4,$X24:$CA24) -> 72.840411 | S24: =SUMIF($X$3:$CA$3,S$4,$X24:$CA24) -> 77.949111 | T24: =SUMIF($X$3:$CA$3,T$4,$X24:$CA24) -> 32 | U24: =SUMIF($X$3:$CA$3,U$4,$X24:$CA24) -> 32 | V24: =SUMIF($X$3:$CE$3,V$4,$X24:$CE24) -> 32 | X24: 0 | Y24: 0 | Z24: 0 | AA24: 0 | AB24: 0 | AC24: 0 | AD24: 0 | AE24: 0 | AF24: 0 | AG24: 0 | AH24: 0 | AI24: 0 | AJ24: 0 | AK24: 0 | AL24: 0 | AM24: 0 | AN24: 0.21279226 | AO24: 0.21279226 | AP24: 1.0100423 | AQ24: 0 | AR24: 1.0207775 | AS24: 0.89600147 | AT24: 0.7709664 | AU24: 1.2042135 | AV24: 0.80168869 | AW24: 0.51127851 | AX24: 0.41057836 | AY24: 0.97109194 | AZ24: 5.188926 | BA24: 6.7689806 | BB24: 6.3738236 | BC24: 6.484811 | BD24: 4.2031735 | BE24: 5.097521 | BF24: 5.46163 | BG24: 6.7507367 | BH24: 11.37104 | BI24: 13.281795 | BJ24: 26.392859 | BK24: 23.51128 | BL24: 22.630113 | BM24: 23.78794 | BN24: 16.924509 | BO24: 9.4978485 | BP24: 7.7676161 | BQ24: 8.8523463 | BR24: =37.57344289-SUM(BP24:BQ24) -> 20.95348 | BS24: =77.94911125-SUM(BP24:BR24) -> 40.375668 | BT24: 8 | BU24: 8 | BV24: 8 | BW24: 8 | BX24: 8 | BY24: 8 | BZ24: 8 | CA24: 8 | CB24: 8 | CC24: 8 | CD24: 8 | CE24: 8
B25: Interest expense | E25: 0 | F25: 0 | G25: 0 | H25: 0 | I25: 0 | J25: 0 | K25: 0 | L25: -0.16884679 | M25: 0 | N25: =SUM(AV25:AY25) -> -1.1574752 | O25: =SUM(AZ25:BC25) -> -0.28331815 | P25: =SUMIF($X$3:$CA$3,P$4,$X25:$CA25) -> 0 | Q25: =SUMIF($X$3:$CA$3,Q$4,$X25:$CA25) -> -1.5481576 | R25: =SUMIF($X$3:$CA$3,R$4,$X25:$CA25) -> -1.3764114 | S25: =SUMIF($X$3:$CA$3,S$4,$X25:$CA25) -> -1.186448 | T25: =SUMIF($X$3:$CA$3,T$4,$X25:$CA25) -> 0 | U25: =SUMIF($X$3:$CA$3,U$4,$X25:$CA25) -> 0 | V25: =SUMIF($X$3:$CE$3,V$4,$X25:$CE25) -> 0 | X25: 0 | Y25: 0 | Z25: 0 | AA25: 0 | AB25: 0 | AC25: 0 | AD25: 0 | AE25: 0 | AF25: 0 | AG25: 0 | AH25: 0 | AI25: 0 | AJ25: 0 | AK25: 0 | AL25: 0 | AM25: 0 | AN25: -0.07954927 | AO25: -0.07954927 | AP25: -0.00730599 | AQ25: -0.00244226 | AR25: 0 | AS25: 0 | AT25: 0 | AU25: 0 | AV25: 0 | AW25: -0.06289191 | AX25: -1.0945833 | AY25: 0 | AZ25: -0.28331815 | BA25: 0 | BB25: 0 | BC25: 0 | BD25: 0 | BE25: 0 | BF25: 0 | BG25: 0 | BH25: 0 | BI25: 0 | BJ25: 0 | BK25: -1.5481576 | BL25: 0 | BM25: 0 | BN25: -1.0469028 | BO25: -0.32950863 | BP25: -0.30235204 | BQ25: -0.32073607 | BR25: =-0.91317087-SUM(BP25:BQ25) -> -0.29008276 | BS25: =-1.18644797-SUM(BP25:BR25) -> -0.2732771 | BT25: 0 | BU25: 0 | BV25: 0 | BW25: 0 | BX25: 0 | BY25: 0 | BZ25: 0 | CA25: 0 | CB25: 0 | CC25: 0 | CD25: 0 | CE25: 0
B26: Impairement loss | E26: -4.6515779 | F26: -3.4960642 | G26: -4.8385604 | H26: -6.5136737 | I26: -7.1912244 | J26: -8.8061087 | K26: -14.462745 | L26: -25.976368 | M26: 22.731227 | N26: -44.011707 | O26: -55.467909 | P26: =SUMIF($X$3:$CA$3,P$4,$X26:$CA26) -> -127.90719 | Q26: =SUMIF($X$3:$CA$3,Q$4,$X26:$CA26) -> -17.09093 | R26: =SUMIF($X$3:$CA$3,R$4,$X26:$CA26) -> -79.479127 | S26: =SUMIF($X$3:$CA$3,S$4,$X26:$CA26) -> -203.27471 | T26: =SUMIF($X$3:$CA$3,T$4,$X26:$CA26) -> 0 | U26: =SUMIF($X$3:$CA$3,U$4,$X26:$CA26) -> 0 | V26: =SUMIF($X$3:$CE$3,V$4,$X26:$CE26) -> 0 | X26: 0 | Y26: 0 | Z26: 0 | AA26: 0 | AB26: -0.52031621 | AC26: -1.6788491 | AD26: -1.5138356 | AE26: -3.4782235 | AF26: -0.37438521 | AG26: -5.0878055 | AH26: 0.43037909 | AI26: -3.7742971 | AJ26: -0.33384969 | AK26: -6.8074322 | AL26: -1.6927326 | AM26: -5.6287301 | AN26: -7.8002539 | AO26: -10.639208 | AP26: -0.35709419 | AQ26: -7.179812 | AR26: -2.6942899 | AS26: 3.2718168 | AT26: 9.7305844 | AU26: 13.881802 | AV26: -12.137102 | AW26: -9.1521584 | AX26: -10.249426 | AY26: -12.473021 | AZ26: -25.623578 | BA26: -19.555796 | BB26: -1.8666259 | BC26: -8.4219096 | BD26: -30.042973 | BE26: -15.982685 | BF26: -29.548448 | BG26: -52.33308 | BH26: -5.3841943 | BI26: -27.736162 | BJ26: 16.814579 | BK26: -0.78515197 | BL26: -11.863557 | BM26: -5.4648797 | BN26: -3.3488203 | BO26: -58.801869 | BP26: -16.816659 | BQ26: -145.84896 | BR26: =-203.2747145-SUM(BP26:BQ26) -> -40.609092 | BS26: 0 | BT26: 0 | BU26: 0 | BV26: 0 | BW26: 0 | BX26: 0 | BY26: 0 | BZ26: 0 | CA26: 0 | CB26: 0 | CC26: 0 | CD26: 0 | CE26: 0
B27: Profit/(loss) on disposal of assets (pre-tax) | E27: 0 | F27: 0 | G27: 0 | H27: 0 | I27: 0 | J27: 0 | K27: =SUMIF($X$3:$BC$3,K$4,$X27:$BC27) -> 0.0014594 | L27: =SUMIF($X$3:$BC$3,L$4,$X27:$BC27) -> -0.00519486 | M27: =SUMIF($X$3:$BC$3,M$4,$X27:$BC27) -> -0.23568619 | N27: =SUMIF($X$3:$BC$3,N$4,$X27:$BC27) -> 0 | O27: =SUMIF($X$3:$BC$3,O$4,$X27:$BC27) -> 0 | P27: =SUMIF($X$3:$CA$3,P$4,$X27:$CA27) -> 0 | Q27: =SUMIF($X$3:$CA$3,Q$4,$X27:$CA27) -> 0 | R27: =SUMIF($X$3:$CA$3,R$4,$X27:$CA27) -> 0 | S27: =SUMIF($X$3:$CA$3,S$4,$X27:$CA27) -> 0 | T27: =SUMIF($X$3:$CA$3,T$4,$X27:$CA27) -> 0 | U27: =SUMIF($X$3:$CA$3,U$4,$X27:$CA27) -> 0 | V27: =SUMIF($X$3:$CE$3,V$4,$X27:$CE27) -> 0 | X27: 0 | Y27: 0 | Z27: 0 | AA27: 0 | AB27: 0 | AC27: 0 | AD27: 0 | AE27: 0 | AF27: 0 | AG27: 0 | AH27: 0 | AI27: =J27-SUM(AF27:AH27) -> 0 | AJ27: 0 | AK27: 0 | AL27: 0 | AM27: 0.0014594 | AN27: 0 | AO27: -0.00028033 | AP27: -0.00491453 | AQ27: 0 | AR27: -0.015131 | AS27: 0 | AT27: -4.206e-05 | AU27: -0.22051313 | AV27: 0 | AW27: 0 | AX27: 0 | AY27: 0 | AZ27: 0 | BA27: 0 | BB27: 0 | BC27: 0 | BD27: 0 | BE27: 0 | BF27: 0 | BG27: 0 | BH27: 0 | BI27: 0 | BJ27: 0 | BK27: 0 | BL27: 0 | BM27: 0 | BN27: 0 | BO27: 0 | BP27: 0 | BQ27: 0 | BR27: 0
B28: Foreign exchange gain/(loss) | E28: -1.2759848 | F28: 0.87583712 | G28: 0.63505934 | H28: -0.39697851 | I28: -1.2495179 | J28: 2.2459649 | K28: -1.0793135 | L28: 8.8697317 | M28: 1.6406342 | N28: -10.819674 | O28: -16.981929 | P28: =SUMIF($X$3:$CA$3,P$4,$X28:$CA28) -> 103.00442 | Q28: =SUMIF($X$3:$CA$3,Q$4,$X28:$CA28) -> 35.235133 | R28: =SUMIF($X$3:$CA$3,R$4,$X28:$CA28) -> 107.85263 | S28: =SUMIF($X$3:$CA$3,S$4,$X28:$CA28) -> -292.07134 | T28: =SUMIF($X$3:$CA$3,T$4,$X28:$CA28) -> 0 | U28: =SUMIF($X$3:$CA$3,U$4,$X28:$CA28) -> 0 | V28: =SUMIF($X$3:$CE$3,V$4,$X28:$CE28) -> 0 | X28: 0 | Y28: 0 | Z28: 0 | AA28: 0 | AB28: -0.03317053 | AC28: -0.23142713 | AD28: -1.2083 | AE28: 0.22337968 | AF28: 0.22431057 | AG28: 0.42130472 | AH28: 0.49871425 | AI28: 1.1016353 | AJ28: -0.0815715 | AK28: -0.17061527 | AL28: -0.75027908 | AM28: -0.07684766 | AN28: -1.5106389 | AO28: 5.4321046 | AP28: 5.9292237 | AQ28: -0.74069781 | AR28: -3.6336342 | AS28: 3.4605056 | AT28: 5.769466 | AU28: -3.9557033 | AV28: 2.2717544 | AW28: -0.79329007 | AX28: -1.6649782 | AY28: -10.63316 | AZ28: 3.1867865 | BA28: -6.8254145 | BB28: 1.6321898 | BC28: -14.975491 | BD28: -3.3635052 | BE28: 62.102671 | BF28: 85.303093 | BG28: -41.037838 | BH28: -25.583344 | BI28: 95.360524 | BJ28: -15.398042 | BK28: -19.144005 | BL28: -1.832293 | BM28: 22.833825 | BN28: 8.0869905 | BO28: 78.764112 | BP28: 25.621481 | BQ28: 166.3353 | BR28: =-255.41106663-SUM(BP23:BR23,BP28:BQ28) -> -484.02812 | BS28: 0 | BT28: 0 | BU28: 0 | BV28: 0 | BW28: 0 | BX28: 0 | BY28: 0 | BZ28: 0 | CA28: 0 | CB28: 0 | CC28: 0 | CD28: 0 | CE28: 0
B29: Income (loss) from associates | E29: 0 | F29: 0 | G29: 0 | H29: =SUMIF($X$3:$BC$3,H$4,$X29:$BC29) -> 0 | I29: =SUMIF($X$3:$BC$3,I$4,$X29:$BC29) -> 0 | J29: =SUMIF($X$3:$BC$3,J$4,$X29:$BC29) -> 0 | K29: =SUMIF($X$3:$BC$3,K$4,$X29:$BC29) -> 0 | L29: =SUMIF($X$3:$BC$3,L$4,$X29:$BC29) -> -3.1526989 | M29: =SUMIF($X$3:$BC$3,M$4,$X29:$BC29) -> -1.3165856 | N29: =SUMIF($X$3:$BC$3,N$4,$X29:$BC29) -> 0.28141801 | O29: =SUMIF($X$3:$BC$3,O$4,$X29:$BC29) -> -3.7562863 | P29: =SUMIF($X$3:$CA$3,P$4,$X29:$CA29) -> -1.97635 | Q29: =SUMIF($X$3:$CA$3,Q$4,$X29:$CA29) -> 0 | R29: =SUMIF($X$3:$CA$3,R$4,$X29:$CA29) -> 0 | S29: =SUMIF($X$3:$CA$3,S$4,$X29:$CA29) -> 0 | T29: =SUMIF($X$3:$CA$3,T$4,$X29:$CA29) -> 0 | U29: =SUMIF($X$3:$CA$3,U$4,$X29:$CA29) -> 0 | V29: =SUMIF($X$3:$CE$3,V$4,$X29:$CE29) -> 0 | X29: 0 | Y29: 0 | Z29: 0 | AA29: 0 | AB29: 0 | AC29: 0 | AD29: 0 | AE29: 0 | AF29: 0 | AG29: 0 | AH29: 0 | AI29: 0 | AJ29: 0 | AK29: 0 | AL29: 0 | AM29: 0 | AN29: 0 | AO29: 0 | AP29: 0 | AQ29: -3.1526989 | AR29: -1.2742773 | AS29: -0.66912725 | AT29: -1.1364825 | AU29: 1.7633014 | AV29: 0.79623006 | AW29: 0.95373568 | AX29: -1.5917059 | AY29: 0.12315822 | AZ29: -0.11154186 | BA29: -2.1641403 | BB29: -0.74584312 | BC29: -0.73476107 | BD29: -2.3436388 | BE29: -1.0160269 | BF29: 0 | BG29: 1.3833157 | BH29: 0 | BI29: 0 | BJ29: 0 | BK29: 0 | BL29: 0 | BM29: 0 | BN29: 0 | BO29: 0 | BP29: 0 | BQ29: 0 | BR29: 0 | BS29: 0 | BT29: 0 | BU29: 0 | BV29: 0 | BW29: 0 | BX29: 0 | BY29: 0 | BZ29: 0 | CA29: 0 | CB29: 0 | CC29: 0 | CD29: 0 | CE29: 0
B30: Share of results in jointly controlled entities | E30: 0 | F30: 0 | G30: 0 | H30: 0 | I30: 0 | J30: 0 | K30: 0 | L30: 0 | M30: 0 | N30: 0 | O30: 0 | P30: =SUMIF($X$3:$CA$3,P$4,$X30:$CA30) -> 0 | Q30: =SUMIF($X$3:$CA$3,Q$4,$X30:$CA30) -> 2 | R30: =SUMIF($X$3:$CA$3,R$4,$X30:$CA30) -> 10 | S30: =SUMIF($X$3:$CA$3,S$4,$X30:$CA30) -> 10 | T30: =SUMIF($X$3:$CA$3,T$4,$X30:$CA30) -> 0 | U30: =SUMIF($X$3:$CA$3,U$4,$X30:$CA30) -> 0 | V30: =SUMIF($X$3:$CE$3,V$4,$X30:$CE30) -> 0 | X30: 0 | Y30: 0 | Z30: 0 | AA30: 0 | AB30: 0 | AC30: 0 | AD30: 0 | AE30: 0 | AF30: 0 | AG30: 0 | AH30: 0 | AI30: 0 | AJ30: 0 | AK30: 0 | AL30: 0 | AM30: 0 | AN30: 0 | AO30: 0 | AP30: 0 | AQ30: 0 | AR30: 0 | AS30: 0 | AT30: 0 | AU30: 0 | AV30: 0 | AW30: 0 | AX30: 0 | AY30: 0 | AZ30: 0 | BA30: 0 | BB30: 0 | BC30: 0 | BD30: 0 | BE30: 0 | BF30: 0 | BG30: 0 | BH30: 0 | BI30: 0 | BJ30: 1 | BK30: 1 | BL30: 1 | BM30: 2 | BN30: 3 | BO30: 4 | BP30: 5 | BQ30: 5 | BR30: 0 | BS30: 0 | BT30: 0 | BU30: 0 | BV30: 0 | BW30: 0 | BX30: 0 | BY30: 0 | BZ30: 0 | CA30: 0 | CB30: 0 | CC30: 0 | CD30: 0 | CE30: 0
B31: Other non-operating income/expense | E31: =+E32-E23-E26-E27-E29-E30-E28 -> 1.6425902 | F31: =+F32-F23-F26-F27-F29-F30-F28 -> 1.1003392 | G31: =+G32-G23-G26-G27-G29-G30-G28 -> 2.824073 | H31: =+H32-H23-H26-H27-H29-H30-H28 -> 4.2469028 | I31: =+I32-I23-I26-I27-I29-I30-I28 -> 5.3171258 | J31: =+J32-J23-J26-J27-J29-J30-J28 -> 10.914922 | K31: =+K32-K23-K26-K27-K29-K30-K28 -> 14.46454 | L31: =+L32-L23-L26-L27-L29-L30-L28 -> 11.182371 | ... O31: =+O32-O23-O26-O27-O29-O30-O28 -> 65.004174 | P31: =SUMIF($X$3:$CA$3,P$4,$X31:$CA31) -> 151.16892 | Q31: =SUMIF($X$3:$CA$3,Q$4,$X31:$CA31) -> -0.00736915 | R31: =SUMIF($X$3:$CA$3,R$4,$X31:$CA31) -> -0.70405333 | S31: =SUMIF($X$3:$CA$3,S$4,$X31:$CA31) -> 565.84909 | T31: =SUMIF($X$3:$CA$3,T$4,$X31:$CA31) -> 153.11671 | U31: =SUMIF($X$3:$CA$3,U$4,$X31:$CA31) -> 0 | V31: =SUMIF($X$3:$CE$3,V$4,$X31:$CE31) -> 0 | X31: =+X32-X23-X26-X27-X29-X30-X28 -> 0 | Y31: =+Y32-Y23-Y26-Y27-Y29-Y30-Y28 -> 0 | Z31: =+Z32-Z23-Z26-Z27-Z29-Z30-Z28 -> 0 | AA31: =+AA32-AA23-AA26-AA27-AA29-AA30-AA28 -> 0 | AB31: =+AB32-AB23-AB26-AB27-AB29-AB30-AB28 -> 0.51978401 | AC31: =+AC32-AC23-AC26-AC27-AC29-AC30-AC28 -> 2.4493645 | AD31: =+AD32-AD23-AD26-AD27-AD29-AD30-AD28 -> 0.47678098 | AE31: =+AE32-AE23-AE26-AE27-AE29-AE30-AE28 -> 1.8711963 | ... BT31: =+BT32-BT23-BT26-BT27-BT29-BT30-BT28 -> -596.88329 | BU31: 200 | BV31: 250 | BW31: 300 | BX31: 0 | BY31: 0 | BZ31: 0 | CA31: 0 | CB31: 0 | CC31: 0 | CD31: 0 | CE31: 0
B32: Other income (loss) | E32: =+E33-E20 -> -4.2849725 | F32: =+F33-F20 -> -1.5198879 | G32: =+G33-G20 -> -1.379428 | H32: =+H33-H20 -> -2.6637495 | I32: =+I33-I20 -> -3.1236165 | J32: =+J33-J20 -> 4.3547783 | K32: =+K33-K20 -> -1.0760583 | L32: =+L33-L20 -> -7.5751188 | ... O32: =+O33-O20 -> 13.331272 | P32: =SUM(P24:P31) -> 145.80287 | Q32: =SUM(Q24:Q31) -> 93.14565 | R32: =SUM(R24:R31) -> 109.13345 | S32: =SUM(S24:S31) -> 157.2657 | T32: =SUM(T24:T31) -> 185.11671 | U32: =SUM(U24:U31) -> 32 | V32: =SUM(V24:V31) -> 32 | X32: =+X33-X20 -> 0 | Y32: =+Y33-Y20 -> 0 | Z32: =+Z33-Z20 -> 0 | AA32: =+AA33-AA20 -> 0 | AB32: =+AB33-AB20 -> -0.03370273 | AC32: =+AC33-AC20 -> 0.53908822 | AD32: =+AD33-AD20 -> -2.2453546 | AE32: =+AE33-AE20 -> -1.3836475 | ... BT32: =+BT33-BT20 -> -588.88329 | BU32: =SUM(BU24:BU31) -> 208 | BV32: =SUM(BV24:BV31) -> 258 | BW32: =SUM(BW24:BW31) -> 308 | BX32: =SUM(BX24:BX31) -> 8 | BY32: =SUM(BY24:BY31) -> 8 | BZ32: =SUM(BZ24:BZ31) -> 8 | CA32: =SUM(CA24:CA31) -> 8 | CB32: =SUM(CB24:CB31) -> 8 | ... CE32: =SUM(CE24:CE31) -> 8
B33: Pre-tax profit | E33: 62.627898 | F33: 77.576932 | G33: 93.359207 | H33: 108.19541 | I33: =SUM(AB33:AE33) -> 110.47321 | J33: 128.02858 | K33: =SUM(AJ33:AM33) -> 127.53739 | L33: 35.510374 | M33: 243.95119 | N33: 561.5991 | O33: 763.07318 | P33: =P20+P32 -> 1027.8648 | Q33: =Q20+Q32 -> 788.72812 | R33: =R20+R32 -> 3234.21 | S33: =S20+S32 -> 10865.719 | T33: =T20+T32 -> 23713.586 | U33: =U20+U32 -> 34376.707 | V33: =V20+V32 -> 39514.918 | X33: 0 | Y33: 0 | Z33: 0 | AA33: 0 | AB33: 29.114392 | AC33: 31.227481 | AD33: 23.399505 | AE33: 26.731837 | AF33: 25.347175 | AG33: 32.56913 | AH33: 40.459621 | AI33: 29.652653 | AJ33: 35.276249 | AK33: 38.867553 | AL33: 40.757933 | AM33: 12.635653 | AN33: -4.2153316 | AO33: -13.294118 | AP33: 24.253633 | AQ33: 28.766191 | AR33: 38.241664 | AS33: 56.844217 | AT33: 61.945019 | AU33: 86.920293 | AV33: 66.227378 | AW33: 158.56193 | AX33: 177.4593 | AY33: 159.3505 | AZ33: 136.99556 | BA33: 243.10482 | BB33: 157.34392 | BC33: 225.62886 | BD33: 156.25975 | BE33: 367.73023 | BF33: 338.76758 | BG33: 165.10727 | BH33: 127.79097 | BI33: 200.39036 | BJ33: 157.87317 | BK33: 302.67362 | BL33: 372.37105 | BM33: 608.80106 | BN33: 888.62074 | BO33: 1364.4172 | BP33: 1773.2538 | BQ33: 2675.1314 | BR33: =7050.53350656-SUM(BP33:BQ33) -> 2602.1483 | BS33: =10865.71903686-SUM(BP33:BR33) -> 3815.1855 | BT33: =3246.58439536 -> 3246.5844 | BU33: =BU20+BU32 -> 5313.3237 | BV33: =BV20+BV32 -> 7259.1399 | BW33: =BW20+BW32 -> 7894.538 | BX33: =BX20+BX32 -> 6647.483 | BY33: =BY20+BY32 -> 7766.39 | BZ33: =BZ20+BZ32 -> 10427.123 | CA33: =CA20+CA32 -> 9535.711 | CB33: =CB20+CB32 -> 5973.2741 | ... CE33: =CE20+CE32 -> 11590.255
B36: Income taxes | E36: 10.053113 | F36: 11.829224 | G36: 14.000439 | H36: 15.79688 | I36: 16.022886 | J36: 22.741796 | K36: 16.446483 | L36: 3.6780402 | M36: 31.094637 | N36: 69.840693 | O36: 101.14704 | P36: =SUMIF($X$3:$BS$3,P$4,$X36:$BS36) -> 124.28375 | Q36: =SUMIF($X$3:$BS$3,Q$4,$X36:$BS36) -> 100.36703 | R36: =SUMIF($X$3:$BS$3,R$4,$X36:$BS36) -> 396.39641 | S36: =SUMIF($X$3:$BS$3,S$4,$X36:$BS36) -> 1312.4428 | T36: =SUMIF($X$3:$CA$3,T$4,$X36:$CA36) -> 2964.1982 | U36: =SUMIF($X$3:$CA$3,U$4,$X36:$CA36) -> 4297.0884 | V36: =SUMIF($X$3:$CE$3,V$4,$X36:$CE36) -> 4939.3648 | X36: 0 | Y36: 0 | Z36: 0 | AA36: 0 | AB36: 4.3355021 | AC36: 4.5909181 | AD36: 3.4291732 | AE36: 3.6672928 | AF36: 3.8682969 | AG36: 5.5777014 | AH36: 8.4337011 | AI36: 4.8620965 | AJ36: 5.3998228 | AK36: 6.0853736 | AL36: 6.7949636 | AM36: -1.833677 | AN36: -0.57791537 | AO36: -1.7769813 | AP36: 3.6836035 | AQ36: 2.3493333 | AR36: 5.8303189 | AS36: 8.592563 | AT36: 9.6268265 | AU36: 7.0449281 | AV36: 10.01117 | AW36: 23.561218 | AX36: 26.828291 | AY36: 9.4400132 | AZ36: 24.58961 | BA36: 32.505567 | BB36: 15.481628 | BC36: 28.570231 | BD36: 23.836916 | BE36: 39.066172 | BF36: 37.420229 | BG36: 23.960435 | BH36: 19.956156 | BI36: 19.86029 | BJ36: 16.674549 | BK36: 43.87603 | BL36: 47.830512 | BM36: 68.1995 | BN36: 107.68996 | BO36: 172.67644 | BP36: 200.72805 | BQ36: 305.3629 | BR36: =723.44099872-SUM(BP36:BQ36) -> 217.35006 | BS36: =1312.44281971-SUM(BP36:BR36) -> 589.00182 | BT36: =+BT87*BT33 -> 405.82305 | BU36: =+BU87*BU33 -> 664.16547 | BV36: =+BV87*BV33 -> 907.39248 | BW36: =+BW87*BW33 -> 986.81725 | BX36: =+BX87*BX33 -> 830.93537 | BY36: =+BY87*BY33 -> 970.79875 | BZ36: =+BZ87*BZ33 -> 1303.3904 | CA36: =+CA87*CA33 -> 1191.9639 | ... CE36: =+CE87*CE33 -> 1448.7818
B37: Minority interest | E37: =+E33-E36-E40 -> 0 | F37: =+F33-F36-F40 -> 0 | G37: =+G33-G36-G40 -> 0 | H37: =+H33-H36-H40 -> 0 | I37: =+I33-I36-I40 -> 0 | J37: =+J33-J36-J40 -> 0 | K37: =+K33-K36-K40 -> 0 | L37: =+L33-L36-L40 -> 0 | ... O37: =+O33-O36-O40 -> 0 | P37: =SUMIF($X$3:$BS$3,P$4,$X37:$BS37) -> -2.8421709e-14 | Q37: =SUMIF($X$3:$BS$3,Q$4,$X37:$BS37) -> 4.2632564e-14 | R37: =SUMIF($X$3:$BS$3,R$4,$X37:$BS37) -> -1.1368684e-13 | S37: =SUMIF($X$3:$BS$3,S$4,$X37:$BS37) -> 21.353487 | T37: =SUMIF($X$3:$CA$3,T$4,$X37:$CA37) -> 66.565083 | U37: =SUMIF($X$3:$CA$3,U$4,$X37:$CA37) -> 0 | V37: =SUMIF($X$3:$CE$3,V$4,$X37:$CE37) -> 0 | X37: =+X33-X36-X40 -> 0 | Y37: =+Y33-Y36-Y40 -> 0 | Z37: =+Z33-Z36-Z40 -> 0 | AA37: =+AA33-AA36-AA40 -> 0 | AB37: =+AB33-AB36-AB40 -> 0 | AC37: =+AC33-AC36-AC40 -> 0 | AD37: =+AD33-AD36-AD40 -> 0 | AE37: =+AE33-AE36-AE40 -> 0 | ... AO37: =+AO33-AO36-AO40 -> 0 | AP37: =+AP33-AP36-AP40-AP38-AP39 -> 0 | AQ37: =+AQ33-AQ36-AQ40-AQ38-AQ39 -> -3.5527137e-15 | AR37: =+AR33-AR36-AR40-AR38-AR39 -> 7.1054274e-15 | AS37: =+AS33-AS36-AS40-AS38-AS39 -> -7.1054274e-15 | AT37: =+AT33-AT36-AT40-AT38-AT39 -> 0 | AU37: =+AU33-AU36-AU40-AU38-AU39 -> 0 | AV37: =+AV33-AV36-AV40-AV38-AV39 -> -7.1054274e-15 | AW37: =+AW33-AW36-AW40-AW38-AW39 -> 0 | ... BT37: =+BT33-BT36-BT40-BT38-BT39 -> 66.565083 | BU37: =+Assumption!S197 -> 0 | BV37: =+Assumption!T197 -> 0 | BW37: =+Assumption!U197 -> 0 | BX37: =+Assumption!V197 -> 0 | BY37: =+Assumption!W197 -> 0 | BZ37: =+Assumption!X197 -> 0 | CA37: =+Assumption!Y197 -> 0 | CB37: =+Assumption!Z197 -> 0 | ... CE37: =+Assumption!AC197 -> 0
B38: Preferred dividends | E38: 0 | F38: 0 | G38: 0 | H38: 0 | I38: 0 | J38: 0 | K38: 0 | L38: 0 | M38: 0 | N38: 0 | O38: 0 | P38: =SUMIF($X$3:$BS$3,P$4,$X38:$BS38) -> 0 | Q38: =SUMIF($X$3:$BS$3,Q$4,$X38:$BS38) -> 0 | R38: =SUMIF($X$3:$BS$3,R$4,$X38:$BS38) -> 0 | S38: =SUMIF($X$3:$BS$3,S$4,$X38:$BS38) -> 0 | T38: =SUMIF($X$3:$CA$3,T$4,$X38:$CA38) -> 0 | U38: =SUMIF($X$3:$CA$3,U$4,$X38:$CA38) -> 0 | V38: =SUMIF($X$3:$CE$3,V$4,$X38:$CE38) -> 0 | AJ38: 0 | AK38: 0 | AL38: 0 | AM38: 0 | AN38: 0 | AO38: 0 | AP38: 0 | AQ38: 0 | AR38: 0 | AS38: 0 | AT38: 0 | AU38: 0 | AV38: 0 | AW38: 0 | AX38: 0 | AY38: 0 | AZ38: 0 | BA38: 0 | BB38: 0 | BC38: 0 | BD38: 0 | BE38: 0 | BF38: 0 | BG38: 0 | BH38: 0 | BI38: 0 | BJ38: 0 | BK38: 0 | BL38: 0 | BM38: 0 | BN38: 0 | BO38: 0 | BP38: 0 | BQ38: 0 | BR38: 0 | BS38: 0
B39: Extraordinary gain/(loss) | E39: 0 | F39: 0 | G39: 0 | H39: 0 | I39: 0 | J39: 0 | K39: 0 | L39: 0 | M39: 0 | N39: 0 | O39: 0 | P39: =SUMIF($X$3:$BS$3,P$4,$X39:$BS39) -> 0 | Q39: =SUMIF($X$3:$BS$3,Q$4,$X39:$BS39) -> 0 | R39: =SUMIF($X$3:$BS$3,R$4,$X39:$BS39) -> 0 | S39: =SUMIF($X$3:$BS$3,S$4,$X39:$BS39) -> 0 | T39: =SUMIF($X$3:$CA$3,T$4,$X39:$CA39) -> 0 | U39: =SUMIF($X$3:$CA$3,U$4,$X39:$CA39) -> 0 | V39: =SUMIF($X$3:$CE$3,V$4,$X39:$CE39) -> 0 | AJ39: 0 | AK39: 0 | AL39: 0 | AM39: 0 | AN39: 0 | AO39: 0 | AP39: 0 | AQ39: 0 | AR39: 0 | AS39: 0 | AT39: 0 | AU39: 0 | AV39: 0 | AW39: 0 | AX39: 0 | AY39: 0 | AZ39: 0 | BA39: 0 | BB39: 0 | BC39: 0 | BD39: 0 | BE39: 0 | BF39: 0 | BG39: 0 | BH39: 0 | BI39: 0 | BJ39: 0 | BK39: 0 | BL39: 0 | BM39: 0 | BN39: 0 | BO39: 0 | BP39: 0 | BQ39: 0 | BR39: 0 | BS39: 0
