Workbook
Name \0: #REF!
Name \0: #REF!
Name \a: #REF!
Name \a: #REF!
Name \b: #REF!
Name \b: #REF!
Name \c: #REF!
Name \c: #N/A
Name \d: #REF!
Name \d: #N/A
Name \e: #REF!
Name \e: #REF!
Name \f: #REF!
Name \f: #REF!
Name \g: #REF!
Name \g: #REF!
Name \h: #REF!
Name \h: #REF!
Name \i: #REF!
Name \i: #N/A
Name \j: #REF!
Name \j: #N/A
Name \k: #REF!
Name \k: #REF!
Name \l: #REF!
Name \l: #REF!
Name \m: #REF!
Name \m: #N/A
Name \P: #REF!
Name \P: #REF!
Name \q: #REF!
Name \q: #REF!
Name \s: #REF!
Name \s: #REF!
Name \u: #REF!
Name \u: #REF!
Name \v: #N/A
Name \x: #REF!
Name \x: #REF!
Name \z: #REF!
Name \z: #N/A
Name ___________DIV01: #REF!
Name ___________DIV01: #REF!
Name ___________DIV86: #REF!
Name ___________DIV86: #REF!
Name ___________DIV87: #REF!
Name ___________DIV87: #REF!
Name ___________DIV88: #REF!
Name ___________DIV88: #REF!
Name ___________DIV89: #REF!
Name ___________DIV89: #REF!
Name ___________DIV90: #REF!
Name ___________DIV90: #REF!
Name ___________DIV91: #REF!
Name ___________DIV91: #REF!
Name ___________DIV92: #REF!
Name ___________DIV92: #REF!
Name ___________DIV93: #REF!
Name ___________DIV93: #REF!
Name ___________DIV94: #REF!

Sheet Cover page
B9: Ronald Keung, CFA
B10: +852 2978 0856
B11: ronald.keung@gs.com
B12: Goldman Sachs (Asia) L.L.C
B14: Key statistics
B15: Rating | E15: Neutral
E16: Zhipu
E17: 2513.HK
B19: Currency | E19: HK$
B20: Target price (HK$) | E20: 1880 | BN20: =#REF!+#REF!-#REF! -> #REF!
B26: Colour coding
B27: Hard-coded | D27: Linked to the file | F27: Assumptions
B30: Source: Company data, Datastream, Goldman Sachs Research estimates.

Sheet Model
A3: December year-end (Rmb mn) | F3: 2022 | G3: 2023 | H3: 2024 | I3: 2025 | J3: =I3+1 -> 2026 | K3: =J3+1 -> 2027 | L3: =K3+1 -> 2028 | M3: =L3+1 -> 2029 | N3: =M3+1 -> 2030 | O3: =N3+1 -> 2031 | P3: =O3+1 -> 2032 | Q3: =P3+1 -> 2033 | ... S3: =R3+1 -> 2035 | U3: 1H24 | V3: 2H24 | W3: 1H25 | X3: 2H25 | Y3: 1H26E | Z3: 2H26E
B4: Revenue | F4: =Revenue!F5 -> 57.409 | G4: =Revenue!G5 -> 124.538 | H4: =Revenue!H5 -> 312.414 | I4: =Revenue!I5 -> 724.334 | J4: =Revenue!J5 -> 6339.2276 | K4: =Revenue!K5 -> 23724.729 | L4: =Revenue!L5 -> 58809.369 | M4: =Revenue!M5 -> 120603.6 | ... S4: =Revenue!S5 -> 1282827.2 | U4: =Revenue!U5 -> 44.909 | V4: =Revenue!V5 -> 267.505 | W4: =Revenue!W5 -> 190.877 | X4: =Revenue!X5 -> 533.457 | Y4: =Revenue!Y5 -> 1115.7648 | Z4: =Revenue!Z5 -> 5223.4628
C5: yoy % | H5: =H4/G4-1 -> 1.5085837 | I5: =I4/H4-1 -> 1.3185069 | J5: =J4/I4-1 -> 7.7518018 | K5: =K4/J4-1 -> 2.7425269 | L5: =L4/K4-1 -> 1.4788215 | M5: =M4/L4-1 -> 1.0507549 | N5: =N4/M4-1 -> 0.82080436 | O5: =O4/N4-1 -> 0.64620893 | ... S5: =S4/R4-1 -> 0.26126355 | W5: =W4/U4-1 -> 3.2503062 | X5: =X4/V4-1 -> 0.9941945 | Y5: =Y4/W4-1 -> 4.8454649 | Z5: =Z4/X4-1 -> 8.7917223
B7: Cost of sales | F7: =Revenue!F118 -> -26.049 | G7: =Revenue!G118 -> -44.056 | H7: =Revenue!H118 -> -136.525 | I7: =Revenue!I118 -> -427.678 | J7: =Revenue!J118 -> -4527.7268 | K7: =Revenue!K118 -> -17264.397 | L7: =Revenue!L118 -> -42438.455 | M7: =Revenue!M118 -> -85122.007 | ... S7: =Revenue!S118 -> -811651.86 | U7: =Revenue!U118 -> -22.95 | V7: =Revenue!V118 -> -113.575 | W7: =Revenue!W118 -> -95.453 | X7: =Revenue!X118 -> -332.225 | Y7: =Revenue!Y118 -> -735.38446 | Z7: =Revenue!Z118 -> -3792.3423
B9: Gross (loss)/profit | F9: =F4+F7 -> 31.36 | G9: =G4+G7 -> 80.482 | H9: =H4+H7 -> 175.889 | I9: =I4+I7 -> 296.656 | J9: =J4+J7 -> 1811.5008 | K9: =K4+K7 -> 6460.3325 | L9: =L4+L7 -> 16370.914 | M9: =M4+M7 -> 35481.597 | ... S9: =S4+S7 -> 471175.34 | U9: =U4+U7 -> 21.959 | V9: =V4+V7 -> 153.93 | W9: =W4+W7 -> 95.424 | X9: =X4+X7 -> 201.232 | Y9: =Y4+Y7 -> 380.38034 | Z9: =Z4+Z7 -> 1431.1205
C10: yoy % | G10: =G9/F9-1 -> 1.5663903 | H10: =H9/G9-1 -> 1.1854452 | I10: =I9/H9-1 -> 0.68660917 | J10: =J9/I9-1 -> 5.1064021 | K10: =K9/J9-1 -> 2.5662874 | L10: =L9/K9-1 -> 1.5340668 | M10: =M9/L9-1 -> 1.1673559 | N10: =N9/M9-1 -> 0.9293395 | ... S10: =S9/R9-1 -> 0.29461363 | W10: =W9/U9-1 -> 3.3455531 | X10: =X9/V9-1 -> 0.30729552 | Y10: =Y9/W9-1 -> 2.9862125 | Z10: =Z9/X9-1 -> 6.1117937
C11: margin % | G11: =G9/G4 -> 0.64624452 | H11: =H9/H4 -> 0.56299974 | I11: =I9/I4 -> 0.40955692 | J11: =J9/J4 -> 0.2857605 | K11: =K9/K4 -> 0.27230374 | L11: =L9/L4 -> 0.27837255 | M11: =M9/M4 -> 0.29420014 | N11: =N9/N4 -> 0.31173693 | ... S11: =S9/S4 -> 0.36729448 | U11: =U9/U4 -> 0.48896658 | V11: =V9/V4 -> 0.5754285 | W11: =W9/W4 -> 0.49992403 | X11: =X9/X4 -> 0.37722253 | Y11: =Y9/Y4 -> 0.34091445 | Z11: =Z9/Z4 -> 0.27397926
B13: Other income | F13: 1.784 | G13: 9.965 | H13: 19.281 | I13: 14.839 | J13: =J66 -> 33.14836 | K13: =K66 -> 432.84256 | L13: =L66 -> 199.21519 | M13: =M66 -> 414.59592 | N13: =N66 -> 560.09699 | O13: =O66 -> 913.91537 | P13: =P66 -> 1673.757 | Q13: =Q66 -> 2943.3992 | ... S13: =S66 -> 7823.4091 | U13: 4.174 | V13: =H13-U13 -> 15.107 | W13: 4.614 | X13: =I13-W13 -> 10.225 | Y13: =Y69 -> 16.736472 | Z13: =Z69 -> 16.411888
B14: Selling and distribution expenses | F14: -15.139 | G14: -101.198 | H14: -387.475 | I14: -390.869 | J14: =-J82 -> -508.1297 | K14: =-K82 -> -736.78807 | L14: =-L82 -> -1105.1821 | M14: =-M82 -> -1602.514 | N14: =-N82 -> -2251.5322 | O14: =-O82 -> -3072.2157 | P14: =-P82 -> -4080.0561 | Q14: =-Q82 -> -5284.6723 | ... S14: =-S82 -> -8288.5624 | U14: -144.194 | V14: =H14-U14 -> -243.281 | W14: -208.57 | X14: =I14-W14 -> -182.299 | Y14: =-Y82 -> -245.46826 | Z14: =-Z82 -> -262.66144
B15: Administrative expenses | F15: -32.316 | G15: -66.302 | H15: -133.603 | I15: -505.357 | J15: =-J92 -> -656.9641 | K15: =-K92 -> -952.59794 | L15: =-L92 -> -1428.8969 | M15: =-M92 -> -2071.9005 | N15: =-N92 -> -2911.0202 | O15: =-O92 -> -3972.0871 | P15: =-P92 -> -5275.1303 | Q15: =-Q92 -> -6832.5862 | ... S15: =-S92 -> -10716.335 | U15: -51.452 | V15: =H15-U15 -> -82.151 | W15: -185.165 | X15: =I15-W15 -> -320.192 | Y15: =-Y92 -> -334.72944 | Z15: =-Z92 -> -322.23466
B16: Research and development expenses | F16: -84.377 | G16: -528.884 | H16: -2195.436 | I16: -3180.443 | J16: =-J102 -> -5724.7974 | K16: =-K102 -> -10877.115 | L16: =-L102 -> -16304.795 | M16: =-M102 -> -26087.673 | N16: =-N102 -> -40435.893 | O16: =-O102 -> -56003.711 | P16: =-P102 -> -71096.712 | Q16: =-Q102 -> -84509.106 | ... S16: =-S102 -> -104512.45 | U16: -859.217 | V16: =H16-U16 -> -1336.219 | W16: -1594.661 | X16: =I16-W16 -> -1585.782 | Y16: =-Y102 -> -2789.412 | Z16: =-Z102 -> -2935.3854
B17: Impairment losses on financial assets | F17: -0.031 | G17: -19.786 | H17: -17.008 | I17: -21.576 | J17: 0 | K17: 0 | L17: 0 | M17: 0 | N17: 0 | O17: 0 | P17: 0 | Q17: 0 | R17: 0 | S17: 0 | U17: -0.763 | V17: =H17-U17 -> -16.245 | W17: -10.867 | X17: =I17-W17 -> -10.709 | Y17: 0 | Z17: 0
B19: Operating profit | F19: =F9+SUM(F13:F17) -> -98.719 | G19: =G9+SUM(G13:G17) -> -625.723 | H19: =H9+SUM(H13:H17) -> -2538.352 | I19: =I9+SUM(I13:I17) -> -3786.75 | J19: =J9+SUM(J13:J17) -> -5045.242 | K19: =K9+SUM(K13:K17) -> -5673.326 | L19: =L9+SUM(L13:L17) -> -2268.745 | M19: =M9+SUM(M13:M17) -> 6134.1057 | ... S19: =S9+SUM(S13:S17) -> 355481.4 | U19: =U9+SUM(U13:U17) -> -1029.493 | V19: =V9+SUM(V13:V17) -> -1508.859 | W19: =W9+SUM(W13:W17) -> -1899.225 | X19: =X9+SUM(X13:X17) -> -1887.525 | Y19: =Y9+SUM(Y13:Y17) -> -2972.4929 | Z19: =Z9+SUM(Z13:Z17) -> -2072.7491
C20: margin % | G20: =G19/G$4 -> -5.024354 | H20: =H19/H$4 -> -8.1249624 | I20: =I19/I$4 -> -5.2279059 | J20: =J19/J$4 -> -0.79587646 | K20: =K19/K$4 -> -0.23913132 | L20: =L19/L$4 -> -0.038577951 | M20: =M19/M$4 -> 0.050861712 | N20: =N19/N$4 -> 0.10664012 | ... S20: =S19/S$4 -> 0.27710779 | U20: =U19/U$4 -> -22.92398 | V20: =V19/V$4 -> -5.640489 | W20: =W19/W$4 -> -9.949994 | X20: =X19/X$4 -> -3.5382889 | Y20: =Y19/Y$4 -> -2.6640855 | Z20: =Z19/Z$4 -> -0.39681515
C21: yoy % | G21: =-(G19/F19-1) -> -5.3384252 | H21: =-(H19/G19-1) -> -3.0566704 | I21: =I19/H19-1 -> 0.49181437 | J21: =J19/I19-1 -> 0.33234093 | K21: =K19/J19-1 -> 0.12449035 | L21: =L19/K19-1 -> -0.60010319 | M21: =M19/L19-1 -> -3.7037441 | N21: =N19/M19-1 -> 2.8176223 | O21: =O19/N19-1 -> 1.4443622 | P21: =P19/O19-1 -> 0.86030547 | ... S21: =S19/R19-1 -> 0.37835329 | W21: =-(W19/U19-1) -> -0.84481585 | X21: =-(X19/V19-1) -> -0.25096182 | Y21: =-(Y19/W19-1) -> -0.56510834 | Z21: =-(Z19/X19-1) -> -0.098130696
B23: Adj. operating profit - non-IFRS | F23: =F19+SUM(F46) -> -97.695 | G23: =G19+SUM(G46) -> -620.221 | H23: =H19+SUM(H46) -> -2514.773 | I23: =I19+SUM(I46) -> -3228.485 | J23: =J19+SUM(J46) -> -4375.324 | K23: =K19+SUM(K46) -> -4869.4244 | L23: =L19+SUM(L46) -> -1304.063 | M23: =M19+SUM(M46) -> 7195.2558 | ... S23: =S19+SUM(S46) -> 357361.3 | U23: =U19+SUM(U46) -> -1025.276 | V23: =V19+SUM(V46) -> -1489.497 | W23: =W19+SUM(W46) -> -1740.373 | X23: =X19+SUM(X46) -> -1488.112 | Y23: =Y19+SUM(Y46) -> -2637.5339 | Z23: =Z19+SUM(Z46) -> -1737.7901
C24: margin % | G24: =G23/G$4 -> -4.9801747 | H24: =H23/H$4 -> -8.0494888 | I24: =I23/I$4 -> -4.4571772 | J24: =J23/J$4 -> -0.69019829 | K24: =K23/K$4 -> -0.20524678 | L24: =L23/L$4 -> -0.022174409 | M24: =M23/M$4 -> 0.059660372 | N24: =N23/N$4 -> 0.11195565 | ... S24: =S23/S$4 -> 0.27857321 | U24: =U23/U$4 -> -22.830079 | V24: =V23/V$4 -> -5.568109 | W24: =W23/W$4 -> -9.1177722 | X24: =X23/X$4 -> -2.7895632 | Y24: =Y23/Y$4 -> -2.3638798 | Z24: =Z23/Z$4 -> -0.33268929
C25: yoy % | G25: =G23/F23-1 -> 5.3485439 | H25: =H23/G23-1 -> 3.0546402 | I25: =I23/H23-1 -> 0.28380772 | J25: =J23/I23-1 -> 0.35522514 | K25: =K23/J23-1 -> 0.11292886 | L25: =L23/K23-1 -> -0.73219359 | M25: =M23/L23-1 -> -6.5175675 | N25: =N23/M23-1 -> 2.4168297 | ... S25: =S23/R23-1 -> 0.37652092 | W25: =W23/U23-1 -> 0.6974678 | X25: =X23/V23-1 -> -0.0009298441 | Y25: =Y23/W23-1 -> 0.51549919 | Z25: =Z23/X23-1 -> 0.16778182
B27: Finance costs | F27: -5.694 | G27: -26.332 | H27: -38.321 | I27: -74.315 | J27: =-J111 -> -35.705665 | K27: =-K111 -> -35.705665 | L27: =-L111 -> -35.705665 | M27: =-M111 -> -35.705665 | N27: =-N111 -> -35.705665 | O27: =-O111 -> -35.705665 | P27: =-P111 -> -35.705665 | Q27: =-Q111 -> -35.705665 | ... S27: =-S111 -> -35.705665 | U27: -12.212 | V27: =H27-U27 -> -26.109 | W27: -53.27 | X27: =I27-W27 -> -21.045 | Y27: =-Y111 -> -17.852833 | Z27: =-Z111 -> -17.852833
B28: Share of profits less losses of associates | F28: 0 | G28: -0.453 | H28: 21.254 | I28: 54.982 | J28: 0 | K28: 0 | L28: 0 | M28: 0 | N28: 0 | O28: 0 | P28: 0 | Q28: 0 | R28: 0 | S28: 0 | U28: 0.324 | V28: =H28-U28 -> 20.93 | W28: 14.147 | X28: =I28-W28 -> 40.835 | Y28: 0 | Z28: 0
B29: Changes in fair value of financial instruments | F29: 5.972 | G29: 26.002 | H29: 66.271 | I29: 25.278 | J29: 0 | K29: =J29 -> 0 | L29: =K29 -> 0 | M29: =L29 -> 0 | N29: =M29 -> 0 | O29: =N29 -> 0 | P29: =O29 -> 0 | Q29: =P29 -> 0 | R29: =Q29 -> 0 | S29: =R29 -> 0 | U29: 7.004 | V29: =H29-U29 -> 59.267 | W29: 9.791 | X29: =I29-W29 -> 15.487 | Y29: 0 | Z29: 0
B30: Changes in the carrying amounts of financial instruments | F30: -45.209 | G30: -161.471 | H30: -468.859 | I30: -937.362 | J30: 0 | K30: 0 | L30: 0 | M30: 0 | N30: 0 | O30: 0 | P30: 0 | Q30: 0 | R30: 0 | S30: 0 | U30: -201.174 | V30: =H30-U30 -> -267.685 | W30: -429.295 | X30: =I30-W30 -> -508.067 | Y30: 0 | Z30: 0
B32: (Loss)/Profit before tax | F32: =SUM(F19,F27:F30) -> -143.65 | G32: =SUM(G19,G27:G30) -> -787.977 | H32: =SUM(H19,H27:H30) -> -2958.007 | I32: =SUM(I19,I27:I30) -> -4718.167 | J32: =SUM(J19,J27:J30) -> -5080.9477 | K32: =SUM(K19,K27:K30) -> -5709.0316 | L32: =SUM(L19,L27:L30) -> -2304.4506 | M32: =SUM(M19,M27:M30) -> 6098.4001 | ... S32: =SUM(S19,S27:S30) -> 355445.7 | U32: =SUM(U19,U27:U30) -> -1235.551 | V32: =SUM(V19,V27:V30) -> -1722.456 | W32: =SUM(W19,W27:W30) -> -2357.852 | X32: =SUM(X19,X27:X30) -> -2360.315 | Y32: =SUM(Y19,Y27:Y30) -> -2990.3457 | Z32: =SUM(Z19,Z27:Z30) -> -2090.602
B33: Income tax expense | F33: 0 | G33: 0 | H33: 0 | I33: 0 | J33: =-J115 -> 0 | K33: =-K115 -> 0 | L33: =-L115 -> 0 | M33: =-M115 -> -1097.712 | N33: =-N115 -> -4208.7587 | O33: =-O115 -> -10297.014 | P33: =-P115 -> -19161.12 | Q33: =-Q115 -> -31293.511 | ... S33: =-S115 -> -63980.226 | U33: 0 | V33: =H33-U33 -> 0 | W33: 0 | X33: 0 | Y33: 0 | Z33: 0
B35: Net profit/(loss) | F35: =F32+F33 -> -143.65 | G35: =G32+G33 -> -787.977 | H35: =H32+H33 -> -2958.007 | I35: =I32+I33 -> -4718.167 | J35: =J32+J33 -> -5080.9477 | K35: =K32+K33 -> -5709.0316 | L35: =L32+L33 -> -2304.4506 | M35: =M32+M33 -> 5000.6881 | ... S35: =S32+S33 -> 291465.47 | U35: =U32+U33 -> -1235.551 | V35: =V32+V33 -> -1722.456 | W35: =W32+W33 -> -2357.852 | X35: =X32+X33 -> -2360.315 | Y35: =Y32+Y33 -> -2990.3457 | Z35: =Z32+Z33 -> -2090.602
C36: Attributable to equity holders of the company | F36: -143.374 | G36: -787.96 | H36: -2956.491 | I36: -4698.203 | J36: =J35*J39 -> -5059.4487 | K36: =K35*K39 -> -5684.875 | L36: =L35*L39 -> -2294.6998 | M36: =M35*M39 -> 4979.5286 | N36: =N35*N39 -> 19092.106 | O36: =O35*O39 -> 46710.134 | P36: =P35*P39 -> 86920.199 | Q36: =Q35*Q39 -> 141956.12 | ... S36: =S35*S39 -> 290232.19 | U36: -1235.551 | V36: =H36-U36 -> -1720.94 | W36: -2351.173 | X36: =I36-W36 -> -2347.03 | Y36: =Y35*Y39 -> -2977.6927 | Z36: =J36-Y36 -> -2081.756
C37: Attributable to non-controlling interests | F37: =F35-F36 -> -0.276 | G37: =G35-G36 -> -0.017 | H37: =H35-H36 -> -1.516 | I37: =I35-I36 -> -19.964 | J37: =J35-J36 -> -21.499035 | K37: =K35-K36 -> -24.15665 | L37: =L35-L36 -> -9.7508317 | M37: =M35-M36 -> 21.159433 | ... S37: =S35-S36 -> 1233.2791 | U37: =U35-U36 -> 0 | V37: =H37-U37 -> -1.516 | W37: =W35-W36 -> -6.679 | X37: =I37-W37 -> -13.285 | Y37: =Y35-Y36 -> -12.653062 | Z37: =Z35-Z36 -> -8.845973
B39: Net profit attributable to equity holders of the company % | F39: =F36/F35 -> 0.99807866 | G39: =G36/G35 -> 0.99997843 | H39: =H36/H35 -> 0.99948749 | I39: =I36/I35 -> 0.9957687 | J39: =I39 -> 0.9957687 | K39: =J39 -> 0.9957687 | L39: =K39 -> 0.9957687 | M39: =L39 -> 0.9957687 | N39: =M39 -> 0.9957687 | O39: =N39 -> 0.9957687 | P39: =O39 -> 0.9957687 | Q39: =P39 -> 0.9957687 | ... S39: =R39 -> 0.9957687 | Y39: =J39 -> 0.9957687 | Z39: =Z36/Z35 -> 0.9957687
B40: Net profit attributable to non-controlling interests % | F40: =F37/F35 -> 0.0019213366 | G40: =G37/G35 -> 2.1574234e-05 | H40: =H37/H35 -> 0.00051250724 | I40: =I37/I35 -> 0.0042313042 | J40: =I40 -> 0.0042313042 | K40: =J40 -> 0.0042313042 | L40: =K40 -> 0.0042313042 | M40: =L40 -> 0.0042313042 | N40: =M40 -> 0.0042313042 | O40: =N40 -> 0.0042313042 | P40: =O40 -> 0.0042313042 | Q40: =P40 -> 0.0042313042 | ... S40: =R40 -> 0.0042313042 | Y40: =J40 -> 0.0042313042 | Z40: =Z37/Z35 -> 0.0042313042
B42: Allocation of loss attributable to financial instruments | F42: 39.483 | G42: 343.06 | H42: 1562.449 | I42: 2779.727 | J42: 1000 | K42: 1000 | L42: 1000 | M42: 1000 | N42: 1000 | O42: 1000 | P42: 1000 | Q42: 1000 | R42: 1000 | S42: 1000 | U42: 647.975 | V42: =H42-U42 -> 914.474 | W42: 1357.897 | X42: =I42-W42 -> 1421.83 | Y42: 500 | Z42: =J42-Y42 -> 500
B43: Net profit attributable to ordinary equity shareholders | F43: =F36+F42 -> -103.891 | G43: =G36+G42 -> -444.9 | H43: =H36+H42 -> -1394.042 | I43: =I36+I42 -> -1918.476 | J43: =J36+J42 -> -4059.4487 | K43: =K36+K42 -> -4684.875 | L43: =L36+L42 -> -1294.6998 | M43: =M36+M42 -> 5979.5286 | ... S43: =S36+S42 -> 291232.19 | U43: =U36+U42 -> -587.576 | V43: =V36+V42 -> -806.466 | W43: =W36+W42 -> -993.276 | X43: =X36+X42 -> -925.2 | Y43: =Y36+Y42 -> -2477.6927 | Z43: =Z36+Z42 -> -1581.756
B45: Non-IFRS adjustments
C46: Add: share-based compensation expeneses | F46: 1.024 | G46: 5.502 | H46: 23.579 | I46: 558.265 | J46: =J118 -> 669.918 | K46: =K118 -> 803.9016 | L46: =L118 -> 964.68192 | M46: =M118 -> 1061.1501 | N46: =N118 -> 1167.2651 | O46: =O118 -> 1283.9916 | P46: =P118 -> 1412.3908 | Q46: =Q118 -> 1553.6299 | ... S46: =S118 -> 1879.8922 | U46: 4.217 | V46: =H46-U46 -> 19.362 | W46: 158.852 | X46: =I46-W46 -> 399.413 | Y46: =J46/2 -> 334.959 | Z46: =J46-Y46 -> 334.959
C47: Add: changes in the carrying amounts of financial instruments | F47: =-F30 -> 45.209 | G47: =-G30 -> 161.471 | H47: =-H30 -> 468.859 | I47: =-I30 -> 937.362 | J47: =-J30 -> 0 | K47: =-K30 -> 0 | L47: =-L30 -> 0 | M47: =-M30 -> 0 | ... S47: =-S30 -> 0 | U47: =-U30 -> 201.174 | V47: =H47-U47 -> 267.685 | W47: =-W30 -> 429.295 | X47: =I47-W47 -> 508.067 | Y47: 0 | Z47: 0
C48: Others | I48: 40.568 | J48: 0 | K48: 0 | L48: 0 | M48: 0 | N48: 0 | O48: 0 | P48: 0 | Q48: 0 | R48: 0 | S48: 0 | W48: 17.731 | X48: =I48-W48 -> 22.837 | Y48: 0 | Z48: 0
B50: Adj. net profit/(loss) - non-IFRS | F50: =F35+SUM(F46:F48) -> -97.417 | G50: =G35+SUM(G46:G48) -> -621.004 | H50: =H35+SUM(H46:H48) -> -2465.569 | I50: =I35+SUM(I46:I48) -> -3181.972 | J50: =J35+SUM(J46:J48) -> -4411.0297 | K50: =K35+SUM(K46:K48) -> -4905.13 | L50: =L35+SUM(L46:L48) -> -1339.7687 | M50: =M35+SUM(M46:M47) -> 6061.8382 | N50: =N35+SUM(N46:N47) -> 20340.499 | O50: =O35+SUM(O46:O47) -> 48192.61 | P50: =P35+SUM(P46:P47) -> 88701.939 | Q50: =Q35+SUM(Q46:Q47) -> 144112.96 | R50: =R35+SUM(R46:R47) -> 213160.15 | S50: =S35+SUM(S46:S47) -> 293345.36 | U50: =U35+SUM(U46:U48) -> -1030.16 | V50: =V35+SUM(V46:V48) -> -1435.409 | W50: =W35+SUM(W46:W48) -> -1751.974 | X50: =X35+SUM(X46:X48) -> -1429.998 | Y50: =Y35+SUM(Y46:Y48) -> -2655.3867 | Z50: =Z35+SUM(Z46:Z48) -> -1755.643
C51: margin % | G51: =G50/G$4 -> -4.986462 | H51: =H50/H$4 -> -7.8919927 | I51: =I50/I$4 -> -4.3929624 | J51: =J50/J$4 -> -0.69583078 | K51: =K50/K$4 -> -0.20675178 | L51: =L50/L$4 -> -0.022781552 | M51: =M50/M$4 -> 0.050262496 | N51: =N50/N$4 -> 0.092627095 | ... S51: =S50/S$4 -> 0.22867099 | U51: =U50/U$4 -> -22.938832 | V51: =V50/V$4 -> -5.3659147 | W51: =W50/W$4 -> -9.1785495 | X51: =X50/X$4 -> -2.6806247 | Y51: =Y50/Y$4 -> -2.3798803 | Z51: =Z50/Z$4 -> -0.33610711
C52: yoy % | G52: =-(G50/F50-1) -> -5.3746985 | H52: =-(H50/G50-1) -> -2.9702949 | I52: =I50/H50-1 -> 0.29056295 | J52: =J50/I50-1 -> 0.3862566 | K52: =K50/J50-1 -> 0.11201474 | L52: =L50/K50-1 -> -0.72686377 | M52: =M50/L50-1 -> -5.5245408 | N52: =N50/M50-1 -> 2.3555002 | O52: =O50/N50-1 -> 1.3692934 | P52: =P50/O50-1 -> 0.84057138 | ... S52: =S50/R50-1 -> 0.37617358 | W52: =-(W50/U50-1) -> -0.70068145 | X52: =-(X50/V50-1) -> 0.0037696573 | Y52: =-(Y50/W50-1) -> -0.51565418 | Z52: =-(Z50/X50-1) -> -0.22772408
B54: Weighted average number of ordinary shares (mn) | F54: =13.320289*10 -> 133.20289 | G54: =15.100831*10 -> 151.00831 | H54: 159.87523 | I54: 159.52222 | J54: =AVERAGE(Y54:Z54) -> 455.73309 | K54: =Z54*1.01 -> 470.27932 | L54: =K54*1.01 -> 474.98211 | M54: =L54*1.01 -> 479.73194 | N54: =M54*1.01 -> 484.52925 | O54: =N54*1.01 -> 489.37455 | P54: =O54*1.01 -> 494.26829 | Q54: =P54*1.01 -> 499.21098 | R54: =Q54*1.01 -> 504.20309 | S54: =R54*1.01 -> 509.24512 | U54: =H54 -> 159.87523 | V54: =I54 -> 159.52222 | W54: =I54 -> 159.52222 | X54: =W54 -> 159.52222 | Y54: 445.84309 | Z54: 465.62309
B55: Diluted average number of ordinary shares (mn) | F55: =F54 -> 133.20289 | G55: =G54 -> 151.00831 | H55: =H54 -> 159.87523 | I55: =I54 -> 159.52222 | J55: =J54 -> 455.73309 | K55: =K54 -> 470.27932 | L55: =L54 -> 474.98211 | M55: =M54 -> 479.73194 | ... S55: =S54 -> 509.24512 | U55: =U54 -> 159.87523 | V55: =V54 -> 159.52222 | W55: =W54 -> 159.52222 | X55: =X54 -> 159.52222 | Y55: 445.84309 | Z55: 465.62309
...

Sheet Revenue
F1: USD/CNY | G1: 7
A4: December year-end. Rmb$ mn. | F4: 2022 | G4: 2023 | H4: 2024 | I4: 2025 | J4: 2026E | K4: 2027E | L4: 2028E | M4: 2029E | N4: 2030E | O4: 2031 | P4: 2032 | Q4: 2033 | R4: 2034 | S4: 2035 | U4: 1H24 | V4: 2H24 | W4: 1H25 | X4: 2H25 | Y4: 1H26 | Z4: 2H26
B5: Revenue | F5: =SUM(F27,F29) -> 57.409 | G5: =SUM(G27,G29) -> 124.538 | H5: =SUM(H27,H29) -> 312.414 | I5: =SUM(I27,I29) -> 724.334 | J5: =SUM(J27,J29) -> 6339.2276 | K5: =SUM(K27,K29) -> 23724.729 | L5: =SUM(L27,L29) -> 58809.369 | M5: =SUM(M27,M29) -> 120603.6 | ... S5: =SUM(S27,S29) -> 1282827.2 | U5: =SUM(U27,U29) -> 44.909 | V5: =SUM(V27,V29) -> 267.505 | W5: =SUM(W27,W29) -> 190.877 | X5: =SUM(X27,X29) -> 533.457 | Y5: =SUM(Y27,Y29) -> 1115.7648 | Z5: =SUM(Z27,Z29) -> 5223.4628
B6: yoy % | G6: =G5/F5-1 -> 1.1693114 | H6: =H5/G5-1 -> 1.5085837 | I6: =I5/H5-1 -> 1.3185069 | J6: =J5/I5-1 -> 7.7518018 | K6: =K5/J5-1 -> 2.7425269 | L6: =L5/K5-1 -> 1.4788215 | M6: =M5/L5-1 -> 1.0507549 | N6: =N5/M5-1 -> 0.82080436 | ... S6: =S5/R5-1 -> 0.26126355 | W6: =W5/U5-1 -> 3.2503062 | X6: =X5/V5-1 -> 0.9941945 | Y6: =Y5/W5-1 -> 4.8454649 | Z6: =Z5/X5-1 -> 8.7917223
B8: By product lines:
B9: Open platform and API | H9: 48.484 | I9: 190.379 | J9: =J29 -> 5248.44 | K9: =K29 -> 21931 | L9: =L29 -> 56143.5 | M9: =M29 -> 116777.5 | N9: =N29 -> 214312 | O9: =O29 -> 354508.05 | P9: =P29 -> 537346.44 | Q9: =Q29 -> 757306.25 | ... S9: =S29 -> 1270029.7
B10: Enterprise-level agents | H10: 47.492 | I10: 165.687 | J10: =I10*(1+J16) -> 414.2175 | K10: =J10*(1+K16) -> 745.5915 | L10: =K10*(1+L16) -> 1230.226 | M10: =L10*(1+M16) -> 1931.4548 | N10: =M10*(1+N16) -> 2877.8676 | O10: =N10*(1+O16) -> 4057.7933 | P10: =O10*(1+P16) -> 5396.8652 | Q10: =P10*(1+Q16) -> 6746.0814 | ... S10: =R10*(1+S16) -> 8603.2777
B11: Enterprise-level general-purpose large models | H11: 214.502 | I11: 365.724 | J11: =I11*(1+J17) -> 672.93216 | K11: =J11*(1+K17) -> 1043.0448 | L11: =K11*(1+L17) -> 1428.9714 | M11: =L11*(1+M17) -> 1886.2423 | N11: =M11*(1+N17) -> 2395.5277 | O11: =N11*(1+O17) -> 2922.5438 | P11: =O11*(1+P17) -> 3419.3763 | Q11: =P11*(1+Q17) -> 3829.7014 | ... S11: =R11*(1+S17) -> 4179.7361
B12: Technical service and others | H12: 1.936 | I12: 2.544 | J12: =I12*(1+J18) -> 3.63792 | K12: =J12*(1+K18) -> 5.093088 | L12: =K12*(1+L18) -> 6.6719453 | M12: =L12*(1+M18) -> 8.4066511 | N12: =M12*(1+N18) -> 10.172048 | O12: =N12*(1+O18) -> 11.799575 | P12: =O12*(1+P18) -> 13.097529 | Q12: =P12*(1+Q18) -> 13.88338 | ... S12: =R12*(1+S18) -> 14.444269
B14: yoy %
B15: Open platform and API | I15: =I9/H9-1 -> 2.9266356 | J15: =J9/I9-1 -> 26.568377 | K15: =K9/J9-1 -> 3.178575 | L15: =L9/K9-1 -> 1.5600064 | M15: =M9/L9-1 -> 1.0799825 | N15: =N9/M9-1 -> 0.83521654 | O15: =O9/N9-1 -> 0.65416798 | P15: =P9/O9-1 -> 0.51575245 | ... S15: =S9/R9-1 -> 0.26359551
B16: Enterprise-level agents | I16: =I10/H10-1 -> 2.4887349 | J16: 1.5 | K16: 0.8 | L16: 0.65 | M16: =L16-8% -> 0.57 | N16: =M16-8% -> 0.49 | O16: =N16-8% -> 0.41 | P16: =O16-8% -> 0.33 | Q16: =P16-8% -> 0.25 | R16: =Q16-8% -> 0.17 | S16: =R16-8% -> 0.09
B17: Enterprise-level general-purpose large models | I17: =I11/H11-1 -> 0.7049911 | J17: 0.84 | K17: 0.55 | L17: 0.37 | M17: =L17-5% -> 0.32 | N17: =M17-5% -> 0.27 | O17: =N17-5% -> 0.22 | P17: =O17-5% -> 0.17 | Q17: =P17-5% -> 0.12 | R17: =Q17-5% -> 0.07 | S17: =R17-5% -> 0.02
B18: Technical service and others | I18: =I12/H12-1 -> 0.31404959 | J18: 0.43 | K18: 0.4 | L18: 0.31 | M18: =L18-5% -> 0.26 | N18: =M18-5% -> 0.21 | O18: =N18-5% -> 0.16 | P18: =O18-5% -> 0.11 | Q18: =P18-5% -> 0.06 | R18: 0.02 | S18: 0.02
B20: Revenue breakdown %
B21: Open platform and API | H21: =H9/$H$5 -> 0.15519151 | I21: =I9/$I$5 -> 0.26283317 | J21: =J9/$J$5 -> 0.82793052 | K21: =K9/K$5 -> 0.9243941 | L21: =L9/L$5 -> 0.95466931 | M21: =M9/M$5 -> 0.96827538 | N21: =N9/N$5 -> 0.97593955 | O21: =O9/O$5 -> 0.980658 | P21: =P9/P$5 -> 0.98383425 | Q21: =Q9/Q$5 -> 0.9862095 | R21: =R9/R$5 -> 0.98819694 | S21: =S9/S$5 -> 0.99002402
B22: Enterprise-level agents | H22: =H10/$H$5 -> 0.15201623 | I22: =I10/$I$5 -> 0.22874392 | J22: =J10/$J$5 -> 0.065341951 | K22: =K10/$K$5 -> 0.031426765 | L22: =L10/L$5 -> 0.020918877 | M22: =M10/M$5 -> 0.016014901 | N22: =N10/N$5 -> 0.013105308 | O22: =O10/O$5 -> 0.011224872 | P22: =P10/P$5 -> 0.0098811872 | Q22: =Q10/Q$5 -> 0.0087851508 | R22: =R10/R$5 -> 0.0077602396 | S22: =S10/S$5 -> 0.0067064977
B23: Enterprise-level general-purpose large models | H23: =H11/$H$5 -> 0.68659535 | I23: =I11/$I$5 -> 0.50491072 | J23: =J11/$J$5 -> 0.10615365 | K23: =K11/$K$5 -> 0.043964457 | L23: =L11/L$5 -> 0.024298364 | M23: =M11/M$5 -> 0.015640016 | N23: =N11/N$5 -> 0.010908816 | O23: =O11/O$5 -> 0.0080844878 | P23: =P11/P$5 -> 0.0062605783 | Q23: =Q11/Q$5 -> 0.0049872663 | R23: =R11/R$5 -> 0.004028899 | S23: =S11/S$5 -> 0.0032582223
B24: Technical service and others | H24: =H12/$H$5 -> 0.0061969054 | I24: =I12/$I$5 -> 0.0035121919 | J24: =J12/$J$5 -> 0.00057387433 | K24: =K12/$K$5 -> 0.00021467423 | L24: =L12/L$5 -> 0.00011345038 | M24: =M12/M$5 -> 6.9704808e-05 | N24: =N12/N$5 -> 4.6321735e-05 | O24: =O12/O$5 -> 3.2640579e-05 | P24: =P12/P$5 -> 2.3980427e-05 | Q24: =Q12/Q$5 -> 1.8079768e-05 | R24: =R12/R$5 -> 1.3923008e-05 | S24: =S12/S$5 -> 1.1259715e-05
B26: By deployment methods:
B27: On-premise deployment | F27: 54.815 | G27: 112.614 | H27: 263.93 | I27: 533.955 | J27: =SUM(J10:J12) -> 1090.7876 | K27: =SUM(K10:K12) -> 1793.7294 | L27: =SUM(L10:L12) -> 2665.8694 | M27: =SUM(M10:M12) -> 3826.1037 | N27: =SUM(N10:N12) -> 5283.5674 | O27: =SUM(O10:O12) -> 6992.1367 | P27: =SUM(P10:P12) -> 8829.339 | Q27: =SUM(Q10:Q12) -> 10589.666 | ... S27: =SUM(S10:S12) -> 12797.458 | U27: 26.806 | V27: =H27-U27 -> 237.124 | W27: 161.777 | X27: =I27-W27 -> 372.178 | Y27: =W27*(1+Y28) -> 388.2648 | Z27: =J27-Y27 -> 702.52278
B28: yoy % | G28: =G27/F27-1 -> 1.0544377 | H28: =H27/G27-1 -> 1.3436695 | I28: =I27/H27-1 -> 1.0230932 | J28: =J27/I27-1 -> 1.0428455 | K28: =K27/J27-1 -> 0.64443515 | L28: =L27/K27-1 -> 0.48621599 | M28: =M27/L27-1 -> 0.43521802 | N28: =N27/M27-1 -> 0.38092633 | ... S28: =S27/R27-1 -> 0.066023378 | W28: =W27/U27-1 -> 5.0351041 | X28: =X27/V27-1 -> 0.56955011 | Y28: 1.4 | Z28: =Z27/X27-1 -> 0.88759889
A29: a+b | B29: Cloud-based deployment | F29: 2.594 | G29: 11.924 | H29: 48.484 | I29: 190.379 | J29: =J35*0.5 -> 5248.44 | K29: =K35*0.5 -> 21931 | L29: =L35*0.5 -> 56143.5 | M29: =M35*0.5 -> 116777.5 | N29: =N35*0.5 -> 214312 | O29: =O35*0.5 -> 354508.05 | P29: =P35*0.5 -> 537346.44 | Q29: =Q35*0.5 -> 757306.25 | ... S29: =S35*0.5 -> 1270029.7 | U29: 18.103 | V29: =H29-U29 -> 30.381 | W29: 29.1 | X29: =I29-W29 -> 161.279 | Y29: =W29*(1+Y30) -> 727.5 | Z29: =J29-Y29 -> 4520.94
B30: yoy % | G30: =G29/F29-1 -> 3.5967618 | H30: =H29/G29-1 -> 3.0660852 | I30: =I29/H29-1 -> 2.9266356 | J30: =J29/I29-1 -> 26.568377 | K30: =K29/J29-1 -> 3.178575 | L30: =L29/K29-1 -> 1.5600064 | M30: =M29/L29-1 -> 1.0799825 | N30: =N29/M29-1 -> 0.83521654 | ... S30: =S29/R29-1 -> 0.26359551 | W30: =W29/U29-1 -> 0.60746838 | X30: =X29/V29-1 -> 4.3085481 | Y30: 24 | Z30: =Z29/X29-1 -> 27.031796
G32: 2025.3 | H32: 2025.12 | I32: 2026.3 | J32: 2026 | K32: 2027 | L32: =K32+1 -> 2028 | M32: =L32+1 -> 2029 | N32: =M32+1 -> 2030 | O32: =N32+1 -> 2031 | P32: =O32+1 -> 2032 | Q32: =P32+1 -> 2033 | R32: =Q32+1 -> 2034 | S32: =R32+1 -> 2035
C33: Year- end ARR ($ mn) | G33: =H33/10 -> 3.90625 | H33: =I33/6.4 -> 39.0625 | I33: 250 | J33: =SUM(J46+J57) -> 1499.5543 | K33: =SUM(K46+K57) -> 6266 | L33: =SUM(L46+L57) -> 16041 | M33: =SUM(M46+M57) -> 33365 | N33: =SUM(N46+N57) -> 61232 | O33: =SUM(O46+O57) -> 101288.01 | P33: =SUM(P46+P57) -> 153527.56 | Q33: =SUM(Q46+Q57) -> 216373.22 | ... S33: =SUM(S46+S57) -> 362865.64
D34: yoy % | I34: 6.4 | J34: =J33/H33-1 -> 37.38859 | K34: =K33/J33-1 -> 3.178575 | L34: =L33/K33-1 -> 1.5600064 | M34: =M33/L33-1 -> 1.0799825 | N34: =N33/M33-1 -> 0.83521654 | O34: =O33/N33-1 -> 0.65416798 | P34: =P33/O33-1 -> 0.51575245 | Q34: =Q33/P33-1 -> 0.4093445 | R34: =R33/Q33-1 -> 0.32719359 | S34: =S33/R33-1 -> 0.26359551
C35: Year-end ARR (Rmb mn) | G35: =G33*$G$1 -> 27.34375 | H35: =H33*$G$1 -> 273.4375 | I35: =I33*$G$1 -> 1750 | J35: =J33*$G$1 -> 10496.88 | K35: =K33*$G$1 -> 43862 | L35: =L33*$G$1 -> 112287 | M35: =M33*$G$1 -> 233555 | N35: =N33*$G$1 -> 428624 | ... S35: =S33*$G$1 -> 2540059.5
D36: yoy % | I36: 64 | J36: =J35/H35-1 -> 37.38859 | K36: =K35/J35-1 -> 3.178575 | L36: =L35/K35-1 -> 1.5600064 | M36: =M35/L35-1 -> 1.0799825 | N36: =N35/M35-1 -> 0.83521654 | O36: =O35/N35-1 -> 0.65416798 | P36: =P35/O35-1 -> 0.51575245 | Q36: =Q35/P35-1 -> 0.4093445 | R36: =R35/Q35-1 -> 0.32719359 | S36: =S35/R35-1 -> 0.26359551
B38: a | C38: API / pay-as-you-go
C39: Daily token volume (bn) | I39: =H33*$G$1/I43*1000/365 -> 218.40928 | J39: =I39*(1+J40) -> 4193.4582 | K39: =J39*(1+K40) -> 13350.053 | L39: =K39*(1+L40) -> 28780.969 | M39: =L39*(1+M40) -> 46069.595 | N39: =M39*(1+N40) -> 68010.104 | O39: =N39*(1+O40) -> 93921.793 | P39: =O39*(1+P40) -> 122548.98 | Q39: =P39*(1+Q40) -> 152431.14 | ... S39: =R39*(1+S40) -> 210594.21
D40: yoy % | J40: 18.2 | K40: 2.1835426 | L40: 1.1558693 | M40: 0.60069647 | N40: 0.47624705 | O40: =N40*0.8 -> 0.38099764 | P40: =O40*0.8 -> 0.30479811 | Q40: =P40*0.8 -> 0.24383849 | R40: =Q40*0.8 -> 0.19507079 | S40: =R40*0.8 -> 0.15605663
C41: Blended API price (per 1M tokens) | I41: =0.7*7 -> 4.9 | J41: =I41*(1+J42) -> 7.84 | K41: =J41*(1+K42) -> 10.192 | L41: =K41*(1+L42) -> 12.2304 | M41: =L41*(1+M42) -> 15.89952 | N41: =M41*(1+N42) -> 19.715405 | O41: =N41*(1+O42) -> 23.500763 | P41: =O41*(1+P42) -> 27.11048 | Q41: =P41*(1+Q42) -> 30.441815 | ... S41: =R41*(1+S42) -> 36.063753
D42: yoy % | J42: 0.6 | K42: 0.3 | L42: 0.2 | M42: 0.3 | N42: 0.24 | O42: =N42*0.8 -> 0.192 | P42: =O42*0.8 -> 0.1536 | Q42: =P42*0.8 -> 0.12288 | R42: =Q42*0.8 -> 0.098304 | S42: =R42*0.8 -> 0.0786432
C43: Realized price | I43: =I41*(1-I45) -> 3.43 | J43: =J41*(1-J45) -> 5.88 | K43: =K41*(1-K45) -> 8.1536 | L43: =L41*(1-L45) -> 9.78432 | M43: =M41*(1-M45) -> 12.719616 | N43: =N41*(1-N45) -> 15.772324 | O43: =O41*(1-O45) -> 18.80061 | P43: =P41*(1-P45) -> 21.688384 | ... S43: =S41*(1-S45) -> 28.851003
D44: yoy % | J44: =J43/I43-1 -> 0.71428571 | K44: =K43/J43-1 -> 0.38666667 | L44: =L43/K43-1 -> 0.2 | M44: =M43/L43-1 -> 0.3 | N44: =N43/M43-1 -> 0.24 | O44: =O43/N43-1 -> 0.192 | P44: =P43/O43-1 -> 0.1536 | Q44: =Q43/P43-1 -> 0.12288 | ... S44: =S43/R43-1 -> 0.0786432
D45: discount % | I45: 0.3 | J45: 0.25 | K45: 0.2 | L45: 0.2 | M45: 0.2 | N45: 0.2 | O45: 0.2 | P45: 0.2 | Q45: 0.2 | R45: 0.2 | S45: 0.2
B46: Revenue from API | J46: =J39*365*J43/$G$1/1000 -> 1285.7143 | K46: =K39*365*K43/$G$1/1000 -> 5675.8016 | L46: =L39*365*L43/$G$1/1000 -> 14683.544 | M46: =M39*365*M43/$G$1/1000 -> 30555.065 | N46: =N39*365*N43/$G$1/1000 -> 55932.463 | O46: =O39*365*O43/$G$1/1000 -> 92073.179 | P46: =P39*365*P43/$G$1/1000 -> 138589.94 | Q46: =Q39*365*Q43/$G$1/1000 -> 193565.99 | ... S46: =S39*365*S43/$G$1/1000 -> 316812.4
B47: yoy % | K47: =K46/J46-1 -> 3.4145124 | L47: =L46/K46-1 -> 1.5870432
B48: % of API | J48: =J46/J33 -> 0.85739763 | K48: =K46/K33 -> 0.90580938 | L48: =L46/L33 -> 0.91537583
...

Sheet Y&Q
B4: December year-end (Rmb mn) | F4: 2022 | G4: 2023 | H4: 2024 | I4: 2025 | J4: 2026E | K4: 2027E | L4: 2028E | M4: 2029E | N4: 2030E | O4: 2031 | P4: 2032 | Q4: 2033 | R4: 2034 | S4: 2035 | U4: 1H24 | V4: 2H24 | W4: 1H25 | X4: 2H25 | Y4: 1H26E | Z4: 2H26E
C5: On-premise deployment | F5: =Revenue!F27 -> 54.815 | G5: =Revenue!G27 -> 112.614 | H5: =Revenue!H27 -> 263.93 | I5: =Revenue!I27 -> 533.955 | J5: =Revenue!J27 -> 1090.7876 | K5: =Revenue!K27 -> 1793.7294 | L5: =Revenue!L27 -> 2665.8694 | M5: =Revenue!M27 -> 3826.1037 | ... S5: =Revenue!S27 -> 12797.458 | U5: =Revenue!U27 -> 26.806 | V5: =Revenue!V27 -> 237.124 | W5: =Revenue!W27 -> 161.777 | X5: =Revenue!X27 -> 372.178 | Y5: =Revenue!Y27 -> 388.2648 | Z5: =Revenue!Z27 -> 702.52278
D6: yoy % | H6: =H5/G5-1 -> 1.3436695 | I6: =I5/H5-1 -> 1.0230932 | J6: =J5/I5-1 -> 1.0428455 | K6: =K5/J5-1 -> 0.64443515 | L6: =L5/K5-1 -> 0.48621599 | M6: =M5/L5-1 -> 0.43521802 | N6: =N5/M5-1 -> 0.38092633 | O6: =O5/N5-1 -> 0.32337419 | ... S6: =S5/R5-1 -> 0.066023378
C7: Cloud-based deployment | F7: =Revenue!F29 -> 2.594 | G7: =Revenue!G29 -> 11.924 | H7: =Revenue!H29 -> 48.484 | I7: =Revenue!I29 -> 190.379 | J7: =Revenue!J29 -> 5248.44 | K7: =Revenue!K29 -> 21931 | L7: =Revenue!L29 -> 56143.5 | M7: =Revenue!M29 -> 116777.5 | ... S7: =Revenue!S29 -> 1270029.7 | U7: =Revenue!U29 -> 18.103 | V7: =Revenue!V29 -> 30.381 | W7: =Revenue!W29 -> 29.1 | X7: =Revenue!X29 -> 161.279 | Y7: =Revenue!Y29 -> 727.5 | Z7: =Revenue!Z29 -> 4520.94
D8: yoy % | H8: =H7/G7-1 -> 3.0660852 | I8: =I7/H7-1 -> 2.9266356 | J8: =J7/I7-1 -> 26.568377 | K8: =K7/J7-1 -> 3.178575 | L8: =L7/K7-1 -> 1.5600064 | M8: =M7/L7-1 -> 1.0799825 | N8: =N7/M7-1 -> 0.83521654 | O8: =O7/N7-1 -> 0.65416798 | ... S8: =S7/R7-1 -> 0.26359551
B9: Revenue | F9: =Revenue!F5 -> 57.409 | G9: =Revenue!G5 -> 124.538 | H9: =Revenue!H5 -> 312.414 | I9: =Revenue!I5 -> 724.334 | J9: =Revenue!J5 -> 6339.2276 | K9: =Revenue!K5 -> 23724.729 | L9: =Revenue!L5 -> 58809.369 | M9: =Revenue!M5 -> 120603.6 | ... S9: =Revenue!S5 -> 1282827.2 | U9: =Revenue!U5 -> 44.909 | V9: =Revenue!V5 -> 267.505 | W9: =Revenue!W5 -> 190.877 | X9: =Revenue!X5 -> 533.457 | Y9: =Revenue!Y5 -> 1115.7648 | Z9: =Revenue!Z5 -> 5223.4628
C10: yoy % | H10: =H9/G9-1 -> 1.5085837 | I10: =I9/H9-1 -> 1.3185069 | J10: =J9/I9-1 -> 7.7518018 | K10: =K9/J9-1 -> 2.7425269 | L10: =L9/K9-1 -> 1.4788215 | M10: =M9/L9-1 -> 1.0507549 | N10: =N9/M9-1 -> 0.82080436 | O10: =O9/N9-1 -> 0.64620893 | ... S10: =S9/R9-1 -> 0.26126355
C11: Cost of sales | F11: =Model!F7 -> -26.049 | G11: =Model!G7 -> -44.056 | H11: =Model!H7 -> -136.525 | I11: =Model!I7 -> -427.678 | J11: =Model!J7 -> -4527.7268 | K11: =Model!K7 -> -17264.397 | L11: =Model!L7 -> -42438.455 | M11: =Model!M7 -> -85122.007 | ... S11: =Model!S7 -> -811651.86 | U11: =Model!U7 -> -22.95 | V11: =Model!V7 -> -113.575 | W11: =Model!W7 -> -95.453 | X11: =Model!X7 -> -332.225 | Y11: =Model!Y7 -> -735.38446 | Z11: =Model!Z7 -> -3792.3423
D12: Amongst which: Inference cost | F12: =Revenue!F130 -> 0 | G12: =Revenue!G130 -> -11.996 | H12: =Revenue!H130 -> -30.173 | I12: =Revenue!I130 -> 0 | J12: =Revenue!J130 -> 0 | K12: =Revenue!K130 -> 0 | L12: =Revenue!L130 -> 0 | M12: =Revenue!M130 -> 0 | ... S12: =Revenue!S130 -> 0 | U12: =Revenue!U130 -> -8.451 | V12: =Revenue!V130 -> -21.722 | W12: =Revenue!W130 -> -35.845 | X12: =Revenue!X130 -> 0 | Y12: =Revenue!Y130 -> 0 | Z12: =Revenue!Z130 -> 0
B14: Gross (loss)/profit | F14: =Model!F9 -> 31.36 | G14: =Model!G9 -> 80.482 | H14: =Model!H9 -> 175.889 | I14: =Model!I9 -> 296.656 | J14: =Model!J9 -> 1811.5008 | K14: =Model!K9 -> 6460.3325 | L14: =Model!L9 -> 16370.914 | M14: =Model!M9 -> 35481.597 | ... S14: =Model!S9 -> 471175.34 | U14: =Model!U9 -> 21.959 | V14: =Model!V9 -> 153.93 | W14: =Model!W9 -> 95.424 | X14: =Model!X9 -> 201.232 | Y14: =Model!Y9 -> 380.38034 | Z14: =Model!Z9 -> 1431.1205
C15: yoy % | H15: =-(H14/G14-1) -> -1.1854452 | I15: =I14/H14-1 -> 0.68660917 | J15: =J14/I14-1 -> 5.1064021 | K15: =K14/J14-1 -> 2.5662874 | L15: =L14/K14-1 -> 1.5340668 | M15: =M14/L14-1 -> 1.1673559 | N15: =N14/M14-1 -> 0.9293395 | O15: =O14/N14-1 -> 0.74382603 | P15: =P14/O14-1 -> 0.55194837 | ... S15: =S14/R14-1 -> 0.29461363
C16: GP Margin % | G16: =G14/G9 -> 0.64624452 | H16: =H14/H9 -> 0.56299974 | I16: =I14/I9 -> 0.40955692 | J16: =J14/J9 -> 0.2857605 | K16: =K14/K9 -> 0.27230374 | L16: =L14/L9 -> 0.27837255 | M16: =M14/M9 -> 0.29420014 | N16: =N14/N9 -> 0.31173693 | ... S16: =S14/S9 -> 0.36729448 | U16: =U14/U9 -> 0.48896658 | V16: =V14/V9 -> 0.5754285 | W16: =W14/W9 -> 0.49992403 | X16: =X14/X9 -> 0.37722253 | Y16: =Y14/Y9 -> 0.34091445 | Z16: =Z14/Z9 -> 0.27397926
C18: Other income | I18: =Model!F13 -> 1.784 | J18: =Model!G13 -> 9.965 | K18: =Model!H13 -> 19.281 | L18: =Model!I13 -> 14.839 | M18: =Model!J13 -> 33.14836 | N18: =Model!K13 -> 432.84256 | O18: =Model!L13 -> 199.21519 | P18: =Model!M13 -> 414.59592 | ... S18: =Model!P13 -> 1673.757 | U18: =Model!R13 -> 4958.4363 | V18: =Model!S13 -> 7823.4091 | W18: =Model!T13 -> 0 | X18: =Model!U13 -> 4.174 | Y18: =Model!V13 -> 15.107 | Z18: =Model!W13 -> 4.614
C19: Selling and distribution expenses | F19: =Model!F14 -> -15.139 | G19: =Model!G14 -> -101.198 | H19: =Model!H14 -> -387.475 | I19: =Model!I14 -> -390.869 | J19: =Model!J14 -> -508.1297 | K19: =Model!K14 -> -736.78807 | L19: =Model!L14 -> -1105.1821 | M19: =Model!M14 -> -1602.514 | ... S19: =Model!S14 -> -8288.5624 | U19: =Model!U14 -> -144.194 | V19: =Model!V14 -> -243.281 | W19: =Model!W14 -> -208.57 | X19: =Model!X14 -> -182.299 | Y19: =Model!Y14 -> -245.46826 | Z19: =Model!Z14 -> -262.66144
C20: Administrative expenses | F20: =Model!F15 -> -32.316 | G20: =Model!G15 -> -66.302 | H20: =Model!H15 -> -133.603 | I20: =Model!I15 -> -505.357 | J20: =Model!J15 -> -656.9641 | K20: =Model!K15 -> -952.59794 | L20: =Model!L15 -> -1428.8969 | M20: =Model!M15 -> -2071.9005 | ... S20: =Model!S15 -> -10716.335 | U20: =Model!U15 -> -51.452 | V20: =Model!V15 -> -82.151 | W20: =Model!W15 -> -185.165 | X20: =Model!X15 -> -320.192 | Y20: =Model!Y15 -> -334.72944 | Z20: =Model!Z15 -> -322.23466
C21: Research and development expenses | F21: =Model!F16 -> -84.377 | G21: =Model!G16 -> -528.884 | H21: =Model!H16 -> -2195.436 | I21: =Model!I16 -> -3180.443 | J21: =Model!J16 -> -5724.7974 | K21: =Model!K16 -> -10877.115 | L21: =Model!L16 -> -16304.795 | M21: =Model!M16 -> -26087.673 | ... S21: =Model!S16 -> -104512.45 | U21: =Model!U16 -> -859.217 | V21: =Model!V16 -> -1336.219 | W21: =Model!W16 -> -1594.661 | X21: =Model!X16 -> -1585.782 | Y21: =Model!Y16 -> -2789.412 | Z21: =Model!Z16 -> -2935.3854
D22: Amongst which: Training cost | F22: =-Model!F97 -> -14.633 | G22: =-Model!G97 -> -311.746 | H22: =-Model!H97 -> -1552.832 | I22: =-Model!I97 -> -2249.5275 | J22: =-Model!J97 -> -4049.1495 | K22: =-Model!K97 -> -7693.3841 | L22: =-Model!L97 -> -11532.383 | M22: =-Model!M97 -> -18451.812 | ... S22: =-Model!S97 -> -73921.662 | U22: =-Model!U97 -> -603.237 | V22: =-Model!V97 -> -949.595 | W22: =-Model!W97 -> -1145.124 | X22: =-Model!X97 -> 0 | Y22: =-Model!Y97 -> 0 | Z22: =-Model!Z97 -> 0
B24: Operating profit | F24: =Model!F19 -> -98.719 | G24: =Model!G19 -> -625.723 | H24: =Model!H19 -> -2538.352 | I24: =Model!I19 -> -3786.75 | J24: =Model!J19 -> -5045.242 | K24: =Model!K19 -> -5673.326 | L24: =Model!L19 -> -2268.745 | M24: =Model!M19 -> 6134.1057 | ... S24: =Model!S19 -> 355481.4 | U24: =Model!U19 -> -1029.493 | V24: =Model!V19 -> -1508.859 | W24: =Model!W19 -> -1899.225 | X24: =Model!X19 -> -1887.525 | Y24: =Model!Y19 -> -2972.4929 | Z24: =Model!Z19 -> -2072.7491
B25: Adj. operating profit - non-IFRS | F25: =Model!F23 -> -97.695 | G25: =Model!G23 -> -620.221 | H25: =Model!H23 -> -2514.773 | I25: =Model!I23 -> -3228.485 | J25: =Model!J23 -> -4375.324 | K25: =Model!K23 -> -4869.4244 | L25: =Model!L23 -> -1304.063 | M25: =Model!M23 -> 7195.2558 | ... S25: =Model!S23 -> 357361.3 | U25: =Model!U23 -> -1025.276 | V25: =Model!V23 -> -1489.497 | W25: =Model!W23 -> -1740.373 | X25: =Model!X23 -> -1488.112 | Y25: =Model!Y23 -> -2637.5339 | Z25: =Model!Z23 -> -1737.7901
C26: yoy % | G26: =-(G25/F25-1) -> -5.3485439 | H26: =-(H25/G25-1) -> -3.0546402 | I26: =-(I25/H25-1) -> -0.28380772 | J26: =-(J25/I25-1) -> -0.35522514 | K26: =-(K25/J25-1) -> -0.11292886 | L26: =-(L25/K25-1) -> 0.73219359 | M26: =-(M25/L25-1) -> 6.5175675 | N26: =N25/M25-1 -> 2.4168297 | O26: =O25/N25-1 -> 1.3805335 | P26: =P25/O25-1 -> 0.84362507 | Q26: =Q25/P25-1 -> 0.62598871 | R26: =R25/Q25-1 -> 0.47975801 | S26: =S25/R25-1 -> 0.37652092 | W26: =-(W25/U25-1) -> -0.6974678 | X26: =-(X25/V25-1) -> 0.0009298441 | Y26: =-(Y25/W25-1) -> -0.51549919 | Z26: =-(Z25/X25-1) -> -0.16778182
C27: OP Margin % | G27: =G25/G9 -> -4.9801747 | H27: =H25/H9 -> -8.0494888 | I27: =I25/I9 -> -4.4571772 | J27: =J25/J9 -> -0.69019829 | K27: =K25/K9 -> -0.20524678 | L27: =L25/L5 -> -0.4891699 | M27: =M25/M5 -> 1.88057 | N27: =N25/N5 -> 4.6530993 | O27: =O25/O5 -> 8.3701637 | P27: =P25/P5 -> 12.220481 | Q27: =Q25/Q5 -> 16.5673 | R27: =R25/R5 -> 21.625577 | S27: =S25/S5 -> 27.924397 | W27: =W25/W9 -> -9.1177722 | X27: =X25/X9 -> -2.7895632 | Y27: =Y25/Y9 -> -2.3638798 | Z27: =Z25/Z9 -> -0.33268929
B29: (Loss)/Profit before tax | F29: =Model!F32 -> -143.65 | G29: =Model!G32 -> -787.977 | H29: =Model!H32 -> -2958.007 | I29: =Model!I32 -> -4718.167 | J29: =Model!J32 -> -5080.9477 | K29: =Model!K32 -> -5709.0316 | L29: =Model!L32 -> -2304.4506 | M29: =Model!M32 -> 6098.4001 | ... S29: =Model!S32 -> 355445.7 | U29: =Model!U32 -> -1235.551 | V29: =Model!V32 -> -1722.456 | W29: =Model!W32 -> -2357.852 | X29: =Model!X32 -> -2360.315 | Y29: =Model!Y32 -> -2990.3457 | Z29: =Model!Z32 -> -2090.602
C30: Income tax expense | F30: =Model!F33 -> 0 | G30: =Model!G33 -> 0 | H30: =Model!H33 -> 0 | I30: =Model!I33 -> 0 | J30: =Model!J33 -> 0 | K30: =Model!K33 -> 0 | L30: =Model!L33 -> 0 | M30: =Model!M33 -> -1097.712 | ... S30: =Model!S33 -> -63980.226 | U30: =Model!U33 -> 0 | V30: =Model!V33 -> 0 | W30: =Model!W33 -> 0 | X30: =Model!X33 -> 0 | Y30: =Model!Y33 -> 0 | Z30: =Model!Z33 -> 0
B31: Net profit/(loss) | F31: =Model!F35 -> -143.65 | G31: =Model!G35 -> -787.977 | H31: =Model!H35 -> -2958.007 | I31: =Model!I35 -> -4718.167 | J31: =Model!J35 -> -5080.9477 | K31: =Model!K35 -> -5709.0316 | L31: =Model!L35 -> -2304.4506 | M31: =Model!M35 -> 5000.6881 | ... S31: =Model!S35 -> 291465.47 | U31: =Model!U35 -> -1235.551 | V31: =Model!V35 -> -1722.456 | W31: =Model!W35 -> -2357.852 | X31: =Model!X35 -> -2360.315 | Y31: =Model!Y35 -> -2990.3457 | Z31: =Model!Z35 -> -2090.602
B32: Adj. net profit/(loss) - non-IFRS | F32: =Model!F50 -> -97.417 | G32: =Model!G50 -> -621.004 | H32: =Model!H50 -> -2465.569 | I32: =Model!I50 -> -3181.972 | J32: =Model!J50 -> -4411.0297 | K32: =Model!K50 -> -4905.13 | L32: =Model!L50 -> -1339.7687 | M32: =Model!M50 -> 6061.8382 | ... S32: =Model!S50 -> 293345.36 | U32: =Model!U50 -> -1030.16 | V32: =Model!V50 -> -1435.409 | W32: =Model!W50 -> -1751.974 | X32: =Model!X50 -> -1429.998 | Y32: =Model!Y50 -> -2655.3867 | Z32: =Model!Z50 -> -1755.643
C33: yoy % | G33: =-(G32/F32-1) -> -5.3746985 | H33: =-(H32/G32-1) -> -2.9702949 | I33: =-(I32/H32-1) -> -0.29056295 | J33: =-(J32/I32-1) -> -0.3862566 | K33: =-(K32/J32-1) -> -0.11201474 | L33: =-(L32/K32-1) -> 0.72686377 | M33: =-(M32/L32-1) -> 5.5245408 | N33: =N32/M32-1 -> 2.3555002 | O33: =O32/N32-1 -> 1.3692934 | P33: =P32/O32-1 -> 0.84057138 | Q33: =Q32/P32-1 -> 0.62468779 | R33: =R32/Q32-1 -> 0.47911855 | S33: =S32/R32-1 -> 0.37617358 | W33: =-(W32/U32-1) -> -0.70068145 | X33: =-(X32/V32-1) -> 0.0037696573 | Y33: =-(Y32/W32-1) -> -0.51565418 | Z33: =-(Z32/X32-1) -> -0.22772408
C34: NP Margin % | G34: =G32/G9 -> -4.986462 | H34: =H32/H9 -> -7.8919927 | I34: =I32/I9 -> -4.3929624 | J34: =J32/J9 -> -0.69583078 | K34: =K32/K9 -> -0.20675178 | L34: =L32/L9 -> -0.022781552 | M34: =M32/M9 -> 0.050262496 | N34: =N32/N9 -> 0.092627095 | ... S34: =S32/S9 -> 0.22867099 | W34: =W32/W9 -> -9.1785495 | X34: =X32/X9 -> -2.6806247 | Y34: =Y32/Y9 -> -2.3798803 | Z34: =Z32/Z9 -> -0.33610711
B36: GPM | G36: =G14/G9 -> 0.64624452 | H36: =H14/H9 -> 0.56299974 | I36: =I14/I9 -> 0.40955692 | J36: =J14/J9 -> 0.2857605 | K36: =K14/K9 -> 0.27230374 | L36: =L14/L9 -> 0.27837255 | M36: =M14/M9 -> 0.29420014 | N36: =N14/N9 -> 0.31173693 | ... S36: =S14/S9 -> 0.36729448 | U36: =U14/U9 -> 0.48896658 | V36: =V14/V9 -> 0.5754285 | W36: =W14/W9 -> 0.49992403 | X36: =X14/X9 -> 0.37722253 | Y36: =Y14/Y9 -> 0.34091445 | Z36: =Z14/Z9 -> 0.27397926
B37: Adj. OPM | G37: =G25/G9 -> -4.9801747 | H37: =H25/H9 -> -8.0494888 | I37: =I25/I9 -> -4.4571772 | J37: =J25/J9 -> -0.69019829 | K37: =K25/K9 -> -0.20524678 | L37: =L25/L5 -> -0.4891699 | M37: =M25/M5 -> 1.88057 | N37: =N25/N5 -> 4.6530993 | O37: =O25/O5 -> 8.3701637 | P37: =P25/P5 -> 12.220481 | Q37: =Q25/Q5 -> 16.5673 | R37: =R25/R5 -> 21.625577 | S37: =S25/S5 -> 27.924397 | U37: =U25/U5 -> -38.248004 | V37: =V25/V5 -> -6.2815109 | W37: =W25/W5 -> -10.757852 | X37: =X25/X5 -> -3.9983879 | Y37: =Y25/Y5 -> -6.7931316 | Z37: =Z25/Z5 -> -2.4736424
B38: Adj. NPM | G38: =G32/G9 -> -4.986462 | H38: =H32/H9 -> -7.8919927 | I38: =I32/I9 -> -4.3929624 | J38: =J32/J9 -> -0.69583078 | K38: =K32/K9 -> -0.20675178 | L38: =L32/L9 -> -0.022781552 | M38: =M32/M9 -> 0.050262496 | N38: =N32/N9 -> 0.092627095 | ... S38: =S32/S9 -> 0.22867099 | U38: =U32/U9 -> -22.938832 | V38: =V32/V9 -> -5.3659147 | W38: =W32/W9 -> -9.1785495 | X38: =X32/X9 -> -2.6806247 | Y38: =Y32/Y9 -> -2.3798803 | Z38: =Z32/Z9 -> -0.33610711

Sheet DCF+base-bull-bear
C1: 7
B2: Total market TAM - US$ mn | F2: 392.74387 | G2: 4963.0775 | H2: 15407.533 | I2: 36237.021 | J2: 71860.359 | K2: 125614.64
B3: Total market TAM - Rmb mn | F3: =F2*$C$1 -> 2749.2071 | G3: =G2*$C$1 -> 34741.542 | H3: =H2*$C$1 -> 107852.73 | I3: =I2*$C$1 -> 253659.15 | J3: =J2*$C$1 -> 503022.52 | K3: =K2*$C$1 -> 879302.5
B4: (Rmb mn) | C4: 2022 | D4: 2023 | E4: 2024 | F4: 2025 | G4: 2026 | H4: 2027 | I4: 2028 | J4: 2029 | K4: 2030 | L4: =K4+1 -> 2031 | M4: =L4+1 -> 2032 | N4: =M4+1 -> 2033 | O4: =N4+1 -> 2034 | P4: =O4+1 -> 2035 | R4: 2031-35E
B5: Revenue | C5: =Model!F4 -> 57.409 | D5: =Model!G4 -> 124.538 | E5: =Model!H4 -> 312.414 | F5: =Model!I4 -> 724.334 | G5: =Model!J4 -> 6339.2276 | H5: =Model!K4 -> 23724.729 | I5: =Model!L4 -> 58809.369 | J5: =Model!M4 -> 120603.6 | K5: =Model!N4 -> 219595.57 | L5: =K5*(1+L6) -> 340746.44 | M5: =L5*(1+M6) -> 472339.31 | N5: =M5*(1+N6) -> 581786.94 | O5: =N5*(1+O6) -> 639965.64 | P5: =O5*(1+P6) -> 671963.92 | R5: =SUM(L5:P5) -> 2706802.2
B6: yoy % | E6: =E5/D5-1 -> 1.5085837 | F6: =F5/E5-1 -> 1.3185069 | G6: =G5/F5-1 -> 7.7518018 | H6: =H5/G5-1 -> 2.7425269 | I6: =I5/H5-1 -> 1.4788215 | J6: =J5/I5-1 -> 1.0507549 | K6: =K5/J5-1 -> 0.82080436 | L6: 0.5517 | M6: =L6*0.7 -> 0.38619 | N6: =M6*0.6 -> 0.231714 | O6: 0.1 | P6: 0.05
B7: Amongst which: Open platform API revenue | E7: =Revenue!H9 -> 48.484 | F7: =Revenue!I9 -> 190.379 | G7: =Revenue!J9 -> 5248.44 | H7: =Revenue!K9 -> 21931 | I7: =Revenue!L9 -> 56143.5 | J7: =Revenue!M9 -> 116777.5 | K7: =Revenue!N9 -> 214312
B8: Implied % of China AI model revenue pool | G8: =G7/G$3 -> 0.15107101 | H8: =H7/H$3 -> 0.20334209 | I8: =I7/I$3 -> 0.22133442 | J8: =J7/J$3 -> 0.23215164 | K8: =K7/K$3 -> 0.24372955
B9: Incremental market share gain | H9: =H8-G8 -> 0.052271081 | I9: =I8-H8 -> 0.017992326 | J9: =J8-I8 -> 0.010817217 | K9: =K8-J8 -> 0.011577911
B11: Training cost as % of revenue | D11: =Model!G97/'DCF+base-bull-bear'!D5 -> 2.5032199 | E11: =Model!H97/'DCF+base-bull-bear'!E5 -> 4.9704303 | F11: =Model!I97/'DCF+base-bull-bear'!F5 -> 3.1056495 | G11: =Model!J97/'DCF+base-bull-bear'!G5 -> 0.63874493 | H11: =Model!K97/'DCF+base-bull-bear'!H5 -> 0.324277 | I11: =Model!L97/'DCF+base-bull-bear'!I5 -> 0.19609771 | J11: =Model!M97/'DCF+base-bull-bear'!J5 -> 0.15299553 | K11: =Model!N97/'DCF+base-bull-bear'!K5 -> 0.13024083 | ... P11: =Model!S97/'DCF+base-bull-bear'!P5 -> 0.11000838
B13: Non-GAAP operating profit | C13: =Model!F23 -> -97.695 | D13: =Model!G23 -> -620.221 | E13: =Model!H23 -> -2514.773 | F13: =Model!I23 -> -3228.485 | G13: =Model!J23 -> -4375.324 | H13: =Model!K23 -> -4869.4244 | I13: =Model!L23 -> -1304.063 | J13: =Model!M23 -> 7195.2558 | K13: =Model!N23 -> 24584.964 | L13: =L5*L14 -> 61334.36 | M13: =M5*M14 -> 94467.862 | N13: =N5*N14 -> 127993.13 | O13: =O5*O14 -> 154871.68 | P13: =P5*P14 -> 176054.55 | R13: =SUM(L13:P13) -> 614721.58
B14: Non-GAAP operating margin % | D14: =D13/D5 -> -4.9801747 | E14: =E13/E5 -> -8.0494888 | F14: =F13/F5 -> -4.4571772 | G14: =G13/G5 -> -0.69019829 | H14: =H13/H5 -> -0.20524678 | I14: =I13/I5 -> -0.022174409 | J14: =J13/J5 -> 0.059660372 | K14: =K13/K5 -> 0.11195565 | L14: 0.18 | M14: 0.2 | N14: 0.22 | O14: 0.242 | P14: 0.262 | R14: =R13/R5 -> 0.22710251
B15: Income tax rate % | C15: =IF(C13<0,0%,-18%) -> 0 | D15: =IF(D13<0,0%,-18%) -> 0 | E15: =IF(E13<0,0%,-18%) -> 0 | F15: =IF(F13<0,0%,-18%) -> 0 | G15: =IF(G13<0,0%,-18%) -> 0 | H15: =IF(H13<0,0%,-18%) -> 0 | I15: =IF(I13<0,0%,-18%) -> 0 | J15: =IF(J13<0,0%,-18%) -> -0.18 | ... P15: =IF(P13<0,0%,-18%) -> -0.18 | R15: =R16/R13 -> -0.18
B16: Income tax expenses | C16: =C15*C13 -> 0 | D16: =D15*D13 -> 0 | E16: =E15*E13 -> 0 | F16: =F15*F13 -> 0 | G16: =G15*G13 -> 0 | H16: =H15*H13 -> 0 | I16: =I15*I13 -> 0 | J16: =J15*J13 -> -1295.1461 | ... P16: =P15*P13 -> -31689.818 | R16: =SUM(L16:P16) -> -110649.88
B17: NOPAT (adjusted) | C17: =C13+C16 -> -97.695 | D17: =D13+D16 -> -620.221 | E17: =E13+E16 -> -2514.773 | F17: =F13+F16 -> -3228.485 | G17: =G13+G16 -> -4375.324 | H17: =H13+H16 -> -4869.4244 | I17: =I13+I16 -> -1304.063 | J17: =J13+J16 -> 5900.1098 | ... P17: =P13+P16 -> 144364.73 | R17: =SUM(L17:P17) -> 504071.69
B18: Depreciation & amortization | C18: =Model!F209+Model!F238 -> 20.018 | D18: =Model!G209+Model!G238 -> 68.931 | E18: =Model!H209+Model!H238 -> 279.937 | F18: =Model!I209+Model!I238 -> 281.061 | G18: =Model!J209+Model!J238 -> 143.61724 | H18: =Model!K209+Model!K238 -> 143.14779 | I18: =Model!L209+Model!L238 -> 48.242611 | J18: =Model!M209+Model!M238 -> 29.841016 | ... P18: =Model!S209+Model!S238 -> 55.781994 | R18: =SUM(L18:P18) -> 232.60341
B19: Change in working capital | C19: =SUM(Model!F255:F261) -> 9.893 | D19: =SUM(Model!G255:G261) -> -96.09 | E19: =SUM(Model!H255:H261) -> -0.026 | F19: =SUM(Model!I255:I261) -> 704.286 | G19: =SUM(Model!J255:J261) -> 1881.9336 | H19: =SUM(Model!K255:K261) -> 2300.1187 | I19: =SUM(Model!L255:L261) -> 2445.5425 | J19: =SUM(Model!M255:M261) -> 2289.5281 | ... P19: =SUM(Model!S255:S261) -> -19218.455 | R19: =SUM(L19:P19) -> -35526.462
B20: Capital expenditures | C20: =-Model!F190-Model!F219 -> -31.651 | D20: =-Model!G190-Model!G219 -> -508.569 | E20: =-Model!H190-Model!H219 -> -132.76 | F20: =-Model!I190-Model!I219 -> -23.088 | G20: =-Model!J190-Model!J219 -> -27.7056 | H20: =-Model!K190-Model!K219 -> -31.85508 | I20: =-Model!L190-Model!L219 -> -35.040588 | J20: =-Model!M190-Model!M219 -> -38.544647 | ... P20: =-Model!S190-Model!S219 -> -68.284193 | R20: =SUM(L20:P20) -> -284.7359
B21: Free cash flow | C21: =C17+C18+C19+C20 -> -99.435 | D21: =D17+D18+D19+D20 -> -1155.949 | E21: =E17+E18+E19+E20 -> -2367.622 | F21: =F17+F18+F19+F20 -> -2266.226 | G21: =G17+G18+G19+G20 -> -2377.4788 | H21: =H17+H18+H19+H20 -> -2458.013 | I21: =I17+I18+I19+I20 -> 1154.6815 | J21: =J17+J18+J19+J20 -> 8180.9342 | ... P21: =P17+P18+P19+P20 -> 125133.77 | R21: =SUM(L21:P21) -> 468493.1
B22: Free cash flow (with terminal value), 12% WACC | C22: =C21 -> -99.435 | D22: =D21 -> -1155.949 | E22: =E21 -> -2367.622 | F22: =F21 -> -2266.226 | G22: =G21 -> -2377.4788 | H22: =H21 -> -2458.013 | I22: =I21 -> 1154.6815 | J22: =J21 -> 8180.9342 | ... O22: =O21 -> 113426.96 | P22: =$P$21*(1+$C$48)*$C$50+$P$21 -> 1560461.6 | R22: =SUM(L22:P22) -> 1903820.9
B23: FCF margin | C23: =IF(C21<0,0,C21/C5) -> 0 | D23: =IF(D21<0,0,D21/D5) -> 0 | E23: =IF(E21<0,0,E21/E5) -> 0 | F23: =IF(F21<0,0,F21/F5) -> 0 | G23: =IF(G21<0,0,G21/G5) -> 0 | H23: =IF(H21<0,0,H21/H5) -> 0 | I23: =IF(I21<0,0,I21/I5) -> 0.019634311 | J23: =IF(J21<0,0,J21/J5) -> 0.067833249 | ... P23: =IF(P21<0,0,P21/P5) -> 0.18622097 | R23: =IF(R21<0,0,R21/R5) -> 0.17307991
B24: Discount factor | C24: =D24 -> 1 | D24: =E24 -> 1 | E24: =F24 -> 1 | F24: =G24 -> 1 | G24: =1/(1+$C$48)^(G4-$G$4) -> 1 | H24: =1/(1+$C$48)^(H4-$G$4) -> 0.8914245 | I24: =1/(1+$C$48)^(I4-$G$4) -> 0.79463763 | J24: =1/(1+$C$48)^(J4-$G$4) -> 0.70835945 | K24: =1/(1+$C$48)^(K4-$G$4) -> 0.63144897 | L24: =1/(1+$C$48)^(L4-$G$4) -> 0.56288908 | M24: =1/(1+$C$48)^(M4-$G$4) -> 0.50177311 | N24: =1/(1+$C$48)^(N4-$G$4) -> 0.44729284 | ... P24: =1/(1+$C$48)^(P4-$G$4) -> 0.35543573
B27: Firm value (discount to 2026E, Rmb mn) | C27: =NPV(C48,H22:P22) -> 731848.32
B28: Net cash (2026E) | C28: =Model!J169 -> 29767.347
B29: Equity valuation (discount to 2026E, Rmb mn) | C29: =C27+C28 -> 761615.67
B30: Equity valuation (discount to 2026E, HK$ mn) | C30: =C29/C52 -> 875420.31
B31: Terminal value as % of total | C31: =P22/(1+$C$48)^(P4-G4)/C29 -> 0.72824632
B33: Shares outstanding (mn) | C33: =Model!Z55 -> 465.62309
B34: Target Price (HK$) | C34: =ROUND(C30/C33,0) -> 1880
B36: WACC calculation | C36: High-end
B37: Equity component
B38: Equity market premium | C38: 0.07
B39: Risk free rate | C39: 0.035
B40: Beta | C40: 1.24
B41: Cost of equity | C41: =+C39+C38*C40 -> 0.1218
B43: Debt component
B44: Cost of debt | C44: 0.05
B45: Tax rate | C45: 0.15
B46: After-tax cost of debt | C46: =C44*(1-C45) -> 0.0425
B48: WACC | C48: =C41 -> 0.1218
...

Sheet Bull bear
B5: Scenarios for valuation | D5: Bear case | F5: Base case | H5: Bull case
D6: 2027E EV/Sales-based | F6: DCF-based | H6: DCF-based, mid-2028E ARR-implied
B7: Zhipu | D7: Applying 8X EV/Sales multiple to 27E open API platform revenue of Rmb22bn. Bear case valuation implies Zhipu’s revenue pool share declines from 20% to 18% from 2027 to 2030E on higher competition. | F7: Assuming Zhipu's revenue pool share to expand from 20% in 2027 to 24% by 2030E, and 26% EBIT margin (by 2035E). Applying 12% WACC and 2% terminal growth rate (consistent with our coverage). | H7: Bull case valuation assumes Zhipu’s revenue pool share to expand from 20% in 2027 to 33% by 2030E. Implies 28X mid-2028E ARR, discounting back using 12% p.a.
B9: Valuation per share (HK$) | D9: =D17/D18 -> 900 | F9: ='DCF+base-bull-bear'!C34 -> 1880 | H9: =H17/H18 -> 3350
B10: Valuation (US$bn) | D10: =D16/1000 -> 53.725741 | F10: ='DCF+base-bull-bear'!C30/7.8/1000*0.984 -> 110.43764 | H10: =H16/1000 -> 199.97915
B12: Upside/downside | D12: =D9/$D$21-1 -> -0.55708661 | F12: =F9/$D$21-1 -> -0.07480315 | H12: =H9/$D$21-1 -> 0.64862205
B14: ARR/Revenue (US$mn) | D14: =Revenue!K29/7 -> 3133 | H14: =Revenue!L29/7 -> 8020.5
B15: Multiple | D15: 7.6471096 | H15: 28.333524
B16: EV/equity value (US$ mn) | D16: =(D14*D15+D20) -> 53725.741 | H16: =H14*H15*(1-12%) -> 199979.15
B17: Equity value (HK$ mn) | D17: =D16*7.8 -> 419060.78 | H17: =H16*7.8 -> 1559837.4
B18: Share outstanding | D18: =H18 -> 465.62309 | H18: ='DCF+base-bull-bear'!C33 -> 465.62309
D19: =D17/D18 -> 900 | H19: =H17/H18 -> 3350
B20: Net cash | D20: ='DCF+base-bull-bear'!C85 -> 29767.347
B21: Current price | D21: 2032
